Workbook
Name \A: #REF!
Name \A: #REF!
Name \B: #REF!
Name \B: #REF!
Name \C: #REF!
Name \D: #REF!
Name \E: #REF!
Name \F: #REF!
Name \i: #REF!
Name \M: #REF!
Name \N: #REF!
Name \O: #REF!
Name \P: #REF!
Name \Q: #REF!
Name \S: #REF!
Name \T: #REF!
Name \U: #REF!
Name \w: #REF!
Name \X: #REF!
Name \Y: #REF!
Name \Z: #REF!
Name ____7HILLS: #REF!
Name ____Ins2: #REF!
Name ____Ins3: #REF!
Name ____NML9798: #REF!
Name ____NML98: #REF!
Name ____PEG1: #REF!
Name ____RR1: #REF!
Name ____SKY98: #REF!
Name ___1Module2_.PRINT_BCCAM: #N/A
Name ___7HILLS: #REF!
Name ___Ins2: #REF!
Name ___Ins3: #REF!
Name ___MT1: #REF!
Name ___MT2: #REF!
Name ___MT3: #REF!
Name ___NML9798: #REF!
Name ___NML98: #REF!
Name ___PEG1: #REF!
Name ___RR1: #REF!
Name ___SKY98: #REF!
Name __1Module2_.PRINT_BCCAM: #N/A
Name __2Module2_.PRINT_BCPR: #N/A
Name __3Module2_.PRINT_BCTAX: #N/A
Name __4Module2_.PRINT_HSUM: #N/A
Name __5_96100: #REF!
Name __7HILLS: #REF!
Name __96100: #REF!
Name __Ins2: #REF!
Name __Ins3: #REF!
Name __MT1: #REF!
Name __MT2: #REF!
Name __MT3: #REF!
Name __NML9798: #REF!
Name __NML98: #REF!
Name __PEG1: #REF!
Name __RR1: #REF!
Name __SKY98: #REF!
Name __soa202: #REF!
Name __soa207: #REF!

Sheet Scenario 1 - Phase 1
A1: Project Details | D1: Unit Breakdown | H1: Breakdown Per Building | N1: List of Take offs | R1: List of Take offs
A2: Project | B2: Robindale & 215 | D2: Unit Type | E2: Number | F2: % | H2: Bldg. | I2: Unit | J2: GSF | N2: Slab SF | O2: =B8/3 -> 103714 | P2: GSF / 3 | R2: 1x1 Counter tops | S2: 14490 | T2: SF
A3: Budget Level | B3: Level 1 | D3: Studios | E3: 0 | F3: =E3/$E$8 -> 0 | H3: 1 | I3: 155 | J3: 141378 | N3: Elevators | O3: 4 | P3: Count Est. | R3: 2x1 Counter Tops | S3: 9294 | T3: SF
A4: Product | B4: Senior | D4: 1 Br - 1 Ba | E4: =77+18+96+30 -> 221 | F4: =E4/$E$8 -> 0.63688761 | H4: 2 | I4: 192 | J4: 169764 | N4: Trash Encl. | O4: 10 | P4: Count Est. 1 per 35 Units | R4: 1x1 Cab Boxes | T4: Boxes
A5: Start Date | B5: 45809 | D5: 2 Br - 1 Ba | E5: =39+21+39+27 -> 126 | F5: =E5/$E$8 -> 0.36311239 | N5: Stairs | O5: 11 | P5: Count | R5: 2x1 Cab Boxes | T5: Boxes
A6: Timline | B6: 24 | D6: 2 Br - 2 Ba | E6: 0 | F6: =E6/$E$8 -> 0 | H6: Totals | I6: =SUM(I3:I5) -> 347 | J6: =SUM(J3:J5) -> 311142 | N6: Pool | O6: 2 | R6: 1x1 Decks | S6: =83*48 -> 3984 | T6: SF
A7: Floors | B7: 3 | D7: 3 Br - 2 Ba | E7: 0 | F7: =E7/$E$8 -> 0 | N7: Gym | O7: 2 | R7: 2x1 Decks | T7: SF
A8: Bldg SF | B8: =J6 -> 311142 | D8: Totals | E8: =SUM(E3:E7) -> 347 | F8: =E8/$E$8 -> 1 | H8: TOTAL COST | J8: =L326 -> 59260086 | N8: Iron Rail | O8: =B8/196333*1600 -> 2535.6267 | P8: Prorate to Bruner SF | R8: Pavers | T8: SF
A9: Acres | B9: 11.7 | D9: Parking | H9: PER UNIT | J9: =J8/E8 -> 170778.35 | N9: Roofing | O9: =(47980+59843)/100 -> 1078.23 | P9: Square | R9: Site Landscaping | S9: =37800+16*200+10600+7900+17600 -> 77100 | T9: Building 1 SF
A10: Site SF | B10: =B9*43560 -> 509652 | D10: Garage Parking | F10: 0 | H10: PER GSF | J10: =J8/B8 -> 190.45994 | N10: Stucco | O10: =(SUM(O14:O16)*40)/9 -> 15620 | P10: Square Yard | R10: Site Landscaping | S10: =21300+24400+20800+6800+4300+12000+22*200 -> 94000 | T10: Building 2 SF
A11: Buildings | B11: 2 | D11: Cover Parking | F11: 0 | N11: Liavable Area | O11: =(120244+147789) -> 268033 | P11: SF | R11: Site Landscaping | S11: 0 | T11: Building 3 SF
A12: Reports Available | D12: Open Parking | F12: =706-190 -> 516 | N12: Carports | O12: =F15*60% -> 309.6 | P12: 60% of spaces (Bruner) | R12: Pool Fence | S12: =103*2+24*2 -> 254
A13: Site Evaluation Report (GCW) | D13: Accessible Parking | F13: =ROUNDUP(E8*0.02,0) -> 7 | N13: Seal Coat | O13: =44500+31000+29000+33400+36700+5600+4900+100400-82500 -> 203000 | P13: Asphalt SF | R13: Dog Park Fence | S13: =67*2+52*2+9+8 -> 255
A14: Soils Report (Universal) | D14: Private Garages | F14: 0 | N14: Building Perimeter | O14: =1545*110% -> 1699.5 | P14: Bldg 1 LF | R14: Corridor | S14: =(2440+1725)*3 -> 12495 | T14: Building 1 SF
A15: Alta Survey (Wallace) | D15: Total Parking Provided | F15: =SUM(F10:F12) -> 516 | N15: Building Perimeter | O15: =1650*110% -> 1815 | P15: Bldg 2 LF | R15: Corridor | S15: =(2450+1950)*3 -> 13200 | T15: Building 2 SF
A16: Plans | D16: Parking Ratio | F16: =SUM(F10:F12)/E8 -> 1.4870317 | N16: Building Perimeter | O16: 0 | P16: Bldg 3 LF | R16: Corridor | S16: 0 | T16: Building 3 SF
R17: Pool Deck | S17: =9800-815-185-125*8 -> 7800 | T17: SF
A19: Description | B19: Cost Code | C19: Cost Category | D19: Subjob | E19: Source | F19: Unit Meas. | G19: Quantity | H19: Unit Cost | I19: Escalation % | J19: T. Unit Cost | K19: Sub Total | L19: Total | N19: Description / Details
A20: General Requirements | B20: 01 | L20: =K21 -> 2008563.6
A21: General Requirements | B21: 01 | C21: S | F21: Mo | G21: =B6 -> 24 | H21: 83690.15 | I21: 0 | J21: =H21*(1+I21) -> 83690.15 | K21: =J21*G21 -> 2008563.6
A22: Existing Conditions | B22: 02 | L22: =K23 -> 8000
A23: Potholing | B23: 02-3213 | C23: S | D23: ON-SITE | E23: Allowance | G23: 1 | H23: 8000 | I23: 0 | J23: =H23*(1+I23) -> 8000 | K23: =J23*G23 -> 8000
A24: Concrete | B24: 03 | L24: =SUM(K25:K34) -> 1975170
A25: Slabs | B25: 03-3101 | C25: S | D25: BUILDING | E25: Torrey Pines | F25: SF | G25: =J6/3 -> 103714 | H25: 11.99 | I25: 0 | J25: =H25*(1+I25) -> 11.99 | K25: =J25*G25 -> 1243530.9
A26: Deepened Footings | B26: 03-3101 | C26: S | D26: BUILDING | E26: N/A | J26: =H26*(1+I26) -> 0 | K26: =J26*G26 -> 0
A27: Concrete Slab Repairs | B27: 03-3101 | C27: RR | D27: BUILDING | E27: Allowance | F27: LS | G27: 1 | H27: =2500*3 -> 7500 | I27: 0 | J27: =H27*(1+I27) -> 7500 | K27: =J27*G27 -> 7500
A28: Pump House Concrete | B28: 03-3101 | C28: S | D28: PUMPHOUSE | E28: Torrey Pines | F28: SF | G28: 300 | H28: 11.99 | I28: 0 | J28: =H28*(1+I28) -> 11.99 | K28: =J28*G28 -> 3597
A29: Trash Enclosure Concrete | B29: 03-3102 | C29: S | D29: OTHER SITE | E29: Russell IV | F29: Count | G29: =O4 -> 10 | H29: 2698 | I29: 0 | J29: =H29*(1+I29) -> 2698 | K29: =J29*G29 -> 26980
A30: Pool Area Shower Concrete | B30: 03-3105 | C30: S | D30: POOL AREA | E30: Torrey Pines | F30: LS | G30: =O6 -> 2 | H30: 2500 | I30: 0 | J30: =H30*(1+I30) -> 2500 | K30: =J30*G30 -> 5000
A31: Cabana Concrete | B31: 03-3107 | C31: S | D31: POOL AREA | E31: N/A | J31: =H31*(1+I31) -> 0 | K31: =J31*G31 -> 0
A32: Pool Equipment Foundation | B32: 03-3108 | C32: S | D32: POOL EQUIP | E32: N/A | J32: =H32*(1+I32) -> 0 | K32: =J32*G32 -> 0
A33: Lightweight Concrete | B33: 03-3116 | C33: S | D33: BUILDING | E33: Torrey Pines | F33: SF | G33: =J6/3*2 -> 207428 | H33: 2.94 | I33: 0 | J33: =H33*(1+I33) -> 2.94 | K33: =J33*G33 -> 609838.32
A34: Deck Concrete | B34: 03-5001 | C34: S | D34: BUILDING | E34: Torrey Pines | F34: SF | G34: =SUM($S$6:$S$7) -> 3984 | H34: 19.76 | I34: 0 | J34: =H34*(1+I34) -> 19.76 | K34: =J34*G34 -> 78723.84
A35: Parking Garage | B35: 03-G | L35: =SUM(K36:K43) -> 0
A36: Parking Garage Structure | C36: S | E36: N/A | J36: =H36*(1+I36) -> 0 | K36: =J36*G36 -> 0
A37: Core Slab Precast Concrete | C37: S | E37: N/A | J37: =H37*(1+I37) -> 0 | K37: =J37*G37 -> 0
A38: Concrete Slab on Grade | C38: S | E38: N/A | J38: =H38*(1+I38) -> 0 | K38: =J38*G38 -> 0
A39: Concrete Topping Slab 4" / Level | C39: S | E39: N/A | J39: =H39*(1+I39) -> 0 | K39: =J39*G39 -> 0
A40: Electrical | C40: S | E40: N/A | J40: =H40*(1+I40) -> 0 | K40: =J40*G40 -> 0
A41: Dry Sprinklers | C41: S | E41: N/A | J41: =H41*(1+I41) -> 0 | K41: =J41*G41 -> 0
...

Sheet _REFERENCE888777888
A1: WorkSheet Name | B1: Report Code | C1: Company Id | D1: Job Id | E1: Start Date | F1: End Date | G1: Payroll Subledger | H1: Pay Period Id

Sheet LEVEL 3
A1: Project Details | D1: Unit Breakdown | H1: Unit Matrix | N1: List of Take offs | Q1: List of Take offs | T1: List of Take offs
A2: Project | B2: Bruner Senior | D2: Unit Type | E2: Number | F2: % | H2: Unit Type | I2: Number | J2: % | K2: SF | N2: Slab SF | O2: =24424+23698 -> 48122 | P2: GSF | Q2: Counter tops | R2: 11437.45 | S2: SF | T2: Fitness Center | U2: 1316 | V2: SF
A3: Budget Level | B3: Level 3 | D3: Studios | E3: 0 | F3: =E3/$E$8 -> 0 | H3: A1A | I3: 5 | J3: =I3/$E$8 -> 0.025773196 | K3: 663 | N3: Elevators | O3: 2 | P3: Count | Q3: Blinds | R3: 513 | AG3: Railing Estimate | AK3: Building 3 | AL3: =21*7 -> 147 | AN3: Stucco | AR3: Building 3 | AS3: =15000+6560+6500+15400+4570+4635+4540+4250 -> 61455
A4: Product | B4: Senior | D4: 1 Br - 1 Ba | E4: 126 | F4: =E4/$E$8 -> 0.64948454 | H4: B1A | I4: 73 | J4: =I4/$E$8 -> 0.37628866 | K4: 663 | N4: Elevators Stops | O4: 8 | P4: Count | Q4: Landscaping | R4: 39274 | S4: SF | AG4: Building 1 | AL4: =14*7 -> 98 | AN4: Building 1
A5: Start Date | B5: 45809 | D5: 2 Br - 1 Ba | E5: 68 | F5: =E5/$E$8 -> 0.35051546 | H5: B1B | I5: 48 | J5: =I5/$E$8 -> 0.24742268 | K5: 675 | N5: Trash Encl. | O5: 4 | P5: Site Plan | AG5: Northwest | AH5: =21*4+8*8+7*6 -> 190 | AL5: =8*22 -> 176 | AN5: Northwest | AO5: 19256
A6: Timeline | B6: 20 | D6: 2 Br - 2 Ba | E6: 0 | F6: =E6/$E$8 -> 0 | H6: A2A | I6: 5 | J6: =I6/$E$8 -> 0.025773196 | K6: 888 | N6: Stairs | O6: 7 | P6: Count | Q6: 1x1 Decks | R6: 0 | S6: SF | AG6: Southwest | AH6: =14*4+21*2+8*6 -> 146 | AL6: =7*10 -> 70 | AN6: Southwest | AO6: 8980
A7: Floors | B7: 4 | D7: 3 Br - 2 Ba | E7: 0 | F7: =E7/$E$8 -> 0 | H7: B2A | I7: 46 | J7: =I7/$E$8 -> 0.2371134 | K7: 888 | N7: Pool | O7: 1 | Q7: 2x1 Decks | S7: SF | AG7: Northeast | AH7: =21*2+14*2+8*6 -> 118 | AL7: =SUM(AL3:AL6) -> 491 | AN7: Northeast | AO7: 8850
A8: Bldg. SF | B8: 196289 | D8: Totals | E8: =SUM(E3:E7) -> 194 | F8: =E8/$E$8 -> 1 | H8: B2B | I8: 17 | J8: =I8/$E$8 -> 0.087628866 | K8: 955 | N8: Gym | O8: 1 | Q8: Lightweight | R8: 147250 | S8: SF | AG8: Southeast | AH8: =21*2+14*8+8*12+7*8 -> 306 | AN8: Southeast | AO8: 19965
A9: Acres | B9: 4.9 | D9: Parking | H9: Totals | I9: =SUM(I3:I8) -> 194 | J9: =SUM(J3:J8) -> 1 | K9: =SUMPRODUCT(I3:I8,K3:K8) -> 145637 | N9: Iron Rail | O9: 1593 | P9: LF | Q9: Pavers | R9: 0 | S9: SF | AG9: More | AH9: =21*4+8*6 -> 132 | AI9: =SUM(AH5:AH9) -> 892 | AN9: More | AO9: =5870+6250+6290+5915 -> 24325 | AP9: =SUM(AO5:AO9) -> 81376
A10: Site SF | B10: =B9*43560 -> 213444 | D10: Cover Parking | F10: 127 | N10: Roofing | O10: =(12209+13565+13960+10629)/100 -> 503.63 | P10: Square | Q10: Pool Deck | R10: 0 | S10: SF
A11: Buildings | B11: 1 | D11: Cover Accesible Parking | F11: 3 | N11: Stucco | O11: 11824 | P11: Square Yard | Q11: Pool Fence | R11: 0 | S11: LF | AG11: Building 2 & 5 | AK11: Building 4 | AL11: =14*8 -> 112 | AN11: Building 2 & 5 | AR11: Building 4 | AS11: =5782+5760+8825+9150 -> 29517
A12: Reports Available | D12: Open Parking | F12: 45 | N12: Livable Area | O12: 0 | P12: SF | Q12: Dog Park Fence | R12: 0 | S12: LF | AG12: Northwest | AL12: =20*8 -> 160 | AN12: Northwest
A13: Site Evaluation Report (GCW) | B13: N | D13: Accessible Parking | F13: 11 | N13: Carports | O13: =F10+F11 -> 130 | P13: Count | Q13: Common Bldg. 1 | R13: 0 | S13: SF | AG13: Southwest | AL13: =8*18 -> 144 | AN13: Southwest
A14: Soils Report (Nova or Universal) | B14: Y - 4/21/20 | D14: Waiver | F14: 8 | H14: TOTAL COST | J14: =L335 -> 33486712 | N14: Stairs Landings | O14: 60 | P14: Landings | Q14: Asphalt | R14: 75608 | AG14: Northeast | AL14: =7*12 -> 84 | AN14: Northeast
A15: Alta Survey (Wallace) | B15: Y - 1/21/20 | D15: Total Parking Provided | F15: =SUM(F10:F14) -> 194 | H15: PER UNIT | J15: =J14/E8 -> 172611.92 | N15: Pump House | O15: 1 | P15: EA | Q15: Pavers | R15: 350 | AG15: Southeast | AH15: =21*2+14*2+8*6+7*6 -> 160 | AI15: =AH15*2 -> 320 | AL15: =SUM(AL11:AL14) -> 500 | AN15: Southeast | AO15: =5035+5775+1960+1960 -> 14730 | AP15: =AO15*2 -> 29460
A16: Plans | B16: N | D16: Parking Ratio | F16: =SUM(F10:F13)/E8 -> 0.95876289 | H16: PER GSF | J16: =J14/B8 -> 170.59902 | N16: Lock Boxes | O16: 0 | P16: EA | Q16: Pavers Pool | R16: 4500
N17: Awning Small | O17: 0 | P17: EA | AG17: B1B Railings | AH17: =12.5*62 -> 775 | AN17: B1B Railings | AO17: =12.5*62 -> 775
N18: Awning Large | O18: 0 | P18: EA
A19: Description | B19: Cost Code | C19: Cost Category | D19: Sub job | E19: Source | F19: UMO | G19: QTY | H19: U.P. | I19: Escal % | J19: Total U.P. | K19: Sub Total | L19: Total | M19: Description / Details
A20: General Requirements | B20: 01 | L20: =K21 -> 1674318
A21: General Requirement | B21: 01 | C21: S | F21: Mo | G21: =$B$6 -> 20 | H21: =1674318/20 -> 83715.9 | I21: 0 | J21: =H21*(1+I21) -> 83715.9 | K21: =J21*G21 -> 1674318 | AG21: Common Areas Flooring | AJ21: Level | AK21: SF
A22: Existing Conditions | B22: 02 | L22: =K23 -> 3500 | AG22: Bathrooms | AJ22: 1 | AK22: 273.4
A23: Potholing | B23: 02-3213 | C23: S | D23: ON-SITE | E23: Allowance | G23: 1 | H23: 3500 | I23: 0 | J23: =H23*(1+I23) -> 3500 | K23: =J23*G23 -> 3500 | AG23: Fitness Center | AJ23: 1 | AK23: 1281.48
A24: Concrete | B24: 03 | L24: =SUM(K25:K34) -> 1089279.8 | AG24: Food Pantry | AJ24: 1 | AK24: 655.42
A25: Slabs | B25: 03-3101 | C25: S | D25: BUILDING | E25: Torrey Pines | F25: SF | G25: =O2 -> 48122 | H25: 11.99 | I25: 0 | J25: =H25*(1+I25) -> 11.99 | K25: =J25*G25 -> 576982.78 | M25: NRC proposal is at $534k or $11.01/sf. | AG25: Great Room | AJ25: 1 | AK25: 1520.89
A26: Deepened Footings | B26: 03-3101 | C26: S | D26: BUILDING | E26: N/A | J26: =H26*(1+I26) -> 0 | K26: =J26*G26 -> 0 | AG26: Hallway | AJ26: 1 | AK26: 5652.7
A27: Concrete Slab Repairs | B27: 03-3101 | C27: RR | D27: BUILDING | E27: Allowance | F27: LS | G27: 1 | H27: 2500 | I27: 0 | J27: =H27*(1+I27) -> 2500 | K27: =J27*G27 -> 2500 | AG27: Main Entry Hallway | AJ27: 1 | AK27: 937.64
A28: Pump House Concrete | B28: 03-3101 | C28: S | D28: PUMPHOUSE | E28: Torrey Pines | F28: SF | G28: 300 | H28: 11.99 | J28: =H28*(1+I28) -> 11.99 | K28: =J28*G28 -> 3597 | AG28: Offices and Leasing | AJ28: 1 | AK28: 555.22
A29: Trash Enclosure Concrete | B29: 03-3102 | C29: S | D29: OTHER SITE | E29: Allowance | F29: SF | G29: =230*4 -> 920 | H29: 11.99 | I29: 0 | J29: =H29*(1+I29) -> 11.99 | K29: =J29*G29 -> 11030.8 | AG29: Hallway | AJ29: 2 | AK29: 5596.41
A30: Pool Area Shower Concrete | B30: 03-3105 | C30: S | D30: POOL AREA | E30: Allowance | F30: LS | G30: =$O$7 -> 1 | H30: 2500 | I30: 0 | J30: =H30*(1+I30) -> 2500 | K30: =J30*G30 -> 2500 | AG30: Wellness/Media/Lounge | AJ30: 2 | AK30: 794.24
A31: Cabana Concrete | B31: 03-3107 | C31: S | D31: POOL AREA | E31: N/A | J31: =H31*(1+I31) -> 0 | K31: =J31*G31 -> 0 | AG31: Hallway | AJ31: 3 | AK31: 5570.59
A32: Pool Equipment Foundation | B32: 03-3108 | C32: S | D32: POOL EQUIP | E32: N/A | J32: =H32*(1+I32) -> 0 | K32: =J32*G32 -> 0 | AG32: Computer/Library/Salon | AJ32: 3 | AK32: 780.29
A33: Lightweight Concrete | B33: 03-3116 | C33: S | D33: BUILDING | E33: Torrey Pines | F33: SF | G33: =R8 -> 147250 | H33: 2.94 | I33: 0 | J33: =H33*(1+I33) -> 2.94 | K33: =J33*G33 -> 432915 | AG33: Hallway | AJ33: 4 | AK33: 5680.05
A34: Deck Concrete | B34: 03-5001 | C34: S | D34: BUILDING | E34: Torrey Pines | F34: SF | G34: 3024 | H34: 19.76 | I34: 0 | J34: =H34*(1+I34) -> 19.76 | K34: =J34*G34 -> 59754.24 | AG34: Laundry/Lounge | AJ34: 4 | AK34: 799.74
A35: Parking Garage | B35: 03-G | L35: =SUM(K36:K43) -> 0 | AG35: Stairwell Landing | AJ35: ALL | AK35: 4823.54
A36: Parking Garage Structure | C36: S | E36: N/A | J36: =H36*(1+I36) -> 0 | K36: =J36*G36 -> 0
A37: Core Slab Precast Concrete | C37: S | E37: N/A | J37: =H37*(1+I37) -> 0 | K37: =J37*G37 -> 0
A38: Concrete Slab on Grade | C38: S | E38: N/A | J38: =H38*(1+I38) -> 0 | K38: =J38*G38 -> 0
A39: Concrete Topping Slab 4" / Level | C39: S | E39: N/A | J39: =H39*(1+I39) -> 0 | K39: =J39*G39 -> 0
A40: Electrical | C40: S | E40: N/A | J40: =H40*(1+I40) -> 0 | K40: =J40*G40 -> 0
...

Sheet LEVEL 2 (Match)
A1: Project Details | D1: Unit Breakdown | H1: Unit Matrix | N1: List of Take offs | Q1: List of Take offs | T1: List of Take offs
A2: Project | B2: Bruner Senior | D2: Unit Type | E2: Number | F2: % | H2: Unit Type | I2: Number | J2: % | K2: SF | N2: Slab SF | O2: =24424+23698 -> 48122 | P2: GSF | Q2: Counter tops | R2: 11437.45 | S2: SF | T2: Fitness Center | U2: 1316 | V2: SF
A3: Budget Level | B3: Level 2 | D3: Studios | E3: 0 | F3: =E3/$E$8 -> 0 | H3: A1A | I3: 5 | J3: =I3/$E$8 -> 0.025773196 | K3: 663 | N3: Elevators | O3: 2 | P3: Count | Q3: Blinds | R3: 513 | AG3: Railing Estimate | AK3: Building 3 | AL3: =21*7 -> 147 | AN3: Stucco | AR3: Building 3 | AS3: =15000+6560+6500+15400+4570+4635+4540+4250 -> 61455
A4: Product | B4: Senior | D4: 1 Br - 1 Ba | E4: 126 | F4: =E4/$E$8 -> 0.64948454 | H4: B1A | I4: 73 | J4: =I4/$E$8 -> 0.37628866 | K4: 663 | N4: Elevators Stops | O4: 8 | P4: Count | Q4: Landscaping | R4: 39274 | S4: SF | AG4: Building 1 | AL4: =14*7 -> 98 | AN4: Building 1
A5: Start Date | B5: 45809 | D5: 2 Br - 1 Ba | E5: 68 | F5: =E5/$E$8 -> 0.35051546 | H5: B1B | I5: 48 | J5: =I5/$E$8 -> 0.24742268 | K5: 675 | N5: Trash Encl. | O5: 4 | P5: Site Plan | AG5: Northwest | AH5: =21*4+8*8+7*6 -> 190 | AL5: =8*22 -> 176 | AN5: Northwest | AO5: 19256
A6: Timeline | B6: 20 | D6: 2 Br - 2 Ba | E6: 0 | F6: =E6/$E$8 -> 0 | H6: A2A | I6: 5 | J6: =I6/$E$8 -> 0.025773196 | K6: 888 | N6: Stairs | O6: 7 | P6: Count | Q6: 1x1 Decks | R6: 0 | S6: SF | AG6: Southwest | AH6: =14*4+21*2+8*6 -> 146 | AL6: =7*10 -> 70 | AN6: Southwest | AO6: 8980
A7: Floors | B7: 4 | D7: 3 Br - 2 Ba | E7: 0 | F7: =E7/$E$8 -> 0 | H7: B2A | I7: 46 | J7: =I7/$E$8 -> 0.2371134 | K7: 888 | N7: Pool | O7: 1 | Q7: 2x1 Decks | S7: SF | AG7: Northeast | AH7: =21*2+14*2+8*6 -> 118 | AL7: =SUM(AL3:AL6) -> 491 | AN7: Northeast | AO7: 8850
A8: Bldg. SF | B8: 196289 | D8: Totals | E8: =SUM(E3:E7) -> 194 | F8: =E8/$E$8 -> 1 | H8: B2B | I8: 17 | J8: =I8/$E$8 -> 0.087628866 | K8: 955 | N8: Gym | O8: 1 | Q8: Lightweight | R8: 147250 | S8: SF | AG8: Southeast | AH8: =21*2+14*8+8*12+7*8 -> 306 | AN8: Southeast | AO8: 19965
A9: Acres | B9: 4.9 | D9: Parking | H9: Totals | I9: =SUM(I3:I8) -> 194 | J9: =SUM(J3:J8) -> 1 | K9: =SUMPRODUCT(I3:I8,K3:K8) -> 145637 | N9: Iron Rail | O9: 1593 | P9: LF | Q9: Pavers | R9: 0 | S9: SF | AG9: More | AH9: =21*4+8*6 -> 132 | AI9: =SUM(AH5:AH9) -> 892 | AN9: More | AO9: =5870+6250+6290+5915 -> 24325 | AP9: =SUM(AO5:AO9) -> 81376
A10: Site SF | B10: =B9*43560 -> 213444 | D10: Cover Parking | F10: 127 | N10: Roofing | O10: =(12209+13565+13960+10629)/100 -> 503.63 | P10: Square | Q10: Pool Deck | R10: 0 | S10: SF
A11: Buildings | B11: 1 | D11: Cover Accesible Parking | F11: 3 | N11: Stucco | O11: 11824 | P11: Square Yard | Q11: Pool Fence | R11: 0 | S11: LF | AG11: Building 2 & 5 | AK11: Building 4 | AL11: =14*8 -> 112 | AN11: Building 2 & 5 | AR11: Building 4 | AS11: =5782+5760+8825+9150 -> 29517
A12: Reports Available | D12: Open Parking | F12: 45 | N12: Livable Area | O12: 0 | P12: SF | Q12: Dog Park Fence | R12: 0 | S12: LF | AG12: Northwest | AL12: =20*8 -> 160 | AN12: Northwest
A13: Site Evaluation Report (GCW) | B13: N | D13: Accessible Parking | F13: 11 | N13: Carports | O13: =F10+F11 -> 130 | P13: Count | Q13: Common Bldg. 1 | R13: 0 | S13: SF | AG13: Southwest | AL13: =8*18 -> 144 | AN13: Southwest
A14: Soils Report (Nova or Universal) | B14: Y - 4/21/20 | D14: Waiver | F14: 8 | H14: TOTAL COST | J14: =L330 -> 33757309 | N14: Stairs Landings | O14: 60 | P14: Landings | Q14: Asphalt | R14: 75608 | AG14: Northeast | AL14: =7*12 -> 84 | AN14: Northeast
A15: Alta Survey (Wallace) | B15: Y - 1/21/20 | D15: Total Parking Provided | F15: =SUM(F10:F14) -> 194 | H15: PER UNIT | J15: =J14/E8 -> 174006.75 | N15: Pump House | O15: 1 | P15: EA | Q15: Pavers | R15: 350 | AG15: Southeast | AH15: =21*2+14*2+8*6+7*6 -> 160 | AI15: =AH15*2 -> 320 | AL15: =SUM(AL11:AL14) -> 500 | AN15: Southeast | AO15: =5035+5775+1960+1960 -> 14730 | AP15: =AO15*2 -> 29460
A16: Plans | B16: N | D16: Parking Ratio | F16: =SUM(F10:F13)/E8 -> 0.95876289 | H16: PER GSF | J16: =J14/B8 -> 171.97759 | N16: Lock Boxes | O16: 0 | P16: EA | Q16: Pavers Pool | R16: 4500
N17: Awning Small | O17: 0 | P17: EA | AG17: B1B Railings | AH17: =12.5*62 -> 775 | AN17: B1B Railings | AO17: =12.5*62 -> 775
N18: Awning Large | O18: 0 | P18: EA
A19: Description | B19: Cost Code | C19: Cost Category | D19: Sub job | E19: Source | F19: UMO | G19: Quantity | H19: U.P. | I19: Escal % | J19: Total U.P. | K19: Sub Total | L19: Total | M19: Description / Details
A20: General Requirements | B20: 01 | L20: =K21 -> 1692096
A21: General Requirement | B21: 01 | C21: S | F21: Mo | G21: =$B$6 -> 20 | H21: =1692096/20 -> 84604.8 | I21: 0 | J21: =H21*(1+I21) -> 84604.8 | K21: =J21*G21 -> 1692096
A22: Existing Conditions | B22: 02 | L22: =K23 -> 3500
A23: Potholing | B23: 02-3213 | C23: S | D23: ON-SITE | E23: Allowance | G23: 1 | H23: 3500 | I23: 0 | J23: =H23*(1+I23) -> 3500 | K23: =J23*G23 -> 3500
A24: Concrete | B24: 03 | L24: =SUM(K25:K34) -> 1089279.8
A25: Slabs | B25: 03-3101 | C25: S | D25: BUILDING | E25: Torrey Pines | F25: SF | G25: =O2 -> 48122 | H25: 11.99 | I25: 0 | J25: =H25*(1+I25) -> 11.99 | K25: =J25*G25 -> 576982.78 | M25: Conventional slab
A26: Deepened Footings | B26: 03-3101 | C26: S | D26: BUILDING | E26: N/A | J26: =H26*(1+I26) -> 0 | K26: =J26*G26 -> 0
A27: Concrete Slab Repairs | B27: 03-3101 | C27: RR | D27: BUILDING | E27: Allowance | F27: LS | G27: 1 | H27: 2500 | I27: 0 | J27: =H27*(1+I27) -> 2500 | K27: =J27*G27 -> 2500
A28: Pump House Concrete | B28: 03-3101 | C28: S | D28: PUMPHOUSE | E28: Torrey Pines | F28: SF | G28: 300 | H28: 11.99 | J28: =H28*(1+I28) -> 11.99 | K28: =J28*G28 -> 3597
A29: Trash Enclosure Concrete | B29: 03-3102 | C29: S | D29: OTHER SITE | E29: Allowance | F29: SF | G29: =230*4 -> 920 | H29: 11.99 | I29: 0 | J29: =H29*(1+I29) -> 11.99 | K29: =J29*G29 -> 11030.8
A30: Pool Area Shower Concrete | B30: 03-3105 | C30: S | D30: POOL AREA | E30: Torrey Pines | F30: LS | G30: =$O$7 -> 1 | H30: 2500 | I30: 0 | J30: =H30*(1+I30) -> 2500 | K30: =J30*G30 -> 2500
A31: Cabana Concrete | B31: 03-3107 | C31: S | D31: POOL AREA | E31: N/A | J31: =H31*(1+I31) -> 0 | K31: =J31*G31 -> 0
A32: Pool Equipment Foundation | B32: 03-3108 | C32: S | D32: POOL EQUIP | E32: N/A | J32: =H32*(1+I32) -> 0 | K32: =J32*G32 -> 0
A33: Lightweight Concrete | B33: 03-3116 | C33: S | D33: BUILDING | E33: Torrey Pines | F33: SF | G33: =R8 -> 147250 | H33: 2.94 | I33: 0 | J33: =H33*(1+I33) -> 2.94 | K33: =J33*G33 -> 432915 | AI33: =237250/B8 -> 1.208677
A34: Deck Concrete | B34: 03-5001 | C34: S | D34: BUILDING | E34: Torrey Pines | F34: SF | G34: 3024 | H34: 19.76 | I34: 0 | J34: =H34*(1+I34) -> 19.76 | K34: =J34*G34 -> 59754.24 | AI34: =237250/194 -> 1222.9381
A35: Parking Garage | B35: 03-G | L35: =SUM(K36:K43) -> 0
A36: Parking Garage Structure | C36: S | E36: N/A | J36: =H36*(1+I36) -> 0 | K36: =J36*G36 -> 0
A37: Core Slab Precast Concrete | C37: S | E37: N/A | J37: =H37*(1+I37) -> 0 | K37: =J37*G37 -> 0
A38: Concrete Slab on Grade | C38: S | E38: N/A | J38: =H38*(1+I38) -> 0 | K38: =J38*G38 -> 0
A39: Concrete Topping Slab 4" / Level | C39: S | E39: N/A | J39: =H39*(1+I39) -> 0 | K39: =J39*G39 -> 0
A40: Electrical | C40: S | E40: N/A | J40: =H40*(1+I40) -> 0 | K40: =J40*G40 -> 0
...

Sheet Comparison to Previous
A1: BRUNER SENIOR | C1: LEVEL 1 | F1: LEVEL 2 | O1: LEVEL 3
F2: Project Details | K2: Unit Breakdown | O2: Project Details | T2: Unit Breakdown
F3: Project | G3: Bruner Senior | K3: Unit Type | L3: Number | M3: % | O3: Project | P3: Bruner Senior | T3: Unit Type | U3: Number | V3: %
F4: Budget Level | G4: Level 2 | K4: Studios | L4: 0 | M4: 0 | O4: Budget Level | P4: Level 2 | T4: Studios | U4: 0 | V4: =U4/$U$9 -> 0
F5: Product | G5: Senior | K5: 1 Br - 1 Ba | L5: 126 | M5: 0.64948454 | O5: Product | P5: Senior | T5: 1 Br - 1 Ba | U5: 126 | V5: =U5/$U$9 -> 0.64948454
F6: Start Date | G6: 45809 | K6: 2 Br - 1 Ba | L6: 68 | M6: 0.35051546 | O6: Start Date | P6: 45809 | T6: 2 Br - 1 Ba | U6: 68 | V6: =U6/$U$9 -> 0.35051546
F7: Timeline | G7: 20 | K7: 2 Br - 2 Ba | L7: 0 | M7: 0 | O7: Timeline | P7: 20 | T7: 2 Br - 2 Ba | U7: 0 | V7: =U7/$U$9 -> 0
F8: Floors | G8: 4 | K8: 3 Br - 2 Ba | L8: 0 | M8: 0 | O8: Floors | P8: 4 | T8: 3 Br - 2 Ba | U8: 0 | V8: =U8/$U$9 -> 0
F9: Bldg. SF | G9: 196289 | K9: Totals | L9: 194 | M9: =L9/$L$9 -> 1 | O9: Bldg. SF | P9: 196289 | T9: Totals | U9: =SUM(U4:U8) -> 194 | V9: =U9/$U$9 -> 1
F10: Acres | G10: 4.9 | K10: Parking | O10: Acres | P10: 4.9 | T10: Parking
F11: Site SF | G11: 213444 | K11: Garage Parking | M11: 127 | O11: Site SF | P11: =P10*43560 -> 213444 | T11: Cover Parking | V11: 127
F12: Buildings | G12: 1 | K12: Cover Parking | M12: 3 | O12: Buildings | P12: 1 | T12: Cover Acc. Parking | V12: 3
K13: Open Parking | M13: 45 | T13: Open Parking | V13: 45
K14: Accessible Parking | M14: 11 | Q14: Net Change | T14: Accessible Parking | V14: 11
F15: TOTAL COST | G15: =M314 -> 33757309 | K15: Private Garages | M15: 8 | O15: TOTAL COST | P15: =V314 -> 33486712 | Q15: =P15-G15 -> -270597.42 | R15: =Q15/G15 -> -0.0080159653 | T15: Waiver | V15: 8
F16: PER UNIT | G16: =G15/L9 -> 174006.75 | K16: Total Parking Provided | M16: 194 | O16: PER UNIT | P16: =P15/U9 -> 172611.92 | Q16: =P16-G16 -> -1394.8321 | T16: Total Parking Provided | V16: =SUM(V11:V15) -> 194
F17: PER GSF | G17: =G15/G9 -> 171.97759 | K17: Parking Ratio | M17: 0.95876289 | O17: PER GSF | P17: =P15/P9 -> 170.59902 | Q17: =P17-G17 -> -1.3785664 | T17: Parking Ratio | V17: =SUM(V11:V14)/U9 -> 0.95876289 | X17: Conditions | Z17: Conditions
X18: 50000 | Z18: 0.05
A19: Description | C19: Total | D19: Variance | F19: Source | G19: UOM | H19: QTY | I19: U.P. | J19: % | K19: Total U.P. | L19: Sub Total | M19: Total | O19: Source | P19: UOM | Q19: QTY | R19: U.P. | S19: % | T19: Total U.P. | U19: Sub Total | V19: Total | X19: PV$ | Z19: PV% | AB19: Notes
A20: General Requirements | C20: 1673802.9 | D20: =V20-C20 -> 515.07497 | M20: ='LEVEL 2 (Match)'!L20 -> 1692096 | V20: ='LEVEL 3'!L20 -> 1674318 | X20: =V20-M20 -> -17778 | Z20: =IF(M20=0,0,X20/M20) -> -0.010506496
A21: Existing Conditions | C21: 3500 | D21: =V21-C21 -> 0 | M21: ='LEVEL 2 (Match)'!L22 -> 3500 | V21: ='LEVEL 3'!L22 -> 3500 | X21: =V21-M21 -> 0 | Z21: =IF(M21=0,0,X21/M21) -> 0
A22: Slabs | D22: =V22-C22 -> 0 | F22: Torrey Pines | G22: SF | H22: 48122 | I22: 11.99 | J22: 0 | K22: 11.99 | L22: ='LEVEL 2 (Match)'!K25 -> 576982.78 | O22: Torrey Pines | P22: ='LEVEL 3'!F25 -> SF | Q22: ='LEVEL 3'!G25 -> 48122 | R22: ='LEVEL 3'!H25 -> 11.99 | S22: ='LEVEL 3'!I25 -> 0 | T22: ='LEVEL 3'!J25 -> 11.99 | U22: ='LEVEL 3'!K25 -> 576982.78 | X22: =U22-L22 -> 0 | Z22: =IF(L22=0,0,X22/L22) -> 0
A23: Deepened Footings | D23: =V23-C23 -> 0 | F23: N/A | K23: 0 | L23: ='LEVEL 2 (Match)'!K26 -> 0 | O23: N/A | P23: ='LEVEL 3'!F26 -> 0 | Q23: ='LEVEL 3'!G26 -> 0 | R23: ='LEVEL 3'!H26 -> 0 | S23: ='LEVEL 3'!I26 -> 0 | T23: ='LEVEL 3'!J26 -> 0 | U23: ='LEVEL 3'!K26 -> 0 | X23: =U23-L23 -> 0 | Z23: =IF(L23=0,0,X23/L23) -> 0
A24: Concrete Slab Repairs | D24: =V24-C24 -> 0 | F24: Allowance | G24: LS | H24: 1 | I24: 2500 | J24: 0 | K24: 2500 | L24: ='LEVEL 2 (Match)'!K27 -> 2500 | O24: Allowance | P24: ='LEVEL 3'!F27 -> LS | Q24: ='LEVEL 3'!G27 -> 1 | R24: ='LEVEL 3'!H27 -> 2500 | S24: ='LEVEL 3'!I27 -> 0 | T24: ='LEVEL 3'!J27 -> 2500 | U24: ='LEVEL 3'!K27 -> 2500 | X24: =U24-L24 -> 0 | Z24: =IF(L24=0,0,X24/L24) -> 0
A25: Pump House Concrete | D25: =V25-C25 -> 0 | F25: Torrey Pines | G25: SF | H25: 300 | I25: 11.99 | K25: 11.99 | L25: ='LEVEL 2 (Match)'!K28 -> 3597 | O25: Torrey Pines | P25: ='LEVEL 3'!F28 -> SF | Q25: ='LEVEL 3'!G28 -> 300 | R25: ='LEVEL 3'!H28 -> 11.99 | S25: ='LEVEL 3'!I28 -> 0 | T25: ='LEVEL 3'!J28 -> 11.99 | U25: ='LEVEL 3'!K28 -> 3597 | X25: =U25-L25 -> 0 | Z25: =IF(L25=0,0,X25/L25) -> 0
A26: Trash Enclosure Concrete | D26: =V26-C26 -> 0 | F26: Allowance | G26: SF | H26: 920 | I26: 11.99 | J26: 0 | K26: 11.99 | L26: ='LEVEL 2 (Match)'!K29 -> 11030.8 | O26: Allowance | P26: ='LEVEL 3'!F29 -> SF | Q26: ='LEVEL 3'!G29 -> 920 | R26: ='LEVEL 3'!H29 -> 11.99 | S26: ='LEVEL 3'!I29 -> 0 | T26: ='LEVEL 3'!J29 -> 11.99 | U26: ='LEVEL 3'!K29 -> 11030.8 | X26: =U26-L26 -> 0 | Z26: =IF(L26=0,0,X26/L26) -> 0
A27: Pool Area Shower Concrete | D27: =V27-C27 -> 0 | F27: Torrey Pines | G27: LS | H27: 1 | I27: 2500 | J27: 0 | K27: 2500 | L27: ='LEVEL 2 (Match)'!K30 -> 2500 | O27: Torrey Pines | P27: ='LEVEL 3'!F30 -> LS | Q27: ='LEVEL 3'!G30 -> 1 | R27: ='LEVEL 3'!H30 -> 2500 | S27: ='LEVEL 3'!I30 -> 0 | T27: ='LEVEL 3'!J30 -> 2500 | U27: ='LEVEL 3'!K30 -> 2500 | X27: =U27-L27 -> 0 | Z27: =IF(L27=0,0,X27/L27) -> 0
A28: Cabana Concrete | D28: =V28-C28 -> 0 | F28: N/A | K28: 0 | L28: ='LEVEL 2 (Match)'!K31 -> 0 | O28: N/A | P28: ='LEVEL 3'!F31 -> 0 | Q28: ='LEVEL 3'!G31 -> 0 | R28: ='LEVEL 3'!H31 -> 0 | S28: ='LEVEL 3'!I31 -> 0 | T28: ='LEVEL 3'!J31 -> 0 | U28: ='LEVEL 3'!K31 -> 0 | X28: =U28-L28 -> 0 | Z28: =IF(L28=0,0,X28/L28) -> 0
A29: Pool Equipment Foundation | D29: =V29-C29 -> 0 | F29: N/A | K29: 0 | L29: ='LEVEL 2 (Match)'!K32 -> 0 | O29: N/A | P29: ='LEVEL 3'!F32 -> 0 | Q29: ='LEVEL 3'!G32 -> 0 | R29: ='LEVEL 3'!H32 -> 0 | S29: ='LEVEL 3'!I32 -> 0 | T29: ='LEVEL 3'!J32 -> 0 | U29: ='LEVEL 3'!K32 -> 0 | X29: =U29-L29 -> 0 | Z29: =IF(L29=0,0,X29/L29) -> 0
A30: Lightweight Concrete | D30: =V30-C30 -> 0 | F30: Torrey Pines | G30: SF | H30: 147250 | I30: 2.94 | J30: 0 | K30: 2.94 | L30: ='LEVEL 2 (Match)'!K33 -> 432915 | O30: Torrey Pines | P30: ='LEVEL 3'!F33 -> SF | Q30: ='LEVEL 3'!G33 -> 147250 | R30: ='LEVEL 3'!H33 -> 2.94 | S30: ='LEVEL 3'!I33 -> 0 | T30: ='LEVEL 3'!J33 -> 2.94 | U30: ='LEVEL 3'!K33 -> 432915 | X30: =U30-L30 -> 0 | Z30: =IF(L30=0,0,X30/L30) -> 0
A31: Deck Concrete | D31: =V31-C31 -> 0 | F31: Torrey Pines | G31: SF | H31: 3024 | I31: 19.76 | J31: 0 | K31: 19.76 | L31: ='LEVEL 2 (Match)'!K34 -> 59754.24 | O31: Torrey Pines | P31: ='LEVEL 3'!F34 -> SF | Q31: ='LEVEL 3'!G34 -> 3024 | R31: ='LEVEL 3'!H34 -> 19.76 | S31: ='LEVEL 3'!I34 -> 0 | T31: ='LEVEL 3'!J34 -> 19.76 | U31: ='LEVEL 3'!K34 -> 59754.24 | X31: =U31-L31 -> 0 | Z31: =IF(L31=0,0,X31/L31) -> 0
A32: Concrete | C32: 1082096 | D32: =V32-C32 -> 7183.85 | M32: =SUM(L22:L31) -> 1089279.8 | V32: ='LEVEL 3'!L24 -> 1089279.8 | X32: =V32-M32 -> 0 | Z32: =IF(M32=0,0,X32/M32) -> 0
A33: Elevator Shaft | D33: =V33-C33 -> 0 | F33: Torrey Pines | G33: Stop | H33: 8 | I33: 9500 | J33: 0 | K33: 9500 | L33: 76000 | O33: Torrey Pines | P33: ='LEVEL 3'!F45 -> Stop | Q33: ='LEVEL 3'!G45 -> 8 | R33: ='LEVEL 3'!H45 -> 9500 | S33: ='LEVEL 3'!I45 -> 0 | T33: ='LEVEL 3'!J45 -> 9500 | U33: ='LEVEL 3'!K45 -> 76000 | X33: =U33-L33 -> 0 | Z33: =IF(L33=0,0,X33/L33) -> 0
A34: Trash Enclosure | D34: =V34-C34 -> 0 | F34: Torrey Pines | G34: Count | H34: 4 | I34: 5700 | J34: 0 | K34: 5700 | L34: 22800 | O34: Torrey Pines | P34: ='LEVEL 3'!F46 -> Count | Q34: ='LEVEL 3'!G46 -> 4 | R34: ='LEVEL 3'!H46 -> 5700 | S34: ='LEVEL 3'!I46 -> 0 | T34: ='LEVEL 3'!J46 -> 5700 | U34: ='LEVEL 3'!K46 -> 22800 | X34: =U34-L34 -> 0 | Z34: =IF(L34=0,0,X34/L34) -> 0
A35: Masonry Veneer | D35: =V35-C35 -> 0 | F35: N/A | I35: 0 | K35: 0 | L35: 0 | O35: N/A | P35: ='LEVEL 3'!F47 -> 0 | Q35: ='LEVEL 3'!G47 -> 0 | R35: ='LEVEL 3'!H47 -> 0 | S35: ='LEVEL 3'!I47 -> 0 | T35: ='LEVEL 3'!J47 -> 0 | U35: ='LEVEL 3'!K47 -> 0 | X35: =U35-L35 -> 0 | Z35: =IF(L35=0,0,X35/L35) -> 0
A36: Masonry Veneer Pool Area | D36: =V36-C36 -> 0 | F36: Allowance | G36: LS | H36: 1 | I36: 5000 | J36: 0 | K36: 5000 | L36: 5000 | O36: Allowance | P36: ='LEVEL 3'!F48 -> LS | Q36: ='LEVEL 3'!G48 -> 1 | R36: ='LEVEL 3'!H48 -> 5000 | S36: ='LEVEL 3'!I48 -> 0 | T36: ='LEVEL 3'!J48 -> 5000 | U36: ='LEVEL 3'!K48 -> 5000 | X36: =U36-L36 -> 0 | Z36: =IF(L36=0,0,X36/L36) -> 0
A37: Pool Eq. Shower Stone | D37: =V37-C37 -> 0 | F37: Torrey Pines | G37: LS | H37: 1 | I37: 9000 | J37: 0 | K37: 9000 | L37: 9000 | O37: Torrey Pines | P37: ='LEVEL 3'!F49 -> LS | Q37: ='LEVEL 3'!G49 -> 1 | R37: ='LEVEL 3'!H49 -> 9000 | S37: ='LEVEL 3'!I49 -> 0 | T37: ='LEVEL 3'!J49 -> 9000 | U37: ='LEVEL 3'!K49 -> 9000 | X37: =U37-L37 -> 0 | Z37: =IF(L37=0,0,X37/L37) -> 0
A38: Masonry | C38: 115440 | D38: =V38-C38 -> -2640 | M38: =SUM(L33:L37) -> 112800 | V38: ='LEVEL 3'!L44 -> 112800 | X38: =V38-M38 -> 0 | Z38: =IF(M38=0,0,X38/M38) -> 0
A39: Structural Steel | D39: =V39-C39 -> 0 | F39: Torrey Pines | G39: LBS | H39: 31706.95 | I39: 3.5584037 | J39: 0 | K39: 3.5584037 | L39: 112826.13 | O39: Torrey Pines | P39: ='LEVEL 3'!F51 -> LBS | Q39: ='LEVEL 3'!G51 -> 31706.95 | R39: ='LEVEL 3'!H51 -> 3.5584037 | S39: ='LEVEL 3'!I51 -> 0 | T39: ='LEVEL 3'!J51 -> 3.5584037 | U39: ='LEVEL 3'!K51 -> 112826.13 | X39: =U39-L39 -> 0 | Z39: =IF(L39=0,0,X39/L39) -> 0
A40: Elevator Shaft Iron | D40: =V40-C40 -> 0 | F40: Torrey Pines | G40: Count | H40: 2 | I40: 4040 | J40: 0 | K40: 4040 | L40: 8080 | O40: Torrey Pines | P40: ='LEVEL 3'!F52 -> Count | Q40: ='LEVEL 3'!G52 -> 2 | R40: ='LEVEL 3'!H52 -> 4040 | S40: ='LEVEL 3'!I52 -> 0 | T40: ='LEVEL 3'!J52 -> 4040 | U40: ='LEVEL 3'!K52 -> 8080 | X40: =U40-L40 -> 0 | Z40: =IF(L40=0,0,X40/L40) -> 0
...

Sheet Comparison to Other
H1: SENIOR / AFFORABLE PROJECTS
C2: Bruner Senior | H2: South Nellis | I2: Torrey Pines | J2: Decatur | K2: Pebble
E3: Units | F3: ='LEVEL 3'!E8 -> 194 | H3: 50 | I3: 190 | J3: 276 | K3: 195
A4: Budget | E4: GSF | F4: ='LEVEL 3'!B8 -> 196289 | H4: 34388 | I4: 188825 | J4: 258464 | K4: 184108
A5: Proposal/Contract | E5: Acres | F5: ='LEVEL 3'!B9 -> 4.9 | H5: 1.3 | I5: 5 | J5: 9.45 | K5: 5
E6: Site SF | F6: =F5*43560 -> 213444 | H6: =H5*43560 -> 56628 | I6: =I5*43560 -> 217800 | J6: 411642 | K6: 217800
A7: Description | B7: % | C7: Cost | D7: UOM | E7: U | F7: PU | H7: PU | I7: PU | J7: PU | K7: PU
A8: Framing | B8: =C8/$C$29 -> 0.11971688 | C8: =VLOOKUP(A8,'LEVEL 3'!$A$21:$K$330,11,FALSE) -> 4008924.5 | D8: SF | E8: =$F$4 -> 196289 | F8: =C8/E8 -> 20.423582 | H8: 20.075375 | I8: 19.921525 | J8: 22.888453 | K8: =3500080/$K$4 -> 19.011015
A9: HVAC Standard | B9: =C9/$C$29 -> 0.061570769 | C9: =VLOOKUP(A9,'LEVEL 3'!$A$21:$K$330,11,FALSE) -> 2061802.6 | D9: Unit | E9: =$F$3 -> 194 | F9: =C9/E9 -> 10627.848 | H9: 10148.68 | I9: 9739.2737 | J9: 10104.674 | K9: =1797559/$K$3 -> 9218.2513
A10: Electrical | B10: =C10/$C$29 -> 0.057054555 | C10: =VLOOKUP(A10,'LEVEL 3'!$A$21:$K$330,11,FALSE) -> 1910569.4 | D10: SF (Bldg) | E10: =$F$4 -> 196289 | F10: =C10/E10 -> 9.7334513 | H10: 12.504362 | I10: 9.2699537 | J10: 10.176018 | K10: =2234019.82/$K$4 -> 12.13429
A11: Drywall | B11: =C11/$C$29 -> 0.046906301 | C11: =VLOOKUP(A11,'LEVEL 3'!$A$21:$K$330,11,FALSE) -> 1570737.8 | D11: SF (Bldg) | E11: =$F$4 -> 196289 | F11: =C11/E11 -> 8.0021691 | H11: 7.7384864 | I11: 8.0157077 | J11: 7.3585311 | K11: =1487010/$K$4 -> 8.0768353
A12: 1 Bathroom Unit | B12: =C12/$C$29 -> 0.060952693 | C12: =VLOOKUP(A12,'LEVEL 3'!$A$21:$K$330,11,FALSE) -> 2041105.3 | D12: 1 Bath Unit | E12: =F3 -> 194 | F12: =C12/E12 -> 10521.161 | H12: 10196.24 | I12: 10526.311 | J12: 11042.514 | K12: =1959791/$K$3 -> 10050.21
A13: Appliances | B13: =C13/$C$29 -> 0.018547372 | C13: =VLOOKUP(A13,'LEVEL 3'!$A$21:$K$330,11,FALSE) -> 621090.5 | D13: Unit | E13: =$F$3 -> 194 | F13: =C13/E13 -> 3201.4974 | H13: 4007.85 | I13: 2926 | J13: 3454.4783 | K13: 3201.4974
A14: Sprinkler System | B14: =C14/$C$29 -> 0.014361161 | C14: =VLOOKUP(A14,'LEVEL 3'!$A$21:$K$330,11,FALSE) -> 480908.05 | D14: SF (Bldg) | E14: =$F$4 -> 196289 | F14: =C14/E14 -> 2.45 | H14: 3.2147842 | I14: 2.453065 | J14: =644184/$J$4 -> 2.4923548 | K14: 2.4480196
A15: Cabinets Units | B15: =C15/$C$29 -> 0.018237443 | C15: =VLOOKUP(A15,'LEVEL 3'!$A$21:$K$330,11,FALSE) -> 610712 | D15: Unit | E15: =$F$3 -> 194 | F15: =C15/E15 -> 3148 | H15: 1330 | I15: 3778.0053 | J15: 3651.0797 | K15: =607178/$K$3 -> 3113.7333
A16: Windows and Sliding Glass Doors | B16: =C16/$C$29 -> 0.0067080811 | C16: =VLOOKUP(A16,'LEVEL 3'!$A$21:$K$330,11,FALSE) -> 224631.58 | D16: Unit | E16: =$F$3 -> 194 | F16: =C16/E16 -> 1157.8947 | H16: 1647.191 | I16: =220000/I3 -> 1157.8947 | J16: =388836/$J$3 -> 1408.8261 | K16: =144157.93/$K$3 -> 739.27144
A17: Finish Carpentry - Units | B17: =C17/$C$29 -> 0.018360865 | C17: =VLOOKUP(A17,'LEVEL 3'!$A$21:$K$330,11,FALSE) -> 614845 | D17: Unit | E17: =$F$3 -> 194 | F17: =C17/E17 -> 3169.3041 | H17: 3036 | I17: 3192.5 | J17: 2901.2899 | K17: 3081.2308
A18: Slabs | B18: =C18/$C$29 -> 0.017230201 | C18: =VLOOKUP(A18,'LEVEL 3'!$A$21:$K$330,11,FALSE) -> 576982.78 | D18: SF (Slab) | E18: ='LEVEL 3'!$O$2 -> 48122 | F18: =C18/E18 -> 11.99 | H18: 16.778816 | I18: 11.989967 | J18: 15.882903 | K18: 16.060895
A19: Insulation | B19: =C19/$C$29 -> 0.015751929 | C19: =VLOOKUP(A19,'LEVEL 3'!$A$21:$K$330,11,FALSE) -> 527480.3 | D19: SF (Bldg) | E19: =$F$4 -> 196289 | F19: =C19/E19 -> 2.6872637 | H19: 2.5423113 | I19: 2.6983715 | J19: 2.2715182 | K19: =460480/$K$4 -> 2.5011406
A20: Fire Alarm / Two Way Comm AOR | B20: =C20/$C$29 -> 0.0094103597 | C20: =VLOOKUP(A20,'LEVEL 3'!$A$21:$K$330,11,FALSE) -> 315122 | D20: Unit | E20: =$F$3 -> 194 | F20: =C20/E20 -> 1624.3402 | H20: =2.27404908689078*H4/H3 -> 1564 | I20: 1662.7789 | J20: 2101 | K20: 1466.6667
A21: Site Landscaping | B21: =C21/$C$29 -> 0.020004507 | C21: =VLOOKUP(A21,'LEVEL 3'!$A$21:$K$330,11,FALSE) -> 669885.17 | D21: SF | E21: ='LEVEL 3'!G256 -> 39274 | F21: =C21/$E$21 -> 17.056708 | H21: 10.527712 | I21: 15.584553 | J21: 16.652199 | K21: 21.389001
A22: Stucco | B22: =C22/$C$29 -> 0.01441335 | C22: =VLOOKUP(A22,'LEVEL 3'!$A$21:$K$330,11,FALSE) -> 482655.68 | D22: SY (Bldg) | E22: ='LEVEL 3'!$G$107 -> 11824 | F22: =C22/E22 -> 40.82 | H22: 39.371016 | I22: 40.818674 | J22: 42.234692 | K22: 46.688382
A23: Counter Tops Units | B23: =C23/$C$29 -> 0.0090816491 | C23: =VLOOKUP(A23,'LEVEL 3'!$A$21:$K$330,11,FALSE) -> 304114.56 | D23: Unit | E23: =$F$3 -> 194 | F23: =C23/E23 -> 1567.6008 | H23: 754 | I23: 1628.8895 | J23: 1551.7283 | K23: 1600.2513
A24: Lightweight Concrete | B24: =C24/$C$29 -> 0.012927964 | C24: =VLOOKUP(A24,'LEVEL 3'!$A$21:$K$330,11,FALSE) -> 432915 | D24: SF (No Slab) | E24: ='LEVEL 3'!$G$33 -> 147250 | F24: =C24/E24 -> 2.94 | H24: 2.9324031 | I24: 2.9421304 | J24: 1.2965678 | K24: 1.1
A25: Pools and Spas | B25: =C25/$C$29 -> 0.007316335 | C25: =VLOOKUP(A25,'LEVEL 3'!$A$21:$K$330,11,FALSE) -> 245000 | D25: LS | E25: 1 | F25: =C25/E25 -> 245000 | H25: N/A | I25: 245000 | J25: 228710 | K25: 208310
A26: Painting | B26: =C26/$C$29 -> 0.010755662 | C26: =VLOOKUP(A26,'LEVEL 3'!$A$21:$K$330,11,FALSE) -> 360171.76 | D26: SF (Bldg) | E26: =$F$4 -> 196289 | F26: =C26/E26 -> 1.8349055 | H26: 2.0533616 | I26: 1.8370925 | J26: 2.0978638 | K26: =355696/$K$4 -> 1.9319964
A27: Roofing | B27: =C27/$C$29 -> 0.0090689374 | C27: =VLOOKUP(A27,'LEVEL 3'!$A$21:$K$330,11,FALSE) -> 303688.89 | D27: Square | E27: ='LEVEL 3'!$O$10 -> 503.63 | F27: =C27/E27 -> 603 | H27: 491.39689 | I27: 603.3984 | J27: 598.38652 | K27: 535.7424
A28: Fire Pump | B28: =C28/$C$29 -> 0.0039717247 | C28: =VLOOKUP(A28,'LEVEL 3'!$A$21:$K$330,11,FALSE) -> 133000 | D28: Unit | E28: =$F$3 -> 194 | F28: =C28/E28 -> 685.56701 | H28: N/A | I28: =133300/$I$3 -> 701.57895 | J28: =113160/$J$3 -> 410 | K28: =120800/$K$3 -> 619.48718
A29: Total Hard Costs | C29: ='LEVEL 3'!$L$335 -> 33486712 | D29: GSF | E29: =$F$4 -> 196289 | F29: =C29/E29 -> 170.59902

Sheet Sheet3
A2: Carports Budget
A4: 116 Total Carports
A6: Item | B6: Source | C6: Unit | D6: Qty | E6: Unit Cost | F6: Total
A7: Carport Non Solar | B7: Pebble | C7: EA | D7: =130-D8 -> 91 | E7: 2064 | F7: =D7*E7 -> 187824
A8: Carport Solar (30% of Total Spaces) | B8: Pebble | C8: EA | D8: =130*0.3 -> 39 | E8: 2623 | F8: =D8*E8 -> 102297
A9: Hard Dig (50% * Unit Cost) | B9: Pebble | C9: EA | D9: =SUM($D$7:$D$8)/2 -> 65 | E9: 250 | F9: =D9*E9 -> 16250
A10: Spoil Removal ($75 per Space) | B10: Pebble | C10: EA | D10: 130 | E10: 75 | F10: =D10*E10 -> 9750
A11: Permit | B11: Pebble | C11: LS | D11: 1 | E11: 1815 | F11: =D11*E11 -> 1815
A12: QAA | B12: Pebble | C12: LS | D12: 1 | E12: 2500 | F12: =D12*E12 -> 2500
F13: =SUM(F7:F12) -> 320436

Sheet Comparison to Previous (Match)
A1: BRUNER SENIOR | C1: LEVEL 1 | L1: LEVEL 2
C2: Project Details | H2: Unit Breakdown | L2: Project Details | Q2: Unit Breakdown
C3: Project | D3: Bruner Senior | H3: Unit Type | I3: Number | J3: % | L3: Project | M3: Bruner Senior | Q3: Unit Type | R3: Number | S3: %
C4: Budget Level | D4: Level 1 | H4: Studios | I4: 0 | J4: =I4/$I$9 -> 0 | L4: Budget Level | M4: Level 2 | Q4: Studios | R4: 0 | S4: =R4/$R$9 -> 0
C5: Product | D5: Senior | H5: 1 Br - 1 Ba | I5: 126 | J5: =I5/$I$9 -> 0.64948454 | L5: Product | M5: Senior | Q5: 1 Br - 1 Ba | R5: 126 | S5: =R5/$R$9 -> 0.64948454
C6: Start Date | D6: 45809 | H6: 2 Br - 1 Ba | I6: 68 | J6: =I6/$I$9 -> 0.35051546 | L6: Start Date | M6: 45809 | Q6: 2 Br - 1 Ba | R6: 68 | S6: =R6/$R$9 -> 0.35051546
C7: Timeline | D7: 20 | H7: 2 Br - 2 Ba | I7: 0 | J7: =I7/$I$9 -> 0 | L7: Timeline | M7: 20 | Q7: 2 Br - 2 Ba | R7: 0 | S7: =R7/$R$9 -> 0
C8: Floors | D8: 4 | H8: 3 Br - 2 Ba | I8: 0 | J8: =I8/$I$9 -> 0 | L8: Floors | M8: 4 | Q8: 3 Br - 2 Ba | R8: 0 | S8: =R8/$R$9 -> 0
C9: Bldg. SF | D9: 196333 | H9: Totals | I9: 194 | J9: =I9/$I$9 -> 1 | L9: Bldg. SF | M9: 196289 | Q9: Totals | R9: =SUM(R4:R8) -> 194 | S9: =R9/$R$9 -> 1
C10: Acres | D10: 4.9 | H10: Parking | L10: Acres | M10: 4.9 | Q10: Parking
C11: Site SF | D11: =D10*43560 -> 213444 | H11: Garage Parking | J11: 0 | L11: Site SF | M11: =M10*43560 -> 213444 | Q11: Cover Parking | S11: 127
C12: Buildings | D12: 1 | H12: Cover Parking | J12: 116 | L12: Buildings | M12: 1 | Q12: Cover Acc. Parking | S12: 3
H13: Open Parking | J13: 83 | Q13: Open Parking | S13: 45
H14: Accessible Parking | J14: 6 | N14: Net Change | Q14: Accessible Parking | S14: 11
C15: TOTAL COST | D15: =J330 -> 33916915 | H15: Private Garages | J15: 0 | L15: TOTAL COST | M15: =S330 -> 33460484 | N15: =M15-D15 -> -456430.63 | O15: =N15/D15 -> -0.013457316 | Q15: Waiver | S15: 8
C16: PER UNIT | D16: =D15/I9 -> 174829.46 | H16: Total Parking Provided | J16: =SUM(J11:J15) -> 205 | L16: PER UNIT | M16: =M15/R9 -> 172476.72 | N16: =M16-D16 -> -2352.7352 | Q16: Total Parking Provided | S16: =SUM(S11:S15) -> 194
C17: PER GSF | D17: =D15/D9 -> 172.75198 | H17: Parking Ratio | J17: =SUM(J11:J14)/I9 -> 1.056701 | L17: PER GSF | M17: =M15/M9 -> 170.46541 | N17: =M17-D17 -> -2.2865751 | Q17: Parking Ratio | S17: =SUM(S11:S14)/R9 -> 0.95876289 | U17: Conditions | W17: Conditions
U18: 50000 | W18: 0.05
A19: Description | C19: Source | D19: UOM | E19: QTY | F19: U.P. | G19: % | H19: Total U.P. | I19: Sub Total | J19: Total | L19: Source | M19: UOM | N19: QTY | O19: U.P. | P19: % | Q19: Total U.P. | R19: Sub Total | S19: Total | U19: PV$ | W19: PV% | Y19: Notes
A20: General Requirements | J20: 1700096 | S20: ='LEVEL 2 (Match)'!L20 -> 1692096 | U20: =S20-J20 -> -8000 | W20: =IF(J20=0,0,U20/J20) -> -0.0047056166
A21: General Requirement | D21: Mo | E21: 20 | F21: 83690.146 | G21: 0 | H21: 83690.146 | I21: 1673802.9 | M21: ='LEVEL 3'!F21 -> Mo | N21: ='LEVEL 3'!G21 -> 20 | O21: ='LEVEL 2 (Match)'!H21 -> 84604.8 | P21: ='LEVEL 2 (Match)'!I21 -> 0 | Q21: ='LEVEL 2 (Match)'!J21 -> 84604.8 | R21: ='LEVEL 2 (Match)'!K21 -> 1692096 | U21: =R21-I21 -> 18293.075 | W21: =U21/I21 -> 0.010929049
A22: Existing Conditions | J22: 3500 | S22: ='LEVEL 3'!L22 -> 3500 | U22: =S22-J22 -> 0 | W22: =IF(J22=0,0,U22/J22) -> 0
A23: Potholing | C23: Allowance | E23: 1 | F23: 3500 | G23: 0 | H23: 3500 | I23: 3500 | L23: Allowance | M23: ='LEVEL 3'!F23 -> 0 | N23: ='LEVEL 3'!G23 -> 1 | O23: ='LEVEL 3'!H23 -> 3500 | P23: ='LEVEL 3'!I23 -> 0 | Q23: ='LEVEL 3'!J23 -> 3500 | R23: ='LEVEL 3'!K23 -> 3500 | U23: =R23-I23 -> 0 | W23: =IF(I23=0,0,U23/I23) -> 0
A24: Concrete | J24: 1159855 | S24: ='LEVEL 3'!L24 -> 1089279.8 | U24: =S24-J24 -> -70575.18 | W24: =IF(J24=0,0,U24/J24) -> -0.060848278
A25: Slabs | C25: Torrey Pines | D25: SF | E25: 47527 | F25: =H25/(1+G25) -> 11.990476 | G25: 0.05 | H25: 12.59 | I25: 598341.17 | L25: Torrey Pines | M25: ='LEVEL 3'!F25 -> SF | N25: ='LEVEL 3'!G25 -> 48122 | O25: ='LEVEL 3'!H25 -> 11.99 | P25: ='LEVEL 3'!I25 -> 0 | Q25: ='LEVEL 3'!J25 -> 11.99 | R25: ='LEVEL 3'!K25 -> 576982.78 | U25: =R25-I25 -> -21358.39 | W25: =IF(I25=0,0,U25/I25) -> -0.035696006
A26: Deepened Footings | C26: N/A | H26: 0 | I26: 0 | L26: N/A | M26: ='LEVEL 3'!F26 -> 0 | N26: ='LEVEL 3'!G26 -> 0 | O26: ='LEVEL 3'!H26 -> 0 | P26: ='LEVEL 3'!I26 -> 0 | Q26: ='LEVEL 3'!J26 -> 0 | R26: ='LEVEL 3'!K26 -> 0 | U26: =R26-I26 -> 0 | W26: =IF(I26=0,0,U26/I26) -> 0
A27: Concrete Slab Repairs | C27: Allowance | D27: LS | E27: 1 | F27: 2500 | G27: 0 | H27: 2500 | I27: 2500 | L27: Allowance | M27: ='LEVEL 3'!F27 -> LS | N27: ='LEVEL 3'!G27 -> 1 | O27: ='LEVEL 3'!H27 -> 2500 | P27: ='LEVEL 3'!I27 -> 0 | Q27: ='LEVEL 3'!J27 -> 2500 | R27: ='LEVEL 3'!K27 -> 2500 | U27: =R27-I27 -> 0 | W27: =IF(I27=0,0,U27/I27) -> 0
A28: Pump House Concrete | C28: Torrey Pines | D28: SF | E28: 300 | F28: 12.62 | H28: 12.62 | I28: 3786 | L28: Torrey Pines | M28: ='LEVEL 3'!F28 -> SF | N28: ='LEVEL 3'!G28 -> 300 | O28: ='LEVEL 3'!H28 -> 11.99 | P28: ='LEVEL 3'!I28 -> 0 | Q28: ='LEVEL 3'!J28 -> 11.99 | R28: ='LEVEL 3'!K28 -> 3597 | U28: =R28-I28 -> -189 | W28: =IF(I28=0,0,U28/I28) -> -0.049920761
A29: Trash Enclosure Concrete | C29: Russell IV | D29: Count | E29: 4 | F29: 2698 | G29: 0 | H29: 2698 | I29: 10792 | L29: Allowance | M29: ='LEVEL 3'!F29 -> SF | N29: ='LEVEL 3'!G29 -> 920 | O29: ='LEVEL 3'!H29 -> 11.99 | P29: ='LEVEL 3'!I29 -> 0 | Q29: ='LEVEL 3'!J29 -> 11.99 | R29: ='LEVEL 3'!K29 -> 11030.8 | U29: =R29-I29 -> 238.8 | W29: =IF(I29=0,0,U29/I29) -> 0.022127502
A30: Pool Area Shower Concrete | C30: Torrey Pines | D30: LS | E30: 1 | F30: 2500 | G30: 0 | H30: 2500 | I30: 2500 | L30: Torrey Pines | M30: ='LEVEL 3'!F30 -> LS | N30: ='LEVEL 3'!G30 -> 1 | O30: ='LEVEL 3'!H30 -> 2500 | P30: ='LEVEL 3'!I30 -> 0 | Q30: ='LEVEL 3'!J30 -> 2500 | R30: ='LEVEL 3'!K30 -> 2500 | U30: =R30-I30 -> 0 | W30: =IF(I30=0,0,U30/I30) -> 0
A31: Cabana Concrete | C31: N/A | H31: 0 | I31: 0 | L31: N/A | M31: ='LEVEL 3'!F31 -> 0 | N31: ='LEVEL 3'!G31 -> 0 | O31: ='LEVEL 3'!H31 -> 0 | P31: ='LEVEL 3'!I31 -> 0 | Q31: ='LEVEL 3'!J31 -> 0 | R31: ='LEVEL 3'!K31 -> 0 | U31: =R31-I31 -> 0 | W31: =IF(I31=0,0,U31/I31) -> 0
A32: Pool Equipment Foundation | C32: N/A | H32: 0 | I32: 0 | L32: N/A | M32: ='LEVEL 3'!F32 -> 0 | N32: ='LEVEL 3'!G32 -> 0 | O32: ='LEVEL 3'!H32 -> 0 | P32: ='LEVEL 3'!I32 -> 0 | Q32: ='LEVEL 3'!J32 -> 0 | R32: ='LEVEL 3'!K32 -> 0 | U32: =R32-I32 -> 0 | W32: =IF(I32=0,0,U32/I32) -> 0
A33: Lightweight Concrete | C33: Torrey Pines | D33: SF | E33: 147250 | F33: 2.94 | G33: 0.1 | H33: 323 | I33: 476205.69 | L33: Torrey Pines | M33: ='LEVEL 3'!F33 -> SF | N33: ='LEVEL 3'!G33 -> 147250 | O33: ='LEVEL 3'!H33 -> 2.94 | P33: ='LEVEL 3'!I33 -> 0 | Q33: ='LEVEL 3'!J33 -> 2.94 | R33: ='LEVEL 3'!K33 -> 432915 | U33: =R33-I33 -> -43290.69 | W33: =IF(I33=0,0,U33/I33) -> -0.090907545
A34: Deck Concrete | C34: Torrey Pines | D34: SF | E34: 3024 | F34: 19.76 | G34: 0.1 | H34: 21.74 | I34: 65729.66 | L34: Torrey Pines | M34: ='LEVEL 3'!F34 -> SF | N34: ='LEVEL 3'!G34 -> 3024 | O34: ='LEVEL 3'!H34 -> 19.76 | P34: ='LEVEL 3'!I34 -> 0 | Q34: ='LEVEL 3'!J34 -> 19.76 | R34: ='LEVEL 3'!K34 -> 59754.24 | U34: =R34-I34 -> -5975.42 | W34: =IF(I34=0,0,U34/I34) -> -0.090909036
A35: Parking Garage | J35: 0 | S35: ='LEVEL 3'!L35 -> 0 | U35: =S35-J35 -> 0 | W35: =IF(J35=0,0,U35/J35) -> 0
A36: Parking Garage Structure | C36: N/A | H36: 0 | I36: 0 | L36: N/A | M36: ='LEVEL 3'!F36 -> 0 | N36: ='LEVEL 3'!G36 -> 0 | O36: ='LEVEL 3'!H36 -> 0 | P36: ='LEVEL 3'!I36 -> 0 | Q36: ='LEVEL 3'!J36 -> 0 | R36: ='LEVEL 3'!K36 -> 0 | U36: =R36-I36 -> 0 | W36: =IF(I36=0,0,U36/I36) -> 0
A37: Core Slab Precast Concrete | C37: N/A | H37: 0 | I37: 0 | L37: N/A | M37: ='LEVEL 3'!F37 -> 0 | N37: ='LEVEL 3'!G37 -> 0 | O37: ='LEVEL 3'!H37 -> 0 | P37: ='LEVEL 3'!I37 -> 0 | Q37: ='LEVEL 3'!J37 -> 0 | R37: ='LEVEL 3'!K37 -> 0 | U37: =R37-I37 -> 0 | W37: =IF(I37=0,0,U37/I37) -> 0
A38: Concrete Slab on Grade | C38: N/A | H38: 0 | I38: 0 | L38: N/A | M38: ='LEVEL 3'!F38 -> 0 | N38: ='LEVEL 3'!G38 -> 0 | O38: ='LEVEL 3'!H38 -> 0 | P38: ='LEVEL 3'!I38 -> 0 | Q38: ='LEVEL 3'!J38 -> 0 | R38: ='LEVEL 3'!K38 -> 0 | U38: =R38-I38 -> 0 | W38: =IF(I38=0,0,U38/I38) -> 0
A39: Concrete Topping Slab 4" / Level | C39: N/A | H39: 0 | I39: 0 | L39: N/A | M39: ='LEVEL 3'!F39 -> 0 | N39: ='LEVEL 3'!G39 -> 0 | O39: ='LEVEL 3'!H39 -> 0 | P39: ='LEVEL 3'!I39 -> 0 | Q39: ='LEVEL 3'!J39 -> 0 | R39: ='LEVEL 3'!K39 -> 0 | U39: =R39-I39 -> 0 | W39: =IF(I39=0,0,U39/I39) -> 0
A40: Electrical | C40: N/A | H40: 0 | I40: 0 | L40: N/A | M40: ='LEVEL 3'!F40 -> 0 | N40: ='LEVEL 3'!G40 -> 0 | O40: ='LEVEL 3'!H40 -> 0 | P40: ='LEVEL 3'!I40 -> 0 | Q40: ='LEVEL 3'!J40 -> 0 | R40: ='LEVEL 3'!K40 -> 0 | U40: =R40-I40 -> 0 | W40: =IF(I40=0,0,U40/I40) -> 0
...

Sheet Sheet1
E2: Unit | F2: ='LEVEL 3'!E8 -> 194 | H2: Building GSF | I2: ='LEVEL 3'!B8 -> 196289
A3: Description | B3: Ovation (Level 1) | C3: Zebel | E3: Ovation (Level 1) | F3: Zebel | H3: Ovation (Level 1) | I3: Zebel
A4: General Requirements | B4: 2175943.9 | C4: 2708450 | E4: =B4/$F$2 -> 11216.206 | F4: =C4/$F$2 -> 13961.082 | H4: =B4/$I$2 -> 11.085409 | I4: =C4/$I$2 -> 13.798277
A5: Existing Conditions | B5: 12000 | C5: 17374 | E5: =B5/$F$2 -> 61.85567 | F5: =C5/$F$2 -> 89.556701 | H5: =B5/$I$2 -> 0.061134348 | I5: =C5/$I$2 -> 0.088512347
A6: Concrete | B6: 2933768.7 | C6: 2862222 | E6: =B6/$F$2 -> 15122.519 | F6: =C6/$F$2 -> 14753.722 | H6: =B6/$I$2 -> 14.94617 | I6: =C6/$I$2 -> 14.581673
A7: Masonry | B7: 205500 | C7: 365194 | E7: =B7/$F$2 -> 1059.2784 | F7: =C7/$F$2 -> 1882.4433 | H7: =B7/$I$2 -> 1.0469257 | I7: =C7/$I$2 -> 1.8604914
A8: Metals | B8: 526095.76 | C8: 438859 | E8: =B8/$F$2 -> 2711.8338 | F8: =C8/$F$2 -> 2262.1598 | H8: =B8/$I$2 -> 2.6802101 | I8: =C8/$I$2 -> 2.2357799
A9: Wood, Plastics, & Composites | B9: 10813331 | C9: 11191767 | E9: =B9/$F$2 -> 55738.819 | F9: =C9/$F$2 -> 57689.521 | H9: =B9/$I$2 -> 55.088828 | I9: =C9/$I$2 -> 57.016781
A10: Thermal & Moisture Protection | B10: 2357905.8 | C10: 2147257 | E10: =B10/$F$2 -> 12154.154 | F10: =C10/$F$2 -> 11068.335 | H10: =B10/$I$2 -> 12.012419 | I10: =C10/$I$2 -> 10.939263
A11: Openings | B11: 648077.1 | C11: 968281 | E11: =B11/$F$2 -> 3340.6036 | F11: =C11/$F$2 -> 4991.1392 | H11: =B11/$I$2 -> 3.3016476 | I11: =C11/$I$2 -> 4.9329356
A12: Finishes | B12: 7174763.2 | C12: 7630096 | E12: =B12/$F$2 -> 36983.315 | F12: =C12/$F$2 -> 39330.392 | H12: =B12/$I$2 -> 36.552039 | I12: =C12/$I$2 -> 38.871745
A13: Specialties | B13: 582625.36 | C13: 422978 | E13: =B13/$F$2 -> 3003.2235 | F13: =C13/$F$2 -> 2180.299 | H13: =B13/$I$2 -> 2.9682018 | I13: =C13/$I$2 -> 2.1548737
A14: Equipment | B14: 1290418 | C14: 1608724 | E14: =B14/$F$2 -> 6651.6392 | F14: =C14/$F$2 -> 8292.3918 | H14: =B14/$I$2 -> 6.5740719 | I14: =C14/$I$2 -> 8.195691
A15: Furnishings | B15: 1990135.6 | C15: 4165522 | E15: =B15/$F$2 -> 10258.431 | F15: =C15/$F$2 -> 21471.763 | H15: =B15/$I$2 -> 10.138803 | I15: =C15/$I$2 -> 21.221373
... A22: Communications | B22: 260127.49 | C22: 231 | E22: =B22/$F$2 -> 1340.8634 | F22: =C22/$F$2 -> 1.1907216 | H22: =B22/$I$2 -> 1.325227 | I22: =C22/$I$2 -> 0.0011768362
A23: Electronic Safety & Security | B23: 1177692 | E23: =B23/$F$2 -> 6070.5773 | F23: =C23/$F$2 -> 0 | H23: =B23/$I$2 -> 5.999786 | I23: =C23/$I$2 -> 0
A24: Earthwork | B24: 2238333.6 | E24: =B24/$F$2 -> 11537.802 | F24: =C24/$F$2 -> 0 | H24: =B24/$I$2 -> 11.403255 | I24: =C24/$I$2 -> 0
A25: Exterior Improvements | B25: 7660331.2 | E25: =B25/$F$2 -> 39486.243 | F25: =C25/$F$2 -> 0 | H25: =B25/$I$2 -> 39.025779 | I25: =C25/$I$2 -> 0
A26: Utilities | B26: 5948000.1 | E26: =B26/$F$2 -> 30659.794 | F26: =C26/$F$2 -> 0 | H26: =B26/$I$2 -> 30.302259 | I26: =C26/$I$2 -> 0
A27: Transportation | B27: 15000 | E27: =B27/$F$2 -> 77.319588 | F27: =C27/$F$2 -> 0 | H27: =B27/$I$2 -> 0.076417935 | I27: =C27/$I$2 -> 0
A28: Electrical Power Generation | B28: 445775 | E28: =B28/$F$2 -> 2297.8093 | F28: =C28/$F$2 -> 0 | H28: =B28/$I$2 -> 2.2710137 | I28: =C28/$I$2 -> 0
A29: Field Surveys, Staking | B29: 427358.97 | E29: =B29/$F$2 -> 2202.8813 | F29: =C29/$F$2 -> 0 | H29: =B29/$I$2 -> 2.1771927 | I29: =C29/$I$2 -> 0
A30: Bid Risk | B30: 1264427.3 | E30: =B30/$F$2 -> 6517.6667 | F30: =C30/$F$2 -> 0 | H30: =B30/$I$2 -> 6.4416617 | I30: =C30/$I$2 -> 0
A31: FFE | B31: 1498772 | E31: =B31/$F$2 -> 7725.6289 | F31: =C31/$F$2 -> 0 | H31: =B31/$I$2 -> 7.6355374 | I31: =C31/$I$2 -> 0
A32: Construction Contingency | B32: 3333086.9 | E32: =B32/$F$2 -> 17180.86 | F32: =C32/$F$2 -> 0 | H32: =B32/$I$2 -> 16.980508 | I32: =C32/$I$2 -> 0
A33: Sub Bonds | B33: 821877.77 | E33: =B33/$F$2 -> 4236.4834 | F33: =C33/$F$2 -> 0 | H33: =B33/$I$2 -> 4.1870801 | I33: =C33/$I$2 -> 0
A34: GL Insurance | B34: 438231.78 | E34: =B34/$F$2 -> 2258.9267 | F34: =C34/$F$2 -> 0 | H34: =B34/$I$2 -> 2.2325845 | I34: =C34/$I$2 -> 0
... A36: Total Hard Costs | B36: 78574003 | E36: =B36/$F$2 -> 405020.64 | F36: =C36/$F$2 -> 0 | H36: =B36/$I$2 -> 400.29754 | I36: =C36/$I$2 -> 0

Sheet Combined Ph 1 & 2
B1: TOTAL COST | K1: PER UNIT | T1: PER GROSS SQUARE FOOT
B3: Phase 1 | E3: Phase 2 | H3: TOTAL | K3: Phase 1 | N3: Phase 2 | Q3: TOTAL | T3: Phase 1 | W3: Phase 2 | Z3: TOTAL
A4: Description | B4: Sub Total | C4: Total | E4: Sub Total | F4: Total | H4: Sub Total | I4: Total | K4: Sub Total | L4: Total | N4: Sub Total | O4: Total | Q4: Sub Total | R4: Total | T4: Sub Total | U4: Total | W4: Sub Total | X4: Total | Z4: Sub Total | AA4: Total
A5: General Requirements | C5: =B6 -> 2008563.6 | F5: =E6 -> 1674318 | I5: =H6 -> 3682881.6 | L5: =C5/'Scenario 1 - Phase 1'!$E$8 -> 5788.3677 | O5: =F5/'LEVEL 3'!$E$8 -> 8630.5052 | R5: =I5/('Scenario 1 - Phase 1'!$E$8+'LEVEL 3'!$E$8) -> 6807.5445 | U5: =C5/'Scenario 1 - Phase 1'!$B$8 -> 6.4554564 | X5: =F5/'LEVEL 3'!$B$8 -> 8.5298616 | AA5: =I5/('Scenario 1 - Phase 1'!$B$8+'LEVEL 3'!$B$8) -> 7.2578963
A6: General Requirements | B6: ='Scenario 1 - Phase 1'!K21 -> 2008563.6 | E6: ='LEVEL 3'!K21 -> 1674318 | H6: =B6+E6 -> 3682881.6 | K6: =B6/'Scenario 1 - Phase 1'!$E$8 -> 5788.3677 | N6: =E6/'LEVEL 3'!$E$8 -> 8630.5052 | Q6: =H6/('Scenario 1 - Phase 1'!$E$8+'LEVEL 3'!$E$8) -> 6807.5445 | T6: =B6/'Scenario 1 - Phase 1'!$B$8 -> 6.4554564 | W6: =E6/'LEVEL 3'!$B$8 -> 8.5298616 | Z6: =H6/('Scenario 1 - Phase 1'!$B$8+'LEVEL 3'!$B$8) -> 7.2578963
A7: Existing Conditions | C7: =B8 -> 8000 | F7: =E8 -> 3500 | I7: =H8 -> 11500 | L7: =K8 -> 23.054755 | O7: =N8 -> 18.041237 | R7: =Q8 -> 21.256932 | U7: =C7/'Scenario 1 - Phase 1'!$B$8 -> 0.025711733 | X7: =F7/'LEVEL 3'!$B$8 -> 0.017830851 | AA7: =I7/('Scenario 1 - Phase 1'!$B$8+'LEVEL 3'!$B$8) -> 0.02266318
A8: Potholing | B8: ='Scenario 1 - Phase 1'!K23 -> 8000 | E8: ='LEVEL 3'!K23 -> 3500 | H8: =B8+E8 -> 11500 | K8: =B8/'Scenario 1 - Phase 1'!$E$8 -> 23.054755 | N8: =E8/'LEVEL 3'!$E$8 -> 18.041237 | Q8: =H8/('Scenario 1 - Phase 1'!$E$8+'LEVEL 3'!$E$8) -> 21.256932 | T8: =B8/'Scenario 1 - Phase 1'!$B$8 -> 0.025711733 | W8: =E8/'LEVEL 3'!$B$8 -> 0.017830851 | Z8: =H8/('Scenario 1 - Phase 1'!$B$8+'LEVEL 3'!$B$8) -> 0.02266318
A9: Concrete | C9: =SUM(B10:B19) -> 1975170 | F9: =SUM(E10:E19) -> 1089279.8 | I9: =SUM(H10:H19) -> 3064449.8 | L9: =SUM(K10:K19) -> 5692.1326 | O9: =SUM(N10:N19) -> 5614.8444 | R9: =SUM(Q10:Q19) -> 5664.4174 | U9: =C9/'Scenario 1 - Phase 1'!$B$8 -> 6.3481305 | X9: =F9/'LEVEL 3'!$B$8 -> 5.5493676 | AA9: =I9/('Scenario 1 - Phase 1'!$B$8+'LEVEL 3'!$B$8) -> 6.0391459
A10: Slabs | B10: ='Scenario 1 - Phase 1'!K25 -> 1243530.9 | E10: ='LEVEL 3'!K25 -> 576982.78 | H10: =B10+E10 -> 1820513.6 | K10: =B10/'Scenario 1 - Phase 1'!$E$8 -> 3583.6624 | N10: =E10/'LEVEL 3'!$E$8 -> 2974.138 | Q10: =H10/('Scenario 1 - Phase 1'!$E$8+'LEVEL 3'!$E$8) -> 3365.0899 | T10: =B10/'Scenario 1 - Phase 1'!$B$8 -> 3.9966667 | W10: =E10/'LEVEL 3'!$B$8 -> 2.9394555 | Z10: =H10/('Scenario 1 - Phase 1'!$B$8+'LEVEL 3'!$B$8) -> 3.5877068
A11: Deepened Footings | B11: ='Scenario 1 - Phase 1'!K26 -> 0 | E11: ='LEVEL 3'!K26 -> 0 | H11: =B11+E11 -> 0 | K11: =B11/'Scenario 1 - Phase 1'!$E$8 -> 0 | N11: =E11/'LEVEL 3'!$E$8 -> 0 | Q11: =H11/('Scenario 1 - Phase 1'!$E$8+'LEVEL 3'!$E$8) -> 0 | T11: =B11/'Scenario 1 - Phase 1'!$B$8 -> 0 | W11: =E11/'LEVEL 3'!$B$8 -> 0 | Z11: =H11/('Scenario 1 - Phase 1'!$B$8+'LEVEL 3'!$B$8) -> 0
A12: Concrete Slab Repairs | B12: ='Scenario 1 - Phase 1'!K27 -> 7500 | E12: ='LEVEL 3'!K27 -> 2500 | H12: =B12+E12 -> 10000 | K12: =B12/'Scenario 1 - Phase 1'!$E$8 -> 21.613833 | N12: =E12/'LEVEL 3'!$E$8 -> 12.886598 | Q12: =H12/('Scenario 1 - Phase 1'!$E$8+'LEVEL 3'!$E$8) -> 18.484288 | T12: =B12/'Scenario 1 - Phase 1'!$B$8 -> 0.02410475 | W12: =E12/'LEVEL 3'!$B$8 -> 0.012736322 | Z12: =H12/('Scenario 1 - Phase 1'!$B$8+'LEVEL 3'!$B$8) -> 0.019707113
A13: Pump House Concrete | B13: ='Scenario 1 - Phase 1'!K28 -> 3597 | E13: ='LEVEL 3'!K28 -> 3597 | H13: =B13+E13 -> 7194 | K13: =B13/'Scenario 1 - Phase 1'!$E$8 -> 10.365994 | N13: =E13/'LEVEL 3'!$E$8 -> 18.541237 | Q13: =H13/('Scenario 1 - Phase 1'!$E$8+'LEVEL 3'!$E$8) -> 13.297597 | T13: =B13/'Scenario 1 - Phase 1'!$B$8 -> 0.011560638 | W13: =E13/'LEVEL 3'!$B$8 -> 0.018325021 | Z13: =H13/('Scenario 1 - Phase 1'!$B$8+'LEVEL 3'!$B$8) -> 0.014177297
A14: Trash Enclosure Concrete | B14: ='Scenario 1 - Phase 1'!K29 -> 26980 | E14: ='LEVEL 3'!K29 -> 11030.8 | H14: =B14+E14 -> 38010.8 | K14: =B14/'Scenario 1 - Phase 1'!$E$8 -> 77.752161 | N14: =E14/'LEVEL 3'!$E$8 -> 56.859794 | Q14: =H14/('Scenario 1 - Phase 1'!$E$8+'LEVEL 3'!$E$8) -> 70.260259 | T14: =B14/'Scenario 1 - Phase 1'!$B$8 -> 0.086712819 | W14: =E14/'LEVEL 3'!$B$8 -> 0.05619673 | Z14: =H14/('Scenario 1 - Phase 1'!$B$8+'LEVEL 3'!$B$8) -> 0.074908313
A15: Pool Area Shower Concrete | B15: ='Scenario 1 - Phase 1'!K30 -> 5000 | E15: ='LEVEL 3'!K30 -> 2500 | H15: =B15+E15 -> 7500 | K15: =B15/'Scenario 1 - Phase 1'!$E$8 -> 14.409222 | N15: =E15/'LEVEL 3'!$E$8 -> 12.886598 | Q15: =H15/('Scenario 1 - Phase 1'!$E$8+'LEVEL 3'!$E$8) -> 13.863216 | T15: =B15/'Scenario 1 - Phase 1'!$B$8 -> 0.016069833 | W15: =E15/'LEVEL 3'!$B$8 -> 0.012736322 | Z15: =H15/('Scenario 1 - Phase 1'!$B$8+'LEVEL 3'!$B$8) -> 0.014780335
A16: Cabana Concrete | B16: ='Scenario 1 - Phase 1'!K31 -> 0 | E16: ='LEVEL 3'!K31 -> 0 | H16: =B16+E16 -> 0 | K16: =B16/'Scenario 1 - Phase 1'!$E$8 -> 0 | N16: =E16/'LEVEL 3'!$E$8 -> 0 | Q16: =H16/('Scenario 1 - Phase 1'!$E$8+'LEVEL 3'!$E$8) -> 0 | T16: =B16/'Scenario 1 - Phase 1'!$B$8 -> 0 | W16: =E16/'LEVEL 3'!$B$8 -> 0 | Z16: =H16/('Scenario 1 - Phase 1'!$B$8+'LEVEL 3'!$B$8) -> 0
A17: Pool Equipment Foundation | B17: ='Scenario 1 - Phase 1'!K32 -> 0 | E17: ='LEVEL 3'!K32 -> 0 | H17: =B17+E17 -> 0 | K17: =B17/'Scenario 1 - Phase 1'!$E$8 -> 0 | N17: =E17/'LEVEL 3'!$E$8 -> 0 | Q17: =H17/('Scenario 1 - Phase 1'!$E$8+'LEVEL 3'!$E$8) -> 0 | T17: =B17/'Scenario 1 - Phase 1'!$B$8 -> 0 | W17: =E17/'LEVEL 3'!$B$8 -> 0 | Z17: =H17/('Scenario 1 - Phase 1'!$B$8+'LEVEL 3'!$B$8) -> 0
A18: Lightweight Concrete | B18: ='Scenario 1 - Phase 1'!K33 -> 609838.32 | E18: ='LEVEL 3'!K33 -> 432915 | H18: =B18+E18 -> 1042753.3 | K18: =B18/'Scenario 1 - Phase 1'!$E$8 -> 1757.4591 | N18: =E18/'LEVEL 3'!$E$8 -> 2231.5206 | Q18: =H18/('Scenario 1 - Phase 1'!$E$8+'LEVEL 3'!$E$8) -> 1927.4553 | T18: =B18/'Scenario 1 - Phase 1'!$B$8 -> 1.96 | W18: =E18/'LEVEL 3'!$B$8 -> 2.205498 | Z18: =H18/('Scenario 1 - Phase 1'!$B$8+'LEVEL 3'!$B$8) -> 2.0549657
A19: Deck Concrete | B19: ='Scenario 1 - Phase 1'!K34 -> 78723.84 | E19: ='LEVEL 3'!K34 -> 59754.24 | H19: =B19+E19 -> 138478.08 | K19: =B19/'Scenario 1 - Phase 1'!$E$8 -> 226.86986 | N19: =E19/'LEVEL 3'!$E$8 -> 308.01155 | Q19: =H19/('Scenario 1 - Phase 1'!$E$8+'LEVEL 3'!$E$8) -> 255.96688 | T19: =B19/'Scenario 1 - Phase 1'!$B$8 -> 0.25301579 | W19: =E19/'LEVEL 3'!$B$8 -> 0.30441971 | Z19: =H19/('Scenario 1 - Phase 1'!$B$8+'LEVEL 3'!$B$8) -> 0.27290032
A20: Parking Garage | C20: =SUM(B21:B28) -> 0 | F20: =SUM(E21:E28) -> 0 | I20: =SUM(H21:H28) -> 0 | L20: =SUM(K21:K28) -> 0 | O20: =SUM(N21:N28) -> 0 | R20: =SUM(Q21:Q28) -> 0 | U20: =C20/'Scenario 1 - Phase 1'!$B$8 -> 0 | X20: =F20/'LEVEL 3'!$B$8 -> 0 | AA20: =I20/('Scenario 1 - Phase 1'!$B$8+'LEVEL 3'!$B$8) -> 0
