Workbook
Name \A: #REF!
Name \A: #REF!
Name \A: #REF!
Name \A: #REF!
Name \A: #REF!
Name \B: #REF!
Name \B: #REF!
Name \B: #REF!
Name \B: #REF!
Name \C: #REF!
Name \C: #REF!
Name \C: #REF!
Name \D: #REF!
Name \D: #REF!
Name \D: #REF!
Name \E: #REF!
Name \E: #REF!
Name \E: #REF!
Name \F: #REF!
Name \F: #REF!
Name \F: #REF!
Name \i: #REF!
Name \i: #REF!
Name \i: #REF!
Name \M: #REF!
Name \M: #REF!
Name \M: #REF!
Name \N: #REF!
Name \N: #REF!
Name \N: #REF!
Name \O: #REF!
Name \O: #REF!
Name \O: #REF!
Name \P: #REF!
Name \P: #REF!
Name \P: #REF!
Name \Q: #REF!
Name \Q: #REF!
Name \Q: #REF!
Name \S: #REF!
Name \S: #REF!
Name \S: #REF!
Name \T: #REF!
Name \T: #REF!
Name \T: #REF!
Name \U: #REF!
Name \U: #REF!
Name \U: #REF!
Name \w: #REF!
Name \w: #REF!
Name \w: #REF!
Name \X: #REF!
Name \X: #REF!
Name \X: #REF!
Name \Y: #REF!
Name \Y: #REF!
Name \Y: #REF!
Name \Z: #REF!
Name \Z: #REF!
Name \Z: #REF!

Sheet _REFERENCE888777888
A1: WorkSheet Name | B1: Report Code | C1: Company Id | D1: Job Id | E1: Start Date | F1: End Date | G1: Payroll Subledger | H1: Pay Period Id

Sheet LEVEL 3
A1: Project Details
A2: Project | B2: Robindale & 215 | J2: Total Cost | K2: =L319 -> 68910228 | M2: Unit Breakdown | Q2: Parking
A3: Budget Level | B3: Level 3 | M3: Unit Type | N3: Number | O3: % | Q3: Cover Parking | S3: 286 | AE3: Railing Estimate | AI3: Building 3 | AJ3: =21*7 -> 147 | AL3: Stucco | AP3: Building 3 | AQ3: =15000+6560+6500+15400+4570+4635+4540+4250 -> 61455
A4: Product | B4: Senior | J4: Cost Per Unit | K4: =K2/N9 -> 189835.34 | M4: Studios | N4: 0 | O4: =N4/$N$9 -> 0 | Q4: Cover Accesible Parking | AE4: Building 1 | AJ4: =14*7 -> 98 | AL4: Building 1
A5: Start Date | M5: 1 Br - 1 Ba | N5: ='Assumptions & Takeoffs'!B4+'Assumptions & Takeoffs'!B5 -> 218 | O5: =N5/$N$9 -> 0.60055096 | Q5: Open Parking | S5: 112 | AE5: Northwest | AF5: =21*4+8*8+7*6 -> 190 | AJ5: =8*22 -> 176 | AL5: Northwest | AM5: 19256
A6: Timeline | B6: 24 | J6: Cost Per SF | K6: =K2/B8 -> 190.05995 | M6: 2 Br - 1 Ba | N6: ='Assumptions & Takeoffs'!B6+'Assumptions & Takeoffs'!B7 -> 145 | O6: =N6/$N$9 -> 0.39944904 | Q6: Accessible Parking | S6: 14 | AE6: Southwest | AF6: =14*4+21*2+8*6 -> 146 | AJ6: =7*10 -> 70 | AL6: Southwest | AM6: 8980
A7: Floors | B7: 2 | M7: 2 Br - 2 Ba | N7: 0 | O7: =N7/$N$9 -> 0 | Q7: Waiver | S7: 0 | AE7: Northeast | AF7: =21*2+14*2+8*6 -> 118 | AJ7: =SUM(AJ3:AJ6) -> 491 | AL7: Northeast | AM7: 8850
A8: Bldg. SF | B8: =98509+136604+127458 -> 362571 | J8: Efficiency | K8: ='Assumptions & Takeoffs'!D8/B8 -> 0.78175861 | M8: 3 Br - 2 Ba | N8: 0 | O8: =N8/$N$9 -> 0 | Q8: Total Parking Provided | S8: =SUM(S3:S7) -> 412 | AE8: Southeast | AF8: =21*2+14*8+8*12+7*8 -> 306 | AL8: Southeast | AM8: 19965
A9: Acres | B9: 17.35 | M9: Totals | N9: =SUM(N4:N8) -> 363 | O9: =N9/$N$9 -> 1 | Q9: Parking Ratio | S9: =S8/N9 -> 1.1349862 | AE9: More | AF9: =21*4+8*6 -> 132 | AG9: =SUM(AF5:AF9) -> 892 | AL9: More | AM9: =5870+6250+6290+5915 -> 24325 | AN9: =SUM(AM5:AM9) -> 81376
A10: Site SF | B10: =B9*43560 -> 755766
A11: Buildings | B11: 3 | AE11: Building 2 & 5 | AI11: Building 4 | AJ11: =14*8 -> 112 | AL11: Building 2 & 5 | AP11: Building 4 | AQ11: =5782+5760+8825+9150 -> 29517
AE12: Northwest | AJ12: =20*8 -> 160 | AL12: Northwest
A13: Description | B13: Cost Code | C13: Cost Category | D13: Sub job | E13: Source | F13: UMO | G13: Quantity | H13: U.P. | I13: Escal % | J13: Total U.P. | K13: Sub Total | L13: Total | M13: Description / Details
A14: General Requirement | B14: 01 | C14: S | F14: Mo | G14: =$B$6 -> 24 | H14: =N324 -> 139138.88 | I14: 0 | J14: =H14*(1+I14) -> 139138.88 | K14: =J14*G14 -> 3339333.1
A15: General Requirements | B15: 01 | L15: =K14 -> 3339333.1
A16: Potholing | B16: 02-3213 | C16: S | D16: ON-SITE | E16: Allowance | G16: 1 | H16: 16000 | I16: 0 | J16: =H16*(1+I16) -> 16000 | K16: =J16*G16 -> 16000
A17: Existing Conditions | B17: 02 | L17: =K16 -> 16000
A18: Slabs | B18: 03-3101 | C18: S | D18: BUILDING | E18: Proposal | F18: LS | G18: 1 | H18: 2185768 | I18: 0 | J18: =H18*(1+I18) -> 2185768 | K18: =J18*G18 -> 2185768 | M18: Proposal (Alpha) - High Bid | O18: NRC Concrete ($1,542,922) - Low Bid
A19: Deepened Footings | B19: 03-3101 | C19: S | D19: BUILDING | E19: N/A | J19: =H19*(1+I19) -> 0 | K19: =J19*G19 -> 0 | AB19: Grading & Paving | AC19: 1833769
A20: Concrete Slab Repairs | B20: 03-3101 | C20: RR | D20: BUILDING | E20: Allowance | F20: LS | G20: 1 | H20: 7500 | I20: 0 | J20: =H20*(1+I20) -> 7500 | K20: =J20*G20 -> 7500 | AB20: Wets | AC20: 1812662
A21: Pump House Concrete | B21: 03-3101 | C21: S | D21: PUMPHOUSE | E21: Allowance | F21: LS | G21: 1 | H21: 8500 | J21: =H21*(1+I21) -> 8500 | K21: =J21*G21 -> 8500 | AB21: Slabs | AC21: 1542922
A22: Trash Enclosure Concrete | B22: 03-3102 | C22: S | D22: OTHER SITE | E22: Proposal | F22: EA | G22: ='Assumptions & Takeoffs'!B14 -> 14 | H22: 2958 | I22: 0 | J22: =H22*(1+I22) -> 2958 | K22: =J22*G22 -> 41412 | M22: Proposal (Alpha) | AB22: Wood Framing | AC22: 6634921
A23: Pool Area Shower Concrete | B23: 03-3105 | C23: S | D23: POOL AREA | E23: Allowance | F23: LS | G23: 1 | H23: 23959 | I23: 0 | J23: =H23*(1+I23) -> 23959 | K23: =J23*G23 -> 23959 | AB23: Plumbing | AC23: 3325080
A24: Cabana Concrete | B24: 03-3107 | C24: S | D24: POOL AREA | E24: Allowance | F24: LS | G24: 1 | H24: 6500 | I24: 0 | J24: =H24*(1+I24) -> 6500 | K24: =J24*G24 -> 6500 | AB24: Electrical | AC24: 4641350
A25: Pool Equipment Foundation | B25: 03-3108 | C25: S | D25: POOL EQUIP | E25: Allowance | F25: LS | G25: 1 | H25: 4290 | I25: 0 | J25: =H25*(1+I25) -> 4290 | K25: =J25*G25 -> 4290 | M25: Proposal (Alpha) | AB25: Mechanical
A26: Lightweight Concrete | B26: 03-3116 | C26: S | D26: BUILDING | E26: Proposal | F26: LS | G26: 1 | H26: =73410+103920+96980 -> 274310 | I26: 0 | J26: =H26*(1+I26) -> 274310 | K26: =J26*G26 -> 274310 | M26: Propsal (Nevada Gyp) - Low Bid | O26: Sound-Crete ($289,353) - High Bid | AB26: Finished Carpentry
A27: Deck Concrete | B27: 03-5001 | C27: S | D27: BUILDING | E27: Proposal | F27: LS | G27: 1 | H27: =10030+12540+10030 -> 32600 | I27: 0 | J27: =H27*(1+I27) -> 32600 | K27: =J27*G27 -> 32600 | M27: Propsal (Nevada Gyp) - Low Bid | O27: Sound-Crete ($41,260) - High Bid | AB27: Drywall & Paint | AC27: 3860853
A28: Concrete | B28: 03 | L28: =SUM(K18:K27) -> 2584839 | AB28: Masonry | AC28: 737195
A29: Elevator Shaft | B29: 04-2201 | C29: S | D29: BUILDING | E29: N/A | F29: Stop | G29: 0 | H29: 11500 | I29: 0 | J29: =H29*(1+I29) -> 11500 | K29: =J29*G29 -> 0 | M29: Wood framed. | AB29: Structural Steel | AC29: 121085
A30: Trash Enclosure | B30: 04-2202 | C30: S | D30: OTHER SITE | E30: Budget | F30: Count | G30: 14 | H30: 7000 | I30: 0 | J30: =H30*(1+I30) -> 7000 | K30: =J30*G30 -> 98000 | M30: See Off and Onsite Budget | O30: AWAITING UPDATED PROPOSALS | AB30: Site Iron | AC30: 608507
A31: Masonry Veneer | B31: 04-4301 | C31: S | D31: ON-SITE | E31: N/A | H31: 0 | J31: =H31*(1+I31) -> 0 | K31: =J31*G31 -> 0 | AB31: Elevators
A32: Masonry Veneer Pool Area | B32: 04-4305 | C32: S | D32: POOL AREA | E32: Allowance | F32: LS | G32: 3 | H32: 5000 | I32: 0 | J32: =H32*(1+I32) -> 5000 | K32: =J32*G32 -> 15000 | O32: AWAITING UPDATED PROPOSALS | AB32: Sprinkler Systems
A33: Pool Eq. Shower | B33: 04-4306 | C33: A | D33: POOL EQUIP | E33: Allowance | F33: LS | G33: 1 | H33: 15000 | I33: 0 | J33: =H33*(1+I33) -> 15000 | K33: =J33*G33 -> 15000 | O33: AWAITING UPDATED PROPOSALS | AB33: Fire Alarm
A34: Masonry | B34: 04 | L34: =SUM(K29:K33) -> 128000 | AB34: Insulation | AC34: 572070
A35: Structural Steel | B35: 05-1201 | C35: S | D35: BUILDING | E35: Proposal | F35: LS | G35: 1 | H35: =51595+31455+26435 -> 109485 | I35: 0 | J35: =H35*(1+I35) -> 109485 | K35: =J35*G35 -> 109485 | M35: Proposal (Imperial Iron) | AB35: Stucco | AC35: 897250
A36: Elevator Shaft Iron | B36: 05-1202 | C36: S | D36: BUILDING | E36: Proposal | F36: LS | G36: 1 | H36: 9600 | I36: 0 | J36: =H36*(1+I36) -> 9600 | K36: =J36*G36 -> 9600 | M36: Proposal (Imperial Iron) | AB36: Roofing | AC36: 1492534
A37: Stair Handrails | B37: 05-5201 | C37: S | D37: BUILDING | E37: West Henderson | F37: Flight | G37: ='Assumptions & Takeoffs'!B15 -> 19 | H37: 3000 | I37: 0 | J37: =H37*(1+I37) -> 3000 | K37: =J37*G37 -> 57000 | M37: West Henderson proposal - Desert Steel | AB37: Dry Utilities
A38: Garage Stair Railings | B38: 05-5201 | C38: S | D38: BUILDING | E38: N/A | H38: 0 | I38: 0 | J38: =H38*(1+I38) -> 0 | K38: =J38*G38 -> 0 | AB38: Lightweight Concrete | AC38: 306910
A39: Cabana Iron | B39: 05-7004 | C39: S | D39: POOL AREA | E39: N/A | H39: 0 | I39: 0 | J39: =H39*(1+I39) -> 0 | K39: =J39*G39 -> 0 | AB39: Decks
A40: Pool Equipment Gate | B40: 05-7005 | C40: S | D40: POOL EQUIP | E40: Budget | F40: Count | G40: 2 | H40: 1950 | I40: 0 | J40: =H40*(1+I40) -> 1950 | K40: =J40*G40 -> 3900 | M40: See Off and Onsite Budget | O40: AWAITING UPDATED PROPOSALS | AB40: Const. Clean
...

Sheet Comparison - Level 3
B1: Level 2.1 | E1: Level 3 | H1: Variance
A3: Units | C3: ='LEVEL 1.2 BUDGET'!N9 -> 363 | F3: ='LEVEL 1.2 BUDGET'!N9 -> 363 | I3: =C3-F3 -> 0
A4: Building Gross Square Feet | C4: ='LEVEL 1.2 BUDGET'!B8 -> 362571 | F4: ='LEVEL 1.2 BUDGET'!B8 -> 362571 | I4: =F4-C4 -> 0
A6: Total Cost | C6: =C312 -> 68033846 | F6: =F312 -> 68938905 | I6: =C6-F6 -> -905059.05 | W6: Studios | X6: 0 | Y6: =X6/$X$10 -> 0 | AC6: Southeast | AD6: =21*2+14*8+8*12+7*8 -> 306 | AJ6: Southeast | AK6: 19965
A7: Cost Per Unit | C7: =C6/X10 -> 187421.06 | F7: =F6/X10 -> 189914.34 | I7: =C7-F7 -> -2493.2756 | W7: 1 Br - 1 Ba | X7: ='Assumptions & Takeoffs'!B4+'Assumptions & Takeoffs'!B5 -> 218 | Y7: =X7/$X$10 -> 0.60055096 | AC7: More | AD7: =21*4+8*6 -> 132 | AE7: =SUM(AD6:AD7) -> 438 | AJ7: More | AK7: =5870+6250+6290+5915 -> 24325 | AL7: =SUM(AK6:AK7) -> 44290
A8: Cost Per SF | C8: =C6/X23 -> 187.64282 | F8: =F6/X23 -> 190.13905 | I8: =C8-F8 -> -2.4962257 | W8: 2 Br - 1 Ba | X8: ='Assumptions & Takeoffs'!B6+'Assumptions & Takeoffs'!B7 -> 145 | Y8: =X8/$X$10 -> 0.39944904
W9: 2 Br - 2 Ba | X9: 0 | Y9: =X9/$X$10 -> 0 | AC9: Building 2 & 5 | AG9: Building 4 | AH9: =14*8 -> 112 | AJ9: Building 2 & 5 | AN9: Building 4 | AO9: =5782+5760+8825+9150 -> 29517
A10: Description | B10: Sub Total | C10: Total | E10: Sub Total | F10: Total | H10: Variance | I10: % Change | K10: Description / Details | W10: Totals | X10: =SUM(X6:X9) -> 363 | Y10: =X10/$X$10 -> 1
A11: General Requirement | B11: =VLOOKUP($A11,'LEVEL 2.1'!$A$13:$K$317,11,FALSE) -> 3292398.3 | E11: =VLOOKUP($A11,'LEVEL 3'!$A$13:$K$317,11,FALSE) -> 3339333.1 | H11: =B11-E11 -> -46934.782 | I11: =H11/B11 -> -0.014255499
A12: General Requirements | C12: =B11 -> 3292398.3 | F12: =E11 -> 3339333.1 | H12: =C12-F12 -> -46934.782 | I12: =H12/C12 -> -0.014255499
A13: Potholing | B13: =VLOOKUP($A13,'LEVEL 2.1'!$A$13:$K$317,11,FALSE) -> 16000 | E13: =VLOOKUP($A13,'LEVEL 3'!$A$13:$K$317,11,FALSE) -> 16000 | H13: =B13-E13 -> 0 | I13: =H13/B13 -> 0
A14: Existing Conditions | C14: =B13 -> 16000 | F14: =E13 -> 16000 | H14: =C14-F14 -> 0 | I14: =H14/C14 -> 0
A15: Slabs | B15: =VLOOKUP($A15,'LEVEL 2.1'!$A$13:$K$317,11,FALSE) -> 2125443.3 | E15: =VLOOKUP($A15,'LEVEL 3'!$A$13:$K$317,11,FALSE) -> 2185768 | H15: =B15-E15 -> -60324.68 | I15: =H15/B15 -> -0.028382164 | K15: Updated per Bids
A16: Concrete Slab Repairs | B16: =VLOOKUP($A16,'LEVEL 2.1'!$A$13:$K$317,11,FALSE) -> 7500 | E16: =VLOOKUP($A16,'LEVEL 3'!$A$13:$K$317,11,FALSE) -> 7500 | H16: =B16-E16 -> 0 | I16: =H16/B16 -> 0 | W16: Project Details
A17: Pump House Concrete | B17: =VLOOKUP($A17,'LEVEL 2.1'!$A$13:$K$317,11,FALSE) -> 8500 | E17: =VLOOKUP($A17,'LEVEL 3'!$A$13:$K$317,11,FALSE) -> 8500 | H17: =B17-E17 -> 0 | I17: =H17/B17 -> 0 | W17: Project | X17: Robindale &215
A18: Trash Enclosure Concrete | B18: =VLOOKUP($A18,'LEVEL 2.1'!$A$13:$K$317,11,FALSE) -> 70000 | E18: =VLOOKUP($A18,'LEVEL 3'!$A$13:$K$317,11,FALSE) -> 41412 | H18: =B18-E18 -> 28588 | I18: =H18/B18 -> 0.4084 | K18: Updated per Bids | W18: Budget Level | X18: Level 1
A19: Pool Area Shower Concrete | B19: =VLOOKUP($A19,'LEVEL 2.1'!$A$13:$K$317,11,FALSE) -> 23959 | E19: =VLOOKUP($A19,'LEVEL 3'!$A$13:$K$317,11,FALSE) -> 23959 | H19: =B19-E19 -> 0 | I19: =H19/B19 -> 0 | W19: Product | X19: Senior
A20: Cabana Concrete | B20: =VLOOKUP($A20,'LEVEL 2.1'!$A$13:$K$317,11,FALSE) -> 6500 | E20: =VLOOKUP($A20,'LEVEL 3'!$A$13:$K$317,11,FALSE) -> 6500 | H20: =B20-E20 -> 0 | I20: 0
A21: Pool Equipment Foundation | B21: =VLOOKUP($A21,'LEVEL 2.1'!$A$13:$K$317,11,FALSE) -> 6500 | E21: =VLOOKUP($A21,'LEVEL 3'!$A$13:$K$317,11,FALSE) -> 4290 | H21: =B21-E21 -> 2210 | I21: =IF(B21=0,"n/a",H21/B21) -> 0.34 | K21: Updated per Bids | W21: Timeline | X21: 30
A22: Lightweight Concrete | B22: =VLOOKUP($A22,'LEVEL 2.1'!$A$13:$K$317,11,FALSE) -> 481539.8 | E22: =VLOOKUP($A22,'LEVEL 3'!$A$13:$K$317,11,FALSE) -> 274310 | H22: =B22-E22 -> 207229.8 | I22: =H22/B22 -> 0.43034823 | K22: Updated per Bids | W22: Floors | X22: 2
A23: Deck Concrete | B23: =VLOOKUP($A23,'LEVEL 2.1'!$A$13:$K$317,11,FALSE) -> 45894.051 | E23: =VLOOKUP($A23,'LEVEL 3'!$A$13:$K$317,11,FALSE) -> 32600 | H23: =B23-E23 -> 13294.051 | I23: =H23/B23 -> 0.28966829 | K23: Updated per Bids | W23: Bldg. SF | X23: =98509+136604+127458 -> 362571
A24: Concrete | C24: =SUM(B15:B23) -> 2775836.2 | F24: =SUM(E15:E23) -> 2584839 | H24: =C24-F24 -> 190997.17 | I24: =H24/C24 -> 0.068807076 | W24: Acres | X24: 17.35
A25: Elevator Shaft | B25: =VLOOKUP($A25,'LEVEL 2.1'!$A$13:$K$317,11,FALSE) -> 0 | E25: =VLOOKUP($A25,'LEVEL 3'!$A$13:$K$317,11,FALSE) -> 0 | H25: =B25-E25 -> 0 | I25: =IF(B25=0,"n/a",H25/B25) -> n/a | W25: Site SF | X25: =X24*43560 -> 755766
A26: Trash Enclosure | B26: =VLOOKUP($A26,'LEVEL 2.1'!$A$13:$K$317,11,FALSE) -> 98000 | E26: =VLOOKUP($A26,'LEVEL 3'!$A$13:$K$317,11,FALSE) -> 98000 | H26: =B26-E26 -> 0 | I26: =H26/B26 -> 0 | W26: Buildings | X26: 3
A27: Masonry Veneer Pool Area | B27: =VLOOKUP($A27,'LEVEL 2.1'!$A$13:$K$317,11,FALSE) -> 15000 | E27: =VLOOKUP($A27,'LEVEL 3'!$A$13:$K$317,11,FALSE) -> 15000 | H27: =B27-E27 -> 0 | I27: =IF(B27=0,"n/a",H27/B27) -> 0
A28: Pool Eq. Shower | B28: =VLOOKUP($A28,'LEVEL 2.1'!$A$13:$K$317,11,FALSE) -> 15000 | E28: =VLOOKUP($A28,'LEVEL 3'!$A$13:$K$317,11,FALSE) -> 15000 | H28: =B28-E28 -> 0 | I28: =IF(B28=0,"n/a",H28/B28) -> 0
A29: Masonry | C29: =SUM(B25:B28) -> 128000 | F29: =SUM(E25:E28) -> 128000 | H29: =C29-F29 -> 0 | I29: =H29/C29 -> 0
A30: Structural Steel | B30: =VLOOKUP($A30,'LEVEL 2.1'!$A$13:$K$317,11,FALSE) -> 150000 | E30: =VLOOKUP($A30,'LEVEL 3'!$A$13:$K$317,11,FALSE) -> 109485 | H30: =B30-E30 -> 40515 | I30: =IF(B30=0,"n/a",H30/B30) -> 0.2701 | K30: Updated per Bids
A31: Elevator Shaft Iron | B31: =VLOOKUP($A31,'LEVEL 2.1'!$A$13:$K$317,11,FALSE) -> 25500 | E31: =VLOOKUP($A31,'LEVEL 3'!$A$13:$K$317,11,FALSE) -> 9600 | H31: =B31-E31 -> 15900 | I31: =H31/B31 -> 0.62352941 | K31: Updated per Bids
A32: Stair Handrails | B32: =VLOOKUP($A32,'LEVEL 2.1'!$A$13:$K$317,11,FALSE) -> 57000 | E32: =VLOOKUP($A32,'LEVEL 3'!$A$13:$K$317,11,FALSE) -> 57000 | H32: =B32-E32 -> 0 | I32: =H32/B32 -> 0
A33: Pool Equipment Gate | B33: =VLOOKUP($A33,'LEVEL 2.1'!$A$13:$K$317,11,FALSE) -> 1950 | E33: =VLOOKUP($A33,'LEVEL 3'!$A$13:$K$317,11,FALSE) -> 3900 | H33: =B33-E33 -> -1950 | I33: =H33/B33 -> -1 | K33: Updated per Bids - Only 1 pool equipment gate
A34: Iron Railings | B34: =VLOOKUP($A34,'LEVEL 2.1'!$A$13:$K$317,11,FALSE) -> 240037.5 | E34: =VLOOKUP($A34,'LEVEL 3'!$A$13:$K$317,11,FALSE) -> 240037.5 | H34: =B34-E34 -> 0 | I34: =H34/B34 -> 0
A35: Cable Railings | B35: =VLOOKUP($A35,'LEVEL 2.1'!$A$13:$K$317,11,FALSE) -> 0 | E35: =VLOOKUP($A35,'LEVEL 3'!$A$13:$K$317,11,FALSE) -> 0 | H35: =B35-E35 -> 0 | I35: =IF(B35=0,"n/a",H35/B35) -> n/a
A36: Metals | C36: =SUM(B30:B35) -> 474487.5 | F36: =SUM(E30:E35) -> 420022.5 | H36: =C36-F36 -> 54465 | I36: =H36/C36 -> 0.11478701
A37: Framing | B37: =VLOOKUP($A37,'LEVEL 2.1'!$A$13:$K$317,11,FALSE) -> 6772826.3 | E37: =VLOOKUP($A37,'LEVEL 3'!$A$13:$K$317,11,FALSE) -> 6634921 | H37: =B37-E37 -> 137905.28 | I37: =H37/B37 -> 0.020361556 | K37: Updated per Bids
A38: Framing Pump House | B38: =VLOOKUP($A38,'LEVEL 2.1'!$A$13:$K$317,11,FALSE) -> 11208 | E38: =VLOOKUP($A38,'LEVEL 3'!$A$13:$K$317,11,FALSE) -> 11208 | H38: =B38-E38 -> 0 | I38: =IF(B38=0,"n/a",H38/B38) -> 0
A39: Framing - Crane | B39: =VLOOKUP($A39,'LEVEL 2.1'!$A$13:$K$317,11,FALSE) -> 0 | E39: =VLOOKUP($A39,'LEVEL 3'!$A$13:$K$317,11,FALSE) -> 0 | H39: =B39-E39 -> 0 | I39: =IF(B39=0,"n/a",H39/B39) -> n/a
A40: Cabana Framing | B40: =VLOOKUP($A40,'LEVEL 2.1'!$A$13:$K$317,11,FALSE) -> 0 | E40: =VLOOKUP($A40,'LEVEL 3'!$A$13:$K$317,11,FALSE) -> 0 | H40: =B40-E40 -> 0 | I40: =IF(B40=0,"n/a",H40/B40) -> n/a
A41: BBQ Framing | B41: =VLOOKUP($A41,'LEVEL 2.1'!$A$13:$K$317,11,FALSE) -> 10000 | E41: =VLOOKUP($A41,'LEVEL 3'!$A$13:$K$317,11,FALSE) -> 10000 | H41: =B41-E41 -> 0 | I41: =H41/B41 -> 0
A42: Fireplace Framing | B42: =VLOOKUP($A42,'LEVEL 2.1'!$A$13:$K$317,11,FALSE) -> 0 | E42: =VLOOKUP($A42,'LEVEL 3'!$A$13:$K$317,11,FALSE) -> 0 | H42: =B42-E42 -> 0 | I42: =IF(B42=0,"n/a",H42/B42) -> n/a
...

Sheet LEVEL 2.1
A1: Project Details
A2: Project | B2: Robindale & 215 | J2: Total Cost | K2: =L319 -> 68005169 | M2: Unit Breakdown | Q2: Parking
A3: Budget Level | B3: Level 2 | M3: Unit Type | N3: Number | O3: % | Q3: Cover Parking | S3: 286 | AE3: Railing Estimate | AI3: Building 3 | AJ3: =21*7 -> 147 | AL3: Stucco | AP3: Building 3 | AQ3: =15000+6560+6500+15400+4570+4635+4540+4250 -> 61455
A4: Product | B4: Senior | J4: Cost Per Unit | K4: =K2/N9 -> 187342.06 | M4: Studios | N4: 0 | O4: =N4/$N$9 -> 0 | Q4: Cover Accesible Parking | AE4: Building 1 | AJ4: =14*7 -> 98 | AL4: Building 1
A5: Start Date | M5: 1 Br - 1 Ba | N5: ='Assumptions & Takeoffs'!B4+'Assumptions & Takeoffs'!B5 -> 218 | O5: =N5/$N$9 -> 0.60055096 | Q5: Open Parking | S5: 157 | AE5: Northwest | AF5: =21*4+8*8+7*6 -> 190 | AJ5: =8*22 -> 176 | AL5: Northwest | AM5: 19256
A6: Timeline | B6: 24 | E6: =80 -> 80 | J6: Cost Per SF | K6: =K2/B8 -> 187.56373 | M6: 2 Br - 1 Ba | N6: ='Assumptions & Takeoffs'!B6+'Assumptions & Takeoffs'!B7 -> 145 | O6: =N6/$N$9 -> 0.39944904 | Q6: Accessible Parking | S6: 14 | AE6: Southwest | AF6: =14*4+21*2+8*6 -> 146 | AJ6: =7*10 -> 70 | AL6: Southwest | AM6: 8980
A7: Floors | B7: 2 | E7: =1000/E6 -> 12.5 | M7: 2 Br - 2 Ba | N7: 0 | O7: =N7/$N$9 -> 0 | Q7: Waiver | S7: 0 | AE7: Northeast | AF7: =21*2+14*2+8*6 -> 118 | AJ7: =SUM(AJ3:AJ6) -> 491 | AL7: Northeast | AM7: 8850
A8: Bldg. SF | B8: =98509+136604+127458 -> 362571 | J8: Efficiency | K8: ='Assumptions & Takeoffs'!D8/B8 -> 0.78175861 | M8: 3 Br - 2 Ba | N8: 0 | O8: =N8/$N$9 -> 0 | Q8: Total Parking Provided | S8: =SUM(S3:S7) -> 457 | AE8: Southeast | AF8: =21*2+14*8+8*12+7*8 -> 306 | AL8: Southeast | AM8: 19965
A9: Acres | B9: 17.35 | M9: Totals | N9: =SUM(N4:N8) -> 363 | O9: =N9/$N$9 -> 1 | Q9: Parking Ratio | S9: =S8/N9 -> 1.2589532 | AE9: More | AF9: =21*4+8*6 -> 132 | AG9: =SUM(AF5:AF9) -> 892 | AL9: More | AM9: =5870+6250+6290+5915 -> 24325 | AN9: =SUM(AM5:AM9) -> 81376
A10: Site SF | B10: =B9*43560 -> 755766
A11: Buildings | B11: 3 | AE11: Building 2 & 5 | AI11: Building 4 | AJ11: =14*8 -> 112 | AL11: Building 2 & 5 | AP11: Building 4 | AQ11: =5782+5760+8825+9150 -> 29517
AE12: Northwest | AJ12: =20*8 -> 160 | AL12: Northwest
A13: Description | B13: Cost Code | C13: Cost Category | D13: Sub job | E13: Source | F13: UMO | G13: Quantity | H13: U.P. | I13: Escal % | J13: Total U.P. | K13: Sub Total | L13: Total | M13: Description / Details
A14: General Requirement | B14: 01 | C14: S | F14: Mo | G14: =$B$6 -> 24 | H14: =N324 -> 137183.26 | I14: 0 | J14: =H14*(1+I14) -> 137183.26 | K14: =J14*G14 -> 3292398.3
A15: General Requirements | B15: 01 | L15: =K14 -> 3292398.3
A16: Potholing | B16: 02-3213 | C16: S | D16: ON-SITE | E16: Allowance | G16: 1 | H16: 16000 | I16: 0 | J16: =H16*(1+I16) -> 16000 | K16: =J16*G16 -> 16000
A17: Existing Conditions | B17: 02 | L17: =K16 -> 16000
A18: Slabs | B18: 03-3101 | C18: S | D18: BUILDING | E18: Torrey Pines | F18: SF | G18: ='Assumptions & Takeoffs'!B11 -> 177268 | H18: 11.99 | I18: 0 | J18: =H18*(1+I18) -> 11.99 | K18: =J18*G18 -> 2125443.3 | M18: 4" over 4" slab profile. WH that has a proposal at $9.16 by NRC but all other competitors are over $12/sf.
A19: Deepened Footings | B19: 03-3101 | C19: S | D19: BUILDING | E19: N/A | J19: =H19*(1+I19) -> 0 | K19: =J19*G19 -> 0
A20: Concrete Slab Repairs | B20: 03-3101 | C20: RR | D20: BUILDING | E20: Allowance | F20: LS | G20: 1 | H20: 7500 | I20: 0 | J20: =H20*(1+I20) -> 7500 | K20: =J20*G20 -> 7500
A21: Pump House Concrete | B21: 03-3101 | C21: S | D21: PUMPHOUSE | E21: Allowance | F21: LS | G21: 1 | H21: 8500 | J21: =H21*(1+I21) -> 8500 | K21: =J21*G21 -> 8500
A22: Trash Enclosure Concrete | B22: 03-3102 | C22: S | D22: OTHER SITE | E22: Allowance | F22: EA | G22: ='Assumptions & Takeoffs'!B14 -> 14 | H22: 5000 | I22: 0 | J22: =H22*(1+I22) -> 5000 | K22: =J22*G22 -> 70000
A23: Pool Area Shower Concrete | B23: 03-3105 | C23: S | D23: POOL AREA | E23: Allowance | F23: LS | G23: 1 | H23: 23959 | I23: 0 | J23: =H23*(1+I23) -> 23959 | K23: =J23*G23 -> 23959
A24: Cabana Concrete | B24: 03-3107 | C24: S | D24: POOL AREA | E24: Allowance | F24: LS | G24: 1 | H24: 6500 | I24: 0 | J24: =H24*(1+I24) -> 6500 | K24: =J24*G24 -> 6500
A25: Pool Equipment Foundation | B25: 03-3108 | C25: S | D25: POOL EQUIP | E25: Allowance | F25: LS | G25: 1 | H25: 6500 | I25: 0 | J25: =H25*(1+I25) -> 6500 | K25: =J25*G25 -> 6500
A26: Lightweight Concrete | B26: 03-3116 | C26: S | D26: BUILDING | E26: Bruner | F26: SF | G26: ='Assumptions & Takeoffs'!E14 -> 171978.5 | H26: 2.8 | I26: 0 | J26: =H26*(1+I26) -> 2.8 | K26: =J26*G26 -> 481539.8 | M26: Nevada Gypsum 1" with Mat.
A27: Deck Concrete | B27: 03-5001 | C27: S | D27: BUILDING | E27: Bruner | F27: SF | G27: ='Assumptions & Takeoffs'!$H$16 -> 2236 | H27: 20.525068 | I27: 0 | J27: =H27*(1+I27) -> 20.525068 | K27: =J27*G27 -> 45894.051
A28: Concrete | B28: 03 | L28: =SUM(K18:K27) -> 2775836.2
A29: Elevator Shaft | B29: 04-2201 | C29: S | D29: BUILDING | E29: N/A | F29: Stop | G29: 0 | H29: 11500 | I29: 0 | J29: =H29*(1+I29) -> 11500 | K29: =J29*G29 -> 0 | M29: Wood framed.
A30: Trash Enclosure | B30: 04-2202 | C30: S | D30: OTHER SITE | E30: West H. | F30: Count | G30: 14 | H30: 7000 | I30: 0 | J30: =H30*(1+I30) -> 7000 | K30: =J30*G30 -> 98000
A31: Masonry Veneer | B31: 04-4301 | C31: S | D31: ON-SITE | E31: N/A | H31: 0 | J31: =H31*(1+I31) -> 0 | K31: =J31*G31 -> 0
A32: Masonry Veneer Pool Area | B32: 04-4305 | C32: S | D32: POOL AREA | E32: Allowance | F32: LS | G32: 3 | H32: 5000 | I32: 0 | J32: =H32*(1+I32) -> 5000 | K32: =J32*G32 -> 15000
A33: Pool Eq. Shower | B33: 04-4306 | C33: A | D33: POOL EQUIP | E33: Allowance | F33: LS | G33: 1 | H33: 15000 | I33: 0 | J33: =H33*(1+I33) -> 15000 | K33: =J33*G33 -> 15000
A34: Masonry | B34: 04 | L34: =SUM(K29:K33) -> 128000
A35: Structural Steel | B35: 05-1201 | C35: S | D35: BUILDING | E35: Allowance | F35: LS | G35: 1 | H35: 150000 | I35: 0 | J35: =H35*(1+I35) -> 150000 | K35: =J35*G35 -> 150000 | M35: Place holder. No Plans
A36: Elevator Shaft Iron | B36: 05-1202 | C36: S | D36: BUILDING | E36: Allowance | F36: Count | G36: ='Assumptions & Takeoffs'!$B$12 -> 6 | H36: 4250 | I36: 0 | J36: =H36*(1+I36) -> 4250 | K36: =J36*G36 -> 25500
A37: Stair Handrails | B37: 05-5201 | C37: S | D37: BUILDING | E37: West H. | F37: Flight | G37: ='Assumptions & Takeoffs'!B15 -> 19 | H37: 3000 | I37: 0 | J37: =H37*(1+I37) -> 3000 | K37: =J37*G37 -> 57000
A38: Garage Stair Railings | B38: 05-5201 | C38: S | D38: BUILDING | E38: N/A | H38: 0 | I38: 0 | J38: =H38*(1+I38) -> 0 | K38: =J38*G38 -> 0
A39: Cabana Iron | B39: 05-7004 | C39: S | D39: POOL AREA | E39: N/A | H39: 0 | I39: 0 | J39: =H39*(1+I39) -> 0 | K39: =J39*G39 -> 0
A40: Pool Equipment Gate | B40: 05-7005 | C40: S | D40: POOL EQUIP | E40: Torrey Pines | F40: Count | G40: 1 | H40: 1950 | I40: 0 | J40: =H40*(1+I40) -> 1950 | K40: =J40*G40 -> 1950
...

Sheet Assumptions & Takeoffs
A2: Unit Matrix | F2: Reports Available
A3: Unit Type | B3: Number | C3: % | D3: SF | F3: SER (GCW)
A4: 1A | B4: 170 | C4: =B4/$B$8 -> 0.46831956 | D4: 676 | F4: Soils Report
A5: 1B | B5: 48 | C5: =B5/$B$8 -> 0.1322314 | D5: 764 | F5: Alta Survey
A6: 2A | B6: 127 | C6: =B6/$B$8 -> 0.34986226 | D6: 901 | F6: Plans | K6: 10
A7: 2B | B7: 18 | C7: =B7/$B$8 -> 0.049586777 | D7: 968 | K7: =K6*16 -> 160
A8: Totals | B8: =SUM(B4:B7) -> 363 | C8: =B8/$B$8 -> 1 | D8: =SUMPRODUCT(B4:B7,D4:D7) -> 283443
K9: 600
A10: List of Take offs | D10: List of Take offs | G10: List of Take offs | K10: =1250-K9-K7 -> 490 | N10: Slabs | P10: Patios | R10: Lightweight
A11: Slab SF | B11: 177268 | C11: GSF | D11: Counter tops | E11: =(((16.19+55.2)*(23+34+30+24+30+27))+((17.33+77.17)*(8+10+8+8+10+8))+((20.29+64.88)*(12+24+24+14+25+26))+((18.98+64.6)*(1+1+2+4+5+5)))+((242.17+36.22)+(140.39+10.04)+(140.45+10.04)+(19.89+4.91)) -> 29662.32 | F11: SF | G11: Fitness Center | H11: 0 | I11: SF | N11: Building 1 | O11: =48798.63-P11 -> 48298.63 | P11: =4*125 -> 500 | R11: =45*3 -> 135 | S11: =O11-R11 -> 48163.63
A12: Elevators | B12: 6 | C12: Count | D12: Blinds | E12: 0 | G12: Unit Appliances | N12: Building 2 | O12: =67208.37-P12 -> 66583.37 | P12: =5*125 -> 625 | R12: =65*3 -> 195 | S12: =O12-R12 -> 66388.37
A13: Elevators Stops | B13: =B12*2 -> 12 | C13: Count | D13: Landscaping | E13: 316370.92 | F13: SF | G13: Kitchens | N13: Building 3 | O13: =63276.41-P13 -> 62776.41 | P13: =4*125 -> 500 | R13: =60*3 -> 180 | S13: =O13-R13 -> 62596.41
A14: Trash Encl. | B14: 14 | C14: Site Plan | D14: Lighweight | E14: 171978.5 | G14: Laundries | N14: Pump House | O14: 600 | Q14: Assumption
A15: Stairs | B15: 19 | C15: Count | D15: 1x1 Decks | E15: =64*48 -> 3072 | F15: SF | G15: Patio | H15: 1223.57 | I15: SF | N15: Pool Equipment | O15: 307
A16: Pool | B16: 1 | D16: 2x1 Decks | E16: 0 | F16: SF | G16: Deck | H16: =K29 -> 2236 | I16: SF
A17: Gym | B17: =869.71+1032.19 -> 1901.9 | C17: SF | D17: Lightweight | E17: 0 | F17: SF
A18: Iron Rail | B18: 2595 | C18: LF | D18: Pavers | E18: 0 | F18: SF | G18: Corridors | H18: 35218.83
A19: Roofing | B19: =1899.71+243.72 -> 2143.43 | C19: Square | D19: Pool Deck | E19: 0 | F19: SF | G19: Other Common Areas | H19: 5741.77
A20: Stucco | B20: =E32 -> 23863.34 | C20: Square Yard | D20: Pool Fence | E20: 0 | F20: LF | G20: Laundry | H20: 1103.55 | N20: Stucco | P20: Returns
A21: Livable Area | B21: =67855+103666+98170 -> 269691 | C21: SF | D21: Dog Park Fence | E21: 0 | F21: LF | G21: Great Room (c | H21: 4961.54 | N21: Building 1 | O21: 48784 | P21: 1800
A22: Carports | B22: ='LEVEL 1.2 BUDGET'!S3 -> 286 | C22: Count | D22: Common Bldg. 1 | E22: 0 | F22: SF | G22: Fitness Center | H22: 1956.73 | N22: Building 2 | O22: 64771 | P22: 2200
A23: Stairs Landings | B23: 0 | C23: Landings | D23: Asphalt | E23: 0 | G23: Leasing | H23: 674.75 | N23: Building 3 | O23: 66016 | P23: 2254
A24: Pump House | B24: 1 | C24: EA | D24: Pavers | E24: 0 | O24: =SUM(O21:O23) -> 179571 | P24: =SUM(P21:P23) -> 6254 | Q24: =P24+O24 -> 185825
A25: Lock Boxes | B25: 0 | C25: EA | D25: Pavers Pool | E25: 0 | K25: =86 -> 86 | N25: Squares | O25: =O24/9 -> 19952.333 | P25: =P24/9 -> 694.88889 | Q25: =Q24/9 -> 20647.222
A26: Awning Small | B26: =12+9+9 -> 30 | C26: EA | K26: =4*2 -> 8
A27: Awning Large | B27: =3+3+4 -> 10 | C27: EA | K27: =5*2 -> 10
D28: Stucco | K28: =4*2 -> 8 | N28: 1 | O28: 94262 | P28: 98509 | Q28: =P28-O28 -> 4247
D29: Building A | E29: 6633.44 | F29: SY | K29: =SUM(K26:K28)*K25 -> 2236 | N29: 2 | O29: 113176 | P29: 136604 | Q29: =P29-O29 -> 23428
D30: Building B | E30: 8701.64 | F30: SY | N30: 3 | O30: 121766 | P30: 127458 | Q30: =P30-O30 -> 5692
D31: Building C | E31: 8528.26 | F31: SY | O31: =SUM(O28:O30) -> 329204 | P31: =SUM(P28:P30) -> 362571 | Q31: =P31-O31 -> 33367
D32: Total | E32: =SUM(E29:E31) -> 23863.34
N37: Unit | P37: SF
N38: 1A | O38: 166
N39: 1B | O39: 52
N40: 2A | O40: 127
N41: 2B | O41: 18
O42: =SUM(O38:O41) -> 363

Sheet LEVEL 2
A1: Project Details
A2: Project | B2: Robindale & 215 | J2: Total Cost | K2: =L319 -> 68767994 | M2: Unit Breakdown | Q2: Parking
A3: Budget Level | B3: Level 2 | M3: Unit Type | N3: Number | O3: % | Q3: Cover Parking | S3: 286 | AE3: Railing Estimate | AI3: Building 3 | AJ3: =21*7 -> 147 | AL3: Stucco | AP3: Building 3 | AQ3: =15000+6560+6500+15400+4570+4635+4540+4250 -> 61455
A4: Product | B4: Senior | J4: Cost Per Unit | K4: =K2/N9 -> 189443.51 | M4: Studios | N4: 0 | O4: =N4/$N$9 -> 0 | Q4: Cover Accesible Parking | AE4: Building 1 | AJ4: =14*7 -> 98 | AL4: Building 1
A5: Start Date | M5: 1 Br - 1 Ba | N5: ='Assumptions & Takeoffs'!B4+'Assumptions & Takeoffs'!B5 -> 218 | O5: =N5/$N$9 -> 0.60055096 | Q5: Open Parking | S5: 157 | AE5: Northwest | AF5: =21*4+8*8+7*6 -> 190 | AJ5: =8*22 -> 176 | AL5: Northwest | AM5: 19256
A6: Timeline | B6: 24 | J6: Cost Per SF | K6: =K2/B8 -> 189.66766 | M6: 2 Br - 1 Ba | N6: ='Assumptions & Takeoffs'!B6+'Assumptions & Takeoffs'!B7 -> 145 | O6: =N6/$N$9 -> 0.39944904 | Q6: Accessible Parking | S6: 14 | AE6: Southwest | AF6: =14*4+21*2+8*6 -> 146 | AJ6: =7*10 -> 70 | AL6: Southwest | AM6: 8980
A7: Floors | B7: 2 | M7: 2 Br - 2 Ba | N7: 0 | O7: =N7/$N$9 -> 0 | Q7: Waiver | S7: 0 | AE7: Northeast | AF7: =21*2+14*2+8*6 -> 118 | AJ7: =SUM(AJ3:AJ6) -> 491 | AL7: Northeast | AM7: 8850
A8: Bldg. SF | B8: =98509+136604+127458 -> 362571 | J8: Efficiency | K8: ='Assumptions & Takeoffs'!D8/B8 -> 0.78175861 | M8: 3 Br - 2 Ba | N8: 0 | O8: =N8/$N$9 -> 0 | Q8: Total Parking Provided | S8: =SUM(S3:S7) -> 457 | AE8: Southeast | AF8: =21*2+14*8+8*12+7*8 -> 306 | AL8: Southeast | AM8: 19965
A9: Acres | B9: 17.35 | M9: Totals | N9: =SUM(N4:N8) -> 363 | O9: =N9/$N$9 -> 1 | Q9: Parking Ratio | S9: =S8/N9 -> 1.2589532 | AE9: More | AF9: =21*4+8*6 -> 132 | AG9: =SUM(AF5:AF9) -> 892 | AL9: More | AM9: =5870+6250+6290+5915 -> 24325 | AN9: =SUM(AM5:AM9) -> 81376
A10: Site SF | B10: =B9*43560 -> 755766
A11: Buildings | B11: 3 | AE11: Building 2 & 5 | AI11: Building 4 | AJ11: =14*8 -> 112 | AL11: Building 2 & 5 | AP11: Building 4 | AQ11: =5782+5760+8825+9150 -> 29517
AE12: Northwest | AJ12: =20*8 -> 160 | AL12: Northwest
A13: Description | B13: Cost Code | C13: Cost Category | D13: Sub job | E13: Source | F13: UMO | G13: Quantity | H13: U.P. | I13: Escal % | J13: Total U.P. | K13: Sub Total | L13: Total | M13: Description / Details
A14: General Requirement | B14: 01 | C14: S | F14: Mo | G14: =$B$6 -> 24 | H14: =N324 -> 138831.55 | I14: 0 | J14: =H14*(1+I14) -> 138831.55 | K14: =J14*G14 -> 3331957.1
A15: General Requirements | B15: 01 | L15: =K14 -> 3331957.1
A16: Potholing | B16: 02-3213 | C16: S | D16: ON-SITE | E16: Allowance | G16: 1 | H16: 16000 | I16: 0 | J16: =H16*(1+I16) -> 16000 | K16: =J16*G16 -> 16000
A17: Existing Conditions | B17: 02 | L17: =K16 -> 16000
A18: Slabs | B18: 03-3101 | C18: S | D18: BUILDING | E18: Torrey Pines | F18: SF | G18: ='Assumptions & Takeoffs'!B11 -> 177268 | H18: 11.99 | I18: 0 | J18: =H18*(1+I18) -> 11.99 | K18: =J18*G18 -> 2125443.3 | M18: 4" over 4" slab profile. WH that has a proposal at $9.16 by NRC but all other competitors are over $12/sf.
A19: Deepened Footings | B19: 03-3101 | C19: S | D19: BUILDING | E19: N/A | J19: =H19*(1+I19) -> 0 | K19: =J19*G19 -> 0
A20: Concrete Slab Repairs | B20: 03-3101 | C20: RR | D20: BUILDING | E20: Allowance | F20: LS | G20: 1 | H20: 7500 | I20: 0 | J20: =H20*(1+I20) -> 7500 | K20: =J20*G20 -> 7500
A21: Pump House Concrete | B21: 03-3101 | C21: S | D21: PUMPHOUSE | E21: Allowance | F21: LS | G21: 1 | H21: 8500 | J21: =H21*(1+I21) -> 8500 | K21: =J21*G21 -> 8500
A22: Trash Enclosure Concrete | B22: 03-3102 | C22: S | D22: OTHER SITE | E22: Allowance | F22: EA | G22: ='Assumptions & Takeoffs'!B14 -> 14 | H22: 5000 | I22: 0 | J22: =H22*(1+I22) -> 5000 | K22: =J22*G22 -> 70000
A23: Pool Area Shower Concrete | B23: 03-3105 | C23: S | D23: POOL AREA | E23: Allowance | F23: LS | G23: 1 | H23: 23959 | I23: 0 | J23: =H23*(1+I23) -> 23959 | K23: =J23*G23 -> 23959
A24: Cabana Concrete | B24: 03-3107 | C24: S | D24: POOL AREA | E24: Allowance | F24: LS | G24: 1 | H24: 6500 | I24: 0 | J24: =H24*(1+I24) -> 6500 | K24: =J24*G24 -> 6500
A25: Pool Equipment Foundation | B25: 03-3108 | C25: S | D25: POOL EQUIP | E25: Allowance | F25: LS | G25: 1 | H25: 6500 | I25: 0 | J25: =H25*(1+I25) -> 6500 | K25: =J25*G25 -> 6500
A26: Lightweight Concrete | B26: 03-3116 | C26: S | D26: BUILDING | E26: Bruner | F26: SF | G26: ='Assumptions & Takeoffs'!E14 -> 171978.5 | H26: 2.8 | I26: 0 | J26: =H26*(1+I26) -> 2.8 | K26: =J26*G26 -> 481539.8 | M26: Nevada Gypsum 1" with Mat.
A27: Deck Concrete | B27: 03-5001 | C27: S | D27: BUILDING | E27: Bruner | F27: SF | G27: ='Assumptions & Takeoffs'!$H$16 -> 2236 | H27: 20.525068 | I27: 0 | J27: =H27*(1+I27) -> 20.525068 | K27: =J27*G27 -> 45894.051
A28: Concrete | B28: 03 | L28: =SUM(K18:K27) -> 2775836.2
A29: Elevator Shaft | B29: 04-2201 | C29: S | D29: BUILDING | E29: N/A | F29: Stop | G29: 0 | H29: 11500 | I29: 0 | J29: =H29*(1+I29) -> 11500 | K29: =J29*G29 -> 0 | M29: Wood framed.
A30: Trash Enclosure | B30: 04-2202 | C30: S | D30: OTHER SITE | E30: West H. | F30: Count | G30: 14 | H30: 7000 | I30: 0 | J30: =H30*(1+I30) -> 7000 | K30: =J30*G30 -> 98000
A31: Masonry Veneer | B31: 04-4301 | C31: S | D31: ON-SITE | E31: N/A | H31: 0 | J31: =H31*(1+I31) -> 0 | K31: =J31*G31 -> 0
A32: Masonry Veneer Pool Area | B32: 04-4305 | C32: S | D32: POOL AREA | E32: Allowance | F32: LS | G32: 3 | H32: 5000 | I32: 0 | J32: =H32*(1+I32) -> 5000 | K32: =J32*G32 -> 15000
A33: Pool Eq. Shower | B33: 04-4306 | C33: A | D33: POOL EQUIP | E33: Allowance | F33: LS | G33: 1 | H33: 15000 | I33: 0 | J33: =H33*(1+I33) -> 15000 | K33: =J33*G33 -> 15000
A34: Masonry | B34: 04 | L34: =SUM(K29:K33) -> 128000
A35: Structural Steel | B35: 05-1201 | C35: S | D35: BUILDING | E35: Allowance | F35: LS | G35: 1 | H35: 150000 | I35: 0 | J35: =H35*(1+I35) -> 150000 | K35: =J35*G35 -> 150000 | M35: Place holder. No Plans
A36: Elevator Shaft Iron | B36: 05-1202 | C36: S | D36: BUILDING | E36: Allowance | F36: Count | G36: ='Assumptions & Takeoffs'!$B$12 -> 6 | H36: 4250 | I36: 0 | J36: =H36*(1+I36) -> 4250 | K36: =J36*G36 -> 25500
A37: Stair Handrails | B37: 05-5201 | C37: S | D37: BUILDING | E37: West H. | F37: Flight | G37: ='Assumptions & Takeoffs'!B15 -> 19 | H37: 3000 | I37: 0 | J37: =H37*(1+I37) -> 3000 | K37: =J37*G37 -> 57000
A38: Garage Stair Railings | B38: 05-5201 | C38: S | D38: BUILDING | E38: N/A | H38: 0 | I38: 0 | J38: =H38*(1+I38) -> 0 | K38: =J38*G38 -> 0
A39: Cabana Iron | B39: 05-7004 | C39: S | D39: POOL AREA | E39: N/A | H39: 0 | I39: 0 | J39: =H39*(1+I39) -> 0 | K39: =J39*G39 -> 0
A40: Pool Equipment Gate | B40: 05-7005 | C40: S | D40: POOL EQUIP | E40: Torrey Pines | F40: Count | G40: 1 | H40: 1950 | I40: 0 | J40: =H40*(1+I40) -> 1950 | K40: =J40*G40 -> 1950
...

Sheet Comparison
B1: Level 1.2 | E1: Level 2 | H1: Variance
A3: Units | C3: ='LEVEL 1.1 BUDGET'!I7 -> 363 | F3: ='LEVEL 1.2 BUDGET'!N9 -> 363 | I3: =C3-F3 -> 0
A4: Building Gross Square Feet | C4: ='Combined - vErik'!B8 -> 329194 | F4: ='LEVEL 1.2 BUDGET'!B8 -> 362571 | I4: =F4-C4 -> 33377
A6: Total Cost | C6: =C312 -> 68871988 | F6: =F312 -> 68767994 | I6: =C6-F6 -> 103993.77 | W6: Studios | X6: 0 | Y6: =X6/$X$10 -> 0 | AC6: Southeast | AD6: =21*2+14*8+8*12+7*8 -> 306 | AJ6: Southeast | AK6: 19965
A7: Cost Per Unit | C7: =C6/X10 -> 189729.99 | F7: =F6/X10 -> 189443.51 | I7: =C7-F7 -> 286.48422 | W7: 1 Br - 1 Ba | X7: ='Assumptions & Takeoffs'!B4+'Assumptions & Takeoffs'!B5 -> 218 | Y7: =X7/$X$10 -> 0.60055096 | AC7: More | AD7: =21*4+8*6 -> 132 | AE7: =SUM(AD6:AD7) -> 438 | AJ7: More | AK7: =5870+6250+6290+5915 -> 24325 | AL7: =SUM(AK6:AK7) -> 44290
A8: Cost Per SF | C8: =C6/'LEVEL 1.2 BUDGET'!$B$8 -> 189.95449 | F8: =F6/X23 -> 189.66766 | I8: =C8-F8 -> 0.2868232 | W8: 2 Br - 1 Ba | X8: ='Assumptions & Takeoffs'!B6+'Assumptions & Takeoffs'!B7 -> 145 | Y8: =X8/$X$10 -> 0.39944904
W9: 2 Br - 2 Ba | X9: 0 | Y9: =X9/$X$10 -> 0 | AC9: Building 2 & 5 | AG9: Building 4 | AH9: =14*8 -> 112 | AJ9: Building 2 & 5 | AN9: Building 4 | AO9: =5782+5760+8825+9150 -> 29517
A10: Description | B10: Sub Total | C10: Total | E10: Sub Total | F10: Total | H10: Variance | I10: % Change | K10: Description / Details | W10: Totals | X10: =SUM(X6:X9) -> 363 | Y10: =X10/$X$10 -> 1
A11: General Requirement | B11: =VLOOKUP($A11,'LEVEL 1.2 BUDGET'!$A$13:$K$316,11,FALSE) -> 3338816 | E11: =VLOOKUP($A11,'LEVEL 2'!$A$13:$K$317,11,FALSE) -> 3331957.1 | H11: =B11-E11 -> 6858.9165 | I11: =H11/B11 -> 0.002054296
A12: General Requirements | C12: 3338816 | F12: =E11 -> 3331957.1 | H12: =C12-F12 -> 6858.9165 | I12: =H12/C12 -> 0.002054296
A13: Potholing | B13: =VLOOKUP(A13,'LEVEL 1.2 BUDGET'!$A$13:$K$316,11,FALSE) -> 16000 | E13: =VLOOKUP($A13,'LEVEL 2'!$A$13:$K$317,11,FALSE) -> 16000 | H13: =B13-E13 -> 0 | I13: =H13/B13 -> 0
A14: Existing Conditions | C14: 16000 | F14: =E13 -> 16000 | H14: =C14-F14 -> 0 | I14: =H14/C14 -> 0
A15: Slabs | B15: =VLOOKUP(A15,'LEVEL 1.2 BUDGET'!$A$13:$K$316,11,FALSE) -> 2130124.3 | E15: =VLOOKUP($A15,'LEVEL 2'!$A$13:$K$317,11,FALSE) -> 2125443.3 | H15: =B15-E15 -> 4681.0159 | I15: =H15/B15 -> 0.0021975318
A16: Concrete Slab Repairs | B16: =VLOOKUP(A16,'LEVEL 1.2 BUDGET'!$A$13:$K$316,11,FALSE) -> 7500 | E16: =VLOOKUP($A16,'LEVEL 2'!$A$13:$K$317,11,FALSE) -> 7500 | H16: =B16-E16 -> 0 | I16: =H16/B16 -> 0 | W16: Project Details
A17: Pump House Concrete | B17: =VLOOKUP(A17,'LEVEL 1.2 BUDGET'!$A$13:$K$316,11,FALSE) -> 8500 | E17: =VLOOKUP($A17,'LEVEL 2'!$A$13:$K$317,11,FALSE) -> 8500 | H17: =B17-E17 -> 0 | I17: =H17/B17 -> 0 | W17: Project | X17: Robindale &215
A18: Trash Enclosure Concrete | B18: =VLOOKUP(A18,'LEVEL 1.2 BUDGET'!$A$13:$K$316,11,FALSE) -> 70000 | E18: =VLOOKUP($A18,'LEVEL 2'!$A$13:$K$317,11,FALSE) -> 70000 | H18: =B18-E18 -> 0 | I18: =H18/B18 -> 0 | W18: Budget Level | X18: Level 1
A19: Pool Area Shower Concrete | B19: =VLOOKUP(A19,'LEVEL 1.2 BUDGET'!$A$13:$K$316,11,FALSE) -> 20200 | E19: =VLOOKUP($A19,'LEVEL 2'!$A$13:$K$317,11,FALSE) -> 23959 | H19: =B19-E19 -> -3759 | I19: =H19/B19 -> -0.18608911 | W19: Product | X19: Senior
A20: Cabana Concrete | B20: =VLOOKUP(A20,'LEVEL 1.2 BUDGET'!$A$13:$K$316,11,FALSE) -> 0 | E20: =VLOOKUP($A20,'LEVEL 2'!$A$13:$K$317,11,FALSE) -> 6500 | H20: =B20-E20 -> -6500 | I20: 0
A21: Pool Equipment Foundation | B21: =VLOOKUP(A21,'LEVEL 1.2 BUDGET'!$A$13:$K$316,11,FALSE) -> 10000 | E21: =VLOOKUP($A21,'LEVEL 2'!$A$13:$K$317,11,FALSE) -> 6500 | H21: =B21-E21 -> 3500 | I21: =IF(B21=0,"n/a",H21/B21) -> 0.35 | W21: Timeline | X21: 30
A22: Lightweight Concrete | B22: =VLOOKUP(A22,'LEVEL 1.2 BUDGET'!$A$13:$K$316,11,FALSE) -> 496015.55 | E22: =VLOOKUP($A22,'LEVEL 2'!$A$13:$K$317,11,FALSE) -> 481539.8 | H22: =B22-E22 -> 14475.748 | I22: =H22/B22 -> 0.029184061 | K22: Updated take off | W22: Floors | X22: 2
A23: Deck Concrete | B23: =VLOOKUP(A23,'LEVEL 1.2 BUDGET'!$A$13:$K$316,11,FALSE) -> 43318 | E23: =VLOOKUP($A23,'LEVEL 2'!$A$13:$K$317,11,FALSE) -> 45894.051 | H23: =B23-E23 -> -2576.0515 | I23: =H23/B23 -> -0.059468385 | W23: Bldg. SF | X23: =98509+136604+127458 -> 362571
A24: Concrete | C24: =SUM(B15:B23) -> 2785657.9 | F24: =SUM(E15:E23) -> 2775836.2 | H24: =C24-F24 -> 9821.7124 | I24: =H24/C24 -> 0.0035258143 | W24: Acres | X24: 17.35
A25: Elevator Shaft | B25: =VLOOKUP(A25,'LEVEL 1.2 BUDGET'!$A$13:$K$316,11,FALSE) -> 138000 | E25: =VLOOKUP($A25,'LEVEL 2'!$A$13:$K$317,11,FALSE) -> 0 | H25: =B25-E25 -> 138000 | I25: =H25/B25 -> 1 | K25: Eliminated CMU shaft for framing. | W25: Site SF | X25: =X24*43560 -> 755766
A26: Trash Enclosure | B26: =VLOOKUP(A26,'LEVEL 1.2 BUDGET'!$A$13:$K$316,11,FALSE) -> 102200 | E26: =VLOOKUP($A26,'LEVEL 2'!$A$13:$K$317,11,FALSE) -> 98000 | H26: =B26-E26 -> 4200 | I26: =H26/B26 -> 0.04109589 | W26: Buildings | X26: 3
A27: Masonry Veneer Pool Area | B27: =VLOOKUP(A27,'LEVEL 1.2 BUDGET'!$A$13:$K$316,11,FALSE) -> 5000 | E27: =VLOOKUP($A27,'LEVEL 2'!$A$13:$K$317,11,FALSE) -> 15000 | H27: =B27-E27 -> -10000 | I27: =IF(B27=0,"n/a",H27/B27) -> -2
A28: Pool Eq. Shower | B28: =VLOOKUP(A28,'LEVEL 1.2 BUDGET'!$A$13:$K$316,11,FALSE) -> 10000 | E28: =VLOOKUP($A28,'LEVEL 2'!$A$13:$K$317,11,FALSE) -> 15000 | H28: =B28-E28 -> -5000 | I28: =IF(B28=0,"n/a",H28/B28) -> -0.5
A29: Masonry | C29: =SUM(B25:B28) -> 255200 | F29: =SUM(E25:E28) -> 128000 | H29: =C29-F29 -> 127200 | I29: =H29/C29 -> 0.4984326
A30: Structural Steel | B30: =VLOOKUP(A30,'LEVEL 1.2 BUDGET'!$A$13:$K$316,11,FALSE) -> 150000 | E30: =VLOOKUP($A30,'LEVEL 2'!$A$13:$K$317,11,FALSE) -> 150000 | H30: =B30-E30 -> 0 | I30: =IF(B30=0,"n/a",H30/B30) -> 0
A31: Elevator Shaft Iron | B31: =VLOOKUP(A31,'LEVEL 1.2 BUDGET'!$A$13:$K$316,11,FALSE) -> 24540 | E31: =VLOOKUP($A31,'LEVEL 2'!$A$13:$K$317,11,FALSE) -> 25500 | H31: =B31-E31 -> -960 | I31: =H31/B31 -> -0.039119804
A32: Stair Handrails | B32: =VLOOKUP(A32,'LEVEL 1.2 BUDGET'!$A$13:$K$316,11,FALSE) -> 45000 | E32: =VLOOKUP($A32,'LEVEL 2'!$A$13:$K$317,11,FALSE) -> 57000 | H32: =B32-E32 -> -12000 | I32: =H32/B32 -> -0.26666667
A33: Pool Equipment Gate | B33: =VLOOKUP(A33,'LEVEL 1.2 BUDGET'!$A$13:$K$316,11,FALSE) -> 1950 | E33: =VLOOKUP($A33,'LEVEL 2'!$A$13:$K$317,11,FALSE) -> 1950 | H33: =B33-E33 -> 0 | I33: =H33/B33 -> 0
A34: Iron Railings | B34: =VLOOKUP(A34,'LEVEL 1.2 BUDGET'!$A$13:$K$316,11,FALSE) -> 238464 | E34: =VLOOKUP($A34,'LEVEL 2'!$A$13:$K$317,11,FALSE) -> 240037.5 | H34: =B34-E34 -> -1573.5 | I34: =H34/B34 -> -0.0065984803
A35: Cable Railings | B35: =VLOOKUP(A35,'LEVEL 1.2 BUDGET'!$A$13:$K$316,11,FALSE) -> 0 | E35: =VLOOKUP($A35,'LEVEL 2'!$A$13:$K$317,11,FALSE) -> 0 | H35: =B35-E35 -> 0 | I35: =IF(B35=0,"n/a",H35/B35) -> n/a
A36: Metals | C36: =SUM(B30:B35) -> 459954 | F36: =SUM(E30:E35) -> 474487.5 | H36: =C36-F36 -> -14533.5 | I36: =H36/C36 -> -0.031597725
A37: Framing | B37: =VLOOKUP(A37,'LEVEL 1.2 BUDGET'!$A$13:$K$316,11,FALSE) -> 6772826.3 | E37: =VLOOKUP($A37,'LEVEL 2'!$A$13:$K$317,11,FALSE) -> 6772826.3 | H37: =B37-E37 -> 0 | I37: =H37/B37 -> 0
A38: Framing Pump House | B38: =VLOOKUP(A38,'LEVEL 1.2 BUDGET'!$A$13:$K$316,11,FALSE) -> 11208 | E38: =VLOOKUP($A38,'LEVEL 2'!$A$13:$K$317,11,FALSE) -> 11208 | H38: =B38-E38 -> 0 | I38: =IF(B38=0,"n/a",H38/B38) -> 0
A39: Framing - Crane | B39: =VLOOKUP(A39,'LEVEL 1.2 BUDGET'!$A$13:$K$316,11,FALSE) -> 0 | E39: =VLOOKUP($A39,'LEVEL 2'!$A$13:$K$317,11,FALSE) -> 0 | H39: =B39-E39 -> 0 | I39: =IF(B39=0,"n/a",H39/B39) -> n/a
A40: Cabana Framing | B40: =VLOOKUP(A40,'LEVEL 1.2 BUDGET'!$A$13:$K$316,11,FALSE) -> 0 | E40: =VLOOKUP($A40,'LEVEL 2'!$A$13:$K$317,11,FALSE) -> 0 | H40: =B40-E40 -> 0 | I40: =IF(B40=0,"n/a",H40/B40) -> n/a
A41: BBQ Framing | B41: =VLOOKUP(A41,'LEVEL 1.2 BUDGET'!$A$13:$K$316,11,FALSE) -> 10000 | E41: =VLOOKUP($A41,'LEVEL 2'!$A$13:$K$317,11,FALSE) -> 10000 | H41: =B41-E41 -> 0 | I41: =H41/B41 -> 0
A42: Fireplace Framing | B42: =VLOOKUP(A42,'LEVEL 1.2 BUDGET'!$A$13:$K$316,11,FALSE) -> 0 | E42: =VLOOKUP($A42,'LEVEL 2'!$A$13:$K$317,11,FALSE) -> 0 | H42: =B42-E42 -> 0 | I42: =IF(B42=0,"n/a",H42/B42) -> n/a
...

Sheet What Changed
A1: ROBINDALE AND 215 - DETAILS OF BUDGET CHANGE
B3: Budget 1.2 | D3: Budget 2 | F3: Variance | H3: Reason for Change
A4: Elevator Shaft | B4: =Comparison!B25 -> 138000 | D4: =Comparison!E25 -> 0 | F4: =B4-D4 -> 138000 | G4: 0 | H4: Elevator Shaft to be framed, not CMU.
A5: Masonry | C5: =Comparison!C29 -> 255200 | E5: =Comparison!F29 -> 128000 | F5: =C5-E5 -> 127200 | G5: =Comparison!$I$29 -> 0.4984326
A6: Finish Carpentry - Units | B6: =Comparison!B45 -> 1125300 | D6: =Comparison!E45 -> 1281767.4 | F6: =B6-D6 -> -156467.35 | G6: =Comparison!$I$37 -> 0 | H6: Added 10% as we have indication BFS has purchased Rystin and Doors and Millwork companies.
A7: Finish Carpentry - Common | B7: =Comparison!B46 -> 398828.1 | D7: =Comparison!E46 -> 430736.14 | F7: =B7-D7 -> -31908.036 | G7: =Comparison!$I$37 -> 0 | H7: Added 10% as we have indication BFS has purchased Rystin and Doors and Millwork companies.
A8: Wood, Plastics, & Composites | C8: =Comparison!C50 -> 8327162.4 | E8: =Comparison!F50 -> 8515537.8 | F8: =C8-E8 -> -188375.39 | G8: =Comparison!$I$50 -> -0.022621799
A9: Roofing | B9: =Comparison!B53 -> 1071280.2 | D9: =Comparison!E53 -> 1277484.3 | F9: =B9-D9 -> -206204.07 | G9: =Comparison!$I$53 -> -0.19248378 | H9: New takeoff based on 50% DD yielded 366 more squares (added parapet walls to take off).
A10: Thermal & Moisture Protection | C10: =Comparison!$C$64 -> 2157341.9 | E10: =Comparison!$F$64 -> 2366346 | F10: =C10-E10 -> -209004.07 | G10: =Comparison!$I$64 -> -0.096880362
A11: Stucco | B11: =Comparison!B86 -> 842819.61 | D11: =Comparison!E86 -> 950639.3 | F11: =B11-D11 -> -107819.69 | G11: =Comparison!$I$69 -> -0.12237509 | H11: New take off based on 50% DD tielded 3k SY more than previous.
A12: Common Tile | B12: =Comparison!B97 -> 75000 | D12: =Comparison!E97 -> 170141.73 | F12: =B12-D12 -> -95141.73 | G12: =Comparison!$I$69 -> -0.12237509 | H12: Increase as an allowance per building.
A13: Hall Flooring | B13: =Comparison!B103 -> 170408.37 | D13: =Comparison!E103 -> 271928.25 | F13: =B13-D13 -> -101519.88 | G13: =Comparison!$I$69 -> -0.12237509 | H13: Updated pricing to Torrey Pines contract versus previous budget using Pebble.
A14: Hall Runner Materials | B14: =Comparison!B110 -> 107683.44 | D14: =Comparison!E110 -> 0 | F14: =B14-D14 -> 107683.44 | G14: =Comparison!$I$141 -> 0 | H14: Deleted hallway runners in latest plans.
A15: Painting | B15: =Comparison!B112 -> 572862.18 | D15: =Comparison!E112 -> 717890.58 | F15: =B15-D15 -> -145028.4 | G15: =Comparison!$I$144 -> 0.051782919 | H15: Based on West Henderson Paint proposal by Classic.
A16: Finishes | C16: =Comparison!$C$148 -> 2059949 | E16: =Comparison!$F$148 -> 1826689.4 | F16: =C16-E16 -> 233259.64 | G16: =Comparison!$I$148 -> 0.11323564
A17: Appliances | B17: =Comparison!B136 -> 1009140 | D17: =Comparison!E136 -> 1220061.2 | F17: =B17-D17 -> -210921.15 | G17: =Comparison!$I$150 -> 0 | H17: Updated to Bruner and 5% for annual increase in appliance cost.
A18: Equipment | C18: =Comparison!$C$152 -> 907561 | E18: =Comparison!$F$152 -> 953492.67 | F18: =C18-E18 -> -45931.667 | G18: =Comparison!$I$152 -> -0.050610005
A19: Cabinets Units | B19: =Comparison!B142 -> 1143813 | D19: =Comparison!E142 -> 941174 | F19: =B19-D19 -> 202639 | G19: =Comparison!$I$150 -> 0 | H19: Using Thermafoil White, W.H. units. Add $150,260 if upgrading to Morning Dew ($159.80 / SF)
A20: Furnishings | C20: =Comparison!C148 -> 2059949 | E20: =Comparison!F148 -> 1826689.4 | F20: =C20-E20 -> 233259.64 | G20: =Comparison!$I$152 -> -0.050610005
A21: Elevator | B21: =Comparison!$B$155 -> 426560 | D21: =Comparison!$E$155 -> 483797 | F21: =B21-D21 -> -57237 | G21: =Comparison!$I$155 -> -0.13418276 | H21: Based on Otis discussion on estimated cost per 2-stop elevator
A22: Conveying Equipment | C22: =Comparison!$C$157 -> 439560 | E22: =Comparison!$F$157 -> 496797 | F22: =C22-E22 -> -57237 | G22: =Comparison!$I$157 -> -0.13021431
A23: Electrical | B23: =Comparison!$B$171 -> 3651773 | D23: =Comparison!$E$171 -> 3846878.3 | F23: =B23-D23 -> -195105.33 | G23: =Comparison!$I$171 -> -0.053427562 | H23: Updated to West Henderson proposal by Sigma (cost/SF).
A24: Electrical | C24: =Comparison!$C$188 -> 4194934 | E24: =Comparison!$F$188 -> 4455520.8 | F24: =C24-E24 -> -260586.83 | G24: =Comparison!$I$188 -> -0.062119411
A25: Fire Alarm / Two Way | B25: =Comparison!$B$195 -> 506841.64 | D25: =Comparison!$E$195 -> 701583.54 | F25: =B25-D25 -> -194741.9 | G25: =Comparison!$I$195 -> -0.38422632 | H25: Used Decatur due to expectation that all Jurisdictions would implement new code.
A26: Electronic Safety & Security | C26: =Comparison!$C$197 -> 848751.36 | E26: =Comparison!$F$197 -> 1047129.9 | F26: =C26-E26 -> -198378.54 | G26: =Comparison!$I$197 -> -0.23372986
A27: Mass Grading | B27: =Comparison!$B$202 -> 1067126 | D27: =Comparison!$E$202 -> 1257581.4 | F27: =B27-D27 -> -190455.36 | G27: =Comparison!$I$202 -> -0.17847505 | H27: Preliminary civil shows an 50k CY export site. Increase export while decreasing hard dig and excavation based on take off.
A28: Earthwork | C28: =Comparison!$C$207 -> 1546728 | E28: =Comparison!$F$207 -> 1777422.5 | F28: =C28-E28 -> -230694.5 | G28: =Comparison!$I$207 -> -0.14915001
A29: Paving | B29: =Comparison!$B$211 -> 670743 | D29: =Comparison!$E$211 -> 601630.93 | F29: =B29-D29 -> 69112.07 | G29: =Comparison!$I$211 -> 0.10303808 | H29: Updated takeoff based on preliminary civil plans.
A30: Walls Iron | B30: =Comparison!$B$221 -> 91085 | D30: =Comparison!$E$221 -> 164035.4 | F30: =B30-D30 -> -72950.4 | G30: =Comparison!$I$221 -> -0.80090465 | H30: Updated takeoff based on preliminary civil plans.
A31: Walls Masonry | B31: =Comparison!$B$232 -> 376743 | D31: =Comparison!$E$232 -> 493481.67 | F31: =B31-D31 -> -116738.67 | G31: =Comparison!$I$232 -> -0.30986289 | H31: Updated takeoff based on preliminary civil plans.
A32: Retaining Walls | B32: =Comparison!$B$234 -> 331457 | D32: =Comparison!$E$234 -> 303105.8 | F32: =B32-D32 -> 28351.2 | G32: =Comparison!$I$234 -> 0.085535077 | H32: Updated takeoff based on preliminary civil plans.
A33: Site Landscaping | B33: =Comparison!$B$237 -> 3976294.8 | D33: =Comparison!$E$237 -> 2847338.3 | F33: =B33-D33 -> 1128956.5 | G33: =Comparison!$I$237 -> 0.28392174 | H33: Updated pricing at West Henderson increased by $0.50 / sf. Robindale assimilates WH based on project size and large open spaces.
A34: Offsite Paving | B34: =Comparison!$B$241 -> 413660 | D34: =Comparison!$E$241 -> 341251.06 | F34: =B34-D34 -> 72408.938 | G34: =(B34-D34)/B34 -> 0.17504457 | H34: Civil plans shows minimal but this budget assumes the entire Robindale frontage to be paved due to poor currect conditions.
A35: Exterior Improvements | C35: =Comparison!$C$245 -> 6907826.6 | E35: =Comparison!$F$245 -> 5896648.9 | F35: =C35-E35 -> 1011177.6 | G35: =Comparison!$I$245 -> 0.14638145
A36: Sewer | B36: =Comparison!$B$249 -> 823398 | D36: =Comparison!$E$249 -> 516087 | F36: =B36-D36 -> 307311 | G36: =Comparison!$I$249 -> 0.37322291 | H36: Preliminary Civils show no lift station ($200k) and hard dig decreased by $50k. Soils show limited hard dig.
A37: Electric | B37: =Comparison!$B$253 -> 452076 | D37: =Comparison!$E$253 -> 350575.2 | F37: =B37-D37 -> 101500.8 | G37: =Comparison!$I$253 -> 0.22452154 | H37: Updated with a internal power design based on previous projects. Lowered Hard dig to $50k from $100k.
A38: Off Site Water | B38: =Comparison!$B$258 -> 345550 | D38: =Comparison!$E$258 -> 387993.65 | F38: =B38-D38 -> -42443.65 | G38: =Comparison!$I$258 -> -0.12282926 | H38: Based on preliminary civils take offs.
A39: Off Site Sewer | B39: =Comparison!$B$259 -> 75000 | D39: =Comparison!$E$259 -> 91720 | F39: =B39-D39 -> -16720 | G39: =Comparison!$I$259 -> -0.22293333 | H39: Based on preliminary civils take offs.
A40: Utilities | C40: =Comparison!$C$262 -> 3305385 | E40: =Comparison!$F$262 -> 2941601.8 | F40: =C40-E40 -> 363783.17 | G40: =Comparison!$I$262 -> 0.11005773
A41: Interior Furniture | B41: =Comparison!$B$294 -> 1500000 | D41: =Comparison!$E$294 -> 1200000 | F41: =B41-D41 -> 300000 | G41: =Comparison!$I$294 -> 0.2 | H41: Assuming Main Building approximatly $500k and $350k for each of the 2 other buidlings.
...

Sheet Unit Pricing Comparison
I1: SENIOR / AFFORABLE PROJECTS
C2: Robindale & 215 (Level 2) | H2: West Henderson Level 3 | I2: Bruner | J2: South Nellis | K2: Torrey Pines | L2: Decatur | M2: Pebble
A3: Budget | E3: Units | F3: ='LEVEL 2'!N9 -> 363 | H3: 380 | I3: 194 | J3: 50 | K3: 190 | L3: 276 | M3: 195
A4: Proposal | E4: GSF | F4: ='LEVEL 2'!B8 -> 362571 | H4: 422635 | I4: 196289 | J4: 34388 | K4: 188825 | L4: 258464 | M4: 184108
A5: Contract | E5: Acres | F5: ='LEVEL 2'!B9 -> 17.35 | H5: 15.83 | I5: 4.9 | J5: 1.3 | K5: 5 | L5: 9.45 | M5: 5
E6: Site SF | F6: =F5*43560 -> 755766 | H6: =H5*43560 -> 689554.8 | I6: =I5*43560 -> 213444 | J6: =J5*43560 -> 56628 | K6: =K5*43560 -> 217800 | L6: 411642 | M6: 217800
A7: Description | B7: % | C7: Cost | D7: UOM | E7: U | F7: PU | H7: PU | I7: PU | J7: PU | K7: PU | L7: PU | M7: PU | O7: COMMENTS ROBINDALE VS WEST HENDERSON | Q7: Recommendation for Robindale
A8: Framing | B8: =C8/$C$29 -> 0.098488059 | C8: =VLOOKUP(A8,'LEVEL 2'!$A$14:$K$317,11,FALSE) -> 6772826.3 | D8: SF | E8: =$F$4 -> 362571 | F8: =C8/E8 -> 18.68 | H8: 17.716624 | I8: 18.68 | J8: 20.075375 | K8: 19.921525 | L8: 22.888453 | M8: 19.011015 | O8: WH is ave between the 3 current proposal. | Q8: Leave as budgeted
A9: Electrical | B9: =C9/$C$29 -> 0.055939952 | C9: =VLOOKUP(A9,'LEVEL 2'!$A$14:$K$317,11,FALSE) -> 3846878.3 | D9: SF (Bldg) | E9: =$F$4 -> 362571 | F9: =C9/E9 -> 10.61 | H9: 11.33 | I9: 10.06 | J9: 12.504362 | K9: 9.2699537 | L9: 10.176018 | M9: 12.13429 | O9: WH is ave between the 3 current proposal. | Q9: Increase to WH
A10: HVAC Standard | B10: =C10/$C$29 -> 0.051969903 | C10: =VLOOKUP(A10,'LEVEL 2'!$A$14:$K$317,11,FALSE) -> 3573866 | D10: Unit | E10: =$F$3 -> 363 | F10: =C10/E10 -> 9845.3608 | H10: 10558.306 | I10: 9845.36 | J10: 10148.68 | K10: 9739.2737 | L10: 10104.674 | M10: 9218.2513 | O10: WH ave of 2 best proposal. 3rd is an outlier. Larger units at WH. | Q10: Increase to WH
A11: Drywall | B11: =C11/$C$29 -> 0.040333707 | C11: =VLOOKUP(A11,'LEVEL 2'!$A$14:$K$317,11,FALSE) -> 2773668.1 | D11: SF (Bldg) | E11: =$F$4 -> 362571 | F11: =C11/E11 -> 7.65 | H11: 7.6967218 | I11: 7.2940664 | J11: 7.7384864 | K11: 8.0157077 | L11: 7.3585311 | M11: 8.0768353 | O11: WH is ave between the 3 current proposal. | Q11: Leave as budgeted
A12: 1 Bathroom Unit | B12: =C12/$C$29 -> 0.053150409 | C12: =VLOOKUP(A12,'LEVEL 2'!$A$14:$K$317,11,FALSE) -> 3655047 | D12: 1 Bath Unit | E12: =F3 -> 363 | F12: =C12/E12 -> 10069 | H12: 10250 | I12: 10069 | J12: 10196.24 | K12: 10526.311 | L12: 11042.514 | M12: =1959791/$M$3 -> 10050.21 | O12: WH is tied to JMAC proposal. | Q12: Increase to WH
A13: Appliances | B13: =C13/$C$29 -> 0.0177417 | C13: =VLOOKUP(A13,'LEVEL 2'!$A$14:$K$317,11,FALSE) -> 1220061.2 | D13: Unit | E13: =$F$3 -> 363 | F13: =C13/E13 -> 3361.05 | H13: 3328.1895 | I13: =614922.64/I3 -> 3169.7043 | J13: 3064.485 | K13: 3144.7947 | L13: 3454.4783 | M13: 3201.4974 | Q13: Decrease to Bruner
A14: Sprinkler System | B14: =C14/$C$29 -> 0.013971807 | C14: =VLOOKUP(A14,'LEVEL 2'!$A$14:$K$317,11,FALSE) -> 960813.15 | D14: SF (Bldg) | E14: =$F$4 -> 362571 | F14: =C14/E14 -> 2.65 | H14: 2.65 | I14: 2.65 | J14: 3.2147842 | K14: 2.453065 | L14: 2.94 | M14: 2.4480196 | Q14: Leave as budgeted
A15: Cabinets Units | B15: =C15/$C$29 -> 0.013686222 | C15: =VLOOKUP(A15,'LEVEL 2'!$A$14:$K$317,11,FALSE) -> 941174 | D15: Unit | E15: =$F$3 -> 363 | F15: =C15/E15 -> 2592.7658 | H15: 3072.4615 | I15: 4150.2474 | J15: 1985.2 | K15: 3778.0053 | L15: 3705.4275 | M15: 3113.7333 | O15: WH has more cabinet boxes due to extra bathrooms (increase/unit) | Q15: Leave as budgeted
A16: Windows and Sliding Glass Doors | B16: =C16/$C$29 -> 0.0081818586 | C16: =VLOOKUP(A16,'LEVEL 2'!$A$14:$K$317,11,FALSE) -> 562650 | D16: Unit | E16: =$F$3 -> 363 | F16: =C16/E16 -> 1550 | H16: 1400 | I16: 1335.866 | J16: 1300.6084 | K16: 1157.8947 | L16: 1408.8261 | M16: 739.27144 | Q16: Leave as budgeted
A17: Finish Carpentry - Units | B17: =C17/$C$29 -> 0.01863901 | C17: =VLOOKUP(A17,'LEVEL 2'!$A$14:$K$317,11,FALSE) -> 1281767.4 | D17: Unit | E17: =$F$3 -> 363 | F17: =C17/E17 -> 3531.0395 | H17: 3002.6901 | I17: 2607.1546 | J17: 2710.9005 | K17: 3210.0359 | L17: 2983.3587 | M17: 3081.2324 | O17: Budgeted basd on WH proposal per liavable SF | Q17: Decrese to WH $/SF
A18: Slabs | B18: =C18/$C$29 -> 0.03090745 | C18: =VLOOKUP(A18,'LEVEL 2'!$A$14:$K$317,11,FALSE) -> 2125443.3 | D18: SF (Slab) | E18: ='Assumptions & Takeoffs'!B11 -> 177268 | F18: =C18/E18 -> 11.99 | H18: 9.5 | I18: 11.11 | J18: 16.778816 | K18: 11.989967 | L18: 15.882903 | M18: 16.060895 | O18: WH has low outlier proposal. | Q18: Leave as budgeted
A19: Insulation | B19: =C19/$C$29 -> 0.01318095 | C19: =VLOOKUP(A19,'LEVEL 2'!$A$14:$K$317,11,FALSE) -> 906427.5 | D19: SF (Bldg) | E19: =$F$4 -> 362571 | F19: =C19/E19 -> 2.5 | H19: 2.3794882 | I19: 2.5 | J19: 2.5423113 | K19: 2.6983715 | L19: 2.2715182 | M19: 2.5011406 | Q19: Leave as budgeted
A20: Fire Alarm / Two Way Comm AOR | B20: =C20/$C$29 -> 0.010202181 | C20: =VLOOKUP(A20,'LEVEL 2'!$A$14:$K$317,11,FALSE) -> 701583.54 | D20: SF (Bldg) | E20: =$F$4 -> 362571 | F20: =C20/E20 -> 1.9350239 | H20: 2.25 | I20: 1.3350213 | J20: 1.977434 | K20: 1.6733483 | L20: 1.94 | M20: 1.553436 | O20: Henderson has signicant higher permit fees | Q20: Leave as budgeted
A21: Site Landscaping | B21: =C21/$C$29 -> 0.041404993 | C21: =VLOOKUP(A21,'LEVEL 2'!$A$14:$K$317,11,FALSE) -> 2847338.3 | D21: Site SF | E21: ='Assumptions & Takeoffs'!E13 -> 316370.92 | F21: =C21/$E$21 -> 9 | H21: 7.5062348 | I21: 13.681367 | J21: 10.5 | K21: 12.007558 | L21: 13.483701 | M21: 21.389001 | O21: Selected a budget cost/SF in between WH and Bruner. | Q21: Leave as budgeted
A22: Stucco | B22: =C22/$C$29 -> 0.013823863 | C22: =VLOOKUP(A22,'LEVEL 2'!$A$14:$K$317,11,FALSE) -> 950639.3 | D22: SY (Bldg) | E22: ='Assumptions & Takeoffs'!B20 -> 23863.34 | F22: =C22/E22 -> 39.836808 | H22: 39.311357 | I22: 39.836808 | J22: 39.371016 | K22: 40.818674 | L22: 42.234692 | M22: 46.688382 | Q22: Leave as budgeted
A23: Counter Tops Units | B23: =C23/$C$29 -> 0.0081535949 | C23: =VLOOKUP(A23,'LEVEL 2'!$A$14:$K$317,11,FALSE) -> 560706.36 | D23: Unit | E23: =$F$3 -> 363 | F23: =C23/E23 -> 1544.6456 | H23: 2157.06 | I23: 1868.4433 | J23: 1100 | K23: 1724 | L23: 1551.7283 | M23: 1600.2513 | O23: WH has more countertops with secondary bathrooms. | Q23: Increase to Bruner
A24: Lightweight Concrete | B24: =C24/$C$29 -> 0.0070023825 | C24: =VLOOKUP(A24,'LEVEL 2'!$A$14:$K$317,11,FALSE) -> 481539.8 | D24: LW SF | E24: ='Assumptions & Takeoffs'!E14 -> 171978.5 | F24: =C24/E24 -> 2.8 | H24: 2.6 | I24: 2.8 | J24: 2.9324031 | K24: 2.9421304 | L24: 1.2965678 | M24: 1.1 | Q24: Leave as budgeted
A25: Pools and Spas | B25: =C25/$C$29 -> 0.004230626 | C25: =VLOOKUP(A25,'LEVEL 2'!$A$14:$K$317,11,FALSE) -> 290931.67 | D25: LS | E25: 1 | F25: =C25/E25 -> 290931.67 | H25: 253813.33 | I25: 249085 | J25: N/A | K25: 245000 | L25: 228710 | M25: 208310 | O25: Budgeted in the event a second spa is designed. | Q25: Leave as budgeted
A26: Painting | B26: =C26/$C$29 -> 0.010439313 | C26: =VLOOKUP(A26,'LEVEL 2'!$A$14:$K$317,11,FALSE) -> 717890.58 | D26: SF (Bldg) | E26: =$F$4 -> 362571 | F26: =C26/E26 -> 1.98 | H26: 1.92 | I26: 1.58 | J26: 2.0533616 | K26: 1.8370925 | L26: 2.0978638 | M26: 1.9319964 | Q26: Leave as budgeted
A27: Roofing | B27: =C27/$C$29 -> 0.018576727 | C27: =VLOOKUP(A27,'LEVEL 2'!$A$14:$K$317,11,FALSE) -> 1277484.3 | D27: Square | E27: ='Assumptions & Takeoffs'!B19 -> 2143.43 | F27: =C27/E27 -> 596 | H27: 573 | I27: 596 | J27: 491.39689 | K27: 603.3984 | L27: 598.38652 | M27: 535.7424 | Q27: Leave as budgeted
A28: Fire Pump | B28: =C28/$C$29 -> 0.0018177061 | C28: =VLOOKUP(A28,'LEVEL 2'!$A$14:$K$317,11,FALSE) -> 125000 | D28: LS | E28: 1 | F28: =C28 -> 125000 | H28: 160560 | I28: 103700 | J28: N/A | K28: =133300 -> 133300 | L28: 160560 | M28: =120800 -> 120800 | Q28: Leave as budgeted
A29: Total Hard Costs (Level 2) | C29: ='LEVEL 2'!K2 -> 68767994 | D29: GSF | E29: =$F$4 -> 362571 | F29: =C29/E29 -> 189.66766
A31: Total Hard Costs (Level 2.1) | C31: ='LEVEL 2.1'!K2 -> 68005169
A32: Variance | C32: =C29-C31 -> 762825.28

Sheet Division Comparison
A1: Project Details | B1: Level 1.2 | D1: Level 2 | F1: Variance
A2: No Units | B2: ='LEVEL 1.2 BUDGET'!N9 -> 363 | D2: ='LEVEL 2'!N9 -> 363 | F2: =D2-B2 -> 0
A3: 1 Br - 1 Ba | B3: ='LEVEL 1.2 BUDGET'!N5 -> 218 | D3: ='LEVEL 2'!N5 -> 218 | F3: =D3-B3 -> 0
A4: 2 Br - 1 Ba | B4: ='LEVEL 1.2 BUDGET'!N6 -> 145 | D4: ='LEVEL 2'!N6 -> 145 | F4: =D4-B4 -> 0
A6: Parking Spaces | B6: ='LEVEL 1.2 BUDGET'!S8 -> 457 | D6: ='LEVEL 2'!S8 -> 457 | F6: =D6-B6 -> 0
