Workbook
Name \A: #REF!
Name \A: #REF!
Name \B: #REF!
Name \B: #REF!
Name \C: #REF!
Name \C: #REF!
Name \D: #REF!
Name \E: #REF!
Name \F: #REF!
Name \i: #REF!
Name \M: #REF!
Name \N: #REF!
Name \O: #REF!
Name \P: #REF!
Name \Q: #REF!
Name \S: #REF!
Name \T: #REF!
Name \U: #REF!
Name \w: #REF!
Name \X: #REF!
Name \Y: #REF!
Name \Z: #REF!
Name ____7HILLS: #REF!
Name ____Ins2: #REF!
Name ____Ins3: #REF!
Name ____NML9798: #REF!
Name ____NML98: #REF!
Name ____PEG1: #REF!
Name ____RR1: #REF!
Name ____SKY98: #REF!
Name ___1Module2_.PRINT_BCCAM: #N/A
Name ___7HILLS: #REF!
Name ___Ins2: #REF!
Name ___Ins3: #REF!
Name ___MT1: #REF!
Name ___MT2: #REF!
Name ___MT3: #REF!
Name ___NML9798: #REF!
Name ___NML98: #REF!
Name ___PEG1: #REF!
Name ___RR1: #REF!
Name ___SKY98: #REF!
Name __1Module2_.PRINT_BCCAM: #N/A
Name __2Module2_.PRINT_BCPR: #N/A
Name __3Module2_.PRINT_BCTAX: #N/A
Name __4Module2_.PRINT_HSUM: #N/A
Name __5_96100: #REF!
Name __7HILLS: #REF!
Name __96100: #REF!
Name __Ins2: #REF!
Name __Ins3: #REF!
Name __MT1: #REF!
Name __MT2: #REF!
Name __MT3: #REF!
Name __NML9798: #REF!
Name __NML98: #REF!
Name __PEG1: #REF!
Name __RR1: #REF!
Name __SKY98: #REF!
Name __soa202: #REF!

Sheet Level 0
A1: Project Details | C1: Unit Breakdown | F1: Parking | I1: Take Offs
A2: Project | B2: Windmill | C2: Studios | D2: 0 | E2: =D2/$D$7 -> 0 | F2: Garage Parking | H2: 0 | I2: Slab SF | J2: 76473
A3: Budget Level | B3: Level 0 | C3: 1 Br - 1 Ba | D3: 207 | E3: =D3/$D$7 -> 0.646875 | F3: Cover Parking | H3: 320 | I3: Elevators | J3: 4 | K3: 4 Stops
A4: Product | B4: Afforable | C4: 2 Br - 1 Ba | D4: 113 | E4: =D4/$D$7 -> 0.353125 | F4: Open Parking | H4: 198 | I4: Roofing | J4: 1126
A5: Timline | B5: 24 | C5: 2 Br - 2 Ba | D5: 0 | E5: =D5/$D$7 -> 0 | F5: Accessible Parking | H5: 12 | I5: Stucco | J5: =(9142.43+7582.01)*1.03 -> 17226.173
A6: Bldg SF | B6: 316920 | C6: 3 Br - 2 Ba | D6: 0 | E6: =D6/$D$7 -> 0 | F6: Total Parking Provided | H6: =SUM(H2:H5) -> 530 | I6: Carports | J6: =H3 -> 320
A7: Acres | B7: 13.01 | C7: Totals | D7: =SUM(D2:D6) -> 320 | E7: =D7/$D$7 -> 1 | F7: Parking Ratio | H7: =H6/D7 -> 1.65625 | I7: Lightweight | J7: =(73099.09+151291.19)*1.05 -> 235609.79
B9: TOTAL COST | C9: =I102 -> 56343546 | E9: PER UNIT | F9: =C9/D7 -> 176073.58 | H9: PER GSF | I9: =C9/B6 -> 177.78476
A11: Description | B11: Cost Code | C11: Unit Meas. | D11: Quantity | E11: Unit Cost | F11: Escalation % | G11: T. Unit Cost | H11: Sub Total | I11: Total | J11: Cost /U | K11: Description / Details
A12: General Requirements | B12: 01 | C12: Mo | D12: =B5 -> 24 | E12: =0.06*SUM(I13:I95,I97:I98)/B5 -> 117382.39 | G12: =E12 -> 117382.39 | I12: =D12*G12 -> 2817177.3 | J12: =I12/$D$7 -> 8803.6791
A13: Potholing | B13: 02 | C13: LS | D13: 1 | E13: 8000 | F13: 0 | G13: =E13*(1+F13) -> 8000 | I13: =$G$13*$D$13 -> 8000 | J13: =I13/$D$7 -> 25
A14: Concrete | B14: 03 | I14: =SUM(H15:H17) -> 1672110.7 | J14: =I14/$D$7 -> 5225.346
A15: Slabs | B15: 03-3101 | C15: SF | D15: =J2 -> 76473 | E15: 11.99 | F15: 0 | G15: =E15*(1+F15) -> 11.99 | H15: =G15*D15 -> 916911.27 | K15: NRC pricing under $10 other over $12.
A16: Lightweight Concrete | B16: 03-3116 | C16: SF | D16: =J7 -> 235609.79 | E16: 2.6 | F16: 0 | G16: =E16*(1+F16) -> 2.6 | H16: =G16*D16 -> 612585.46
A17: Other | C17: SF | D17: =B6 -> 316920 | E17: 0.45 | F17: 0 | G17: =E17 -> 0.45 | H17: =G17*D17 -> 142614
A18: Masonry | B18: 04 | C18: LS | D18: 1 | E18: 120000 | F18: 0 | G18: =E18*(1+F18) -> 120000 | I18: =$G$18*$D$18 -> 120000 | J18: =I18/$D$7 -> 375 | K18: No elevator shaft
A19: Metals | B19: 05 | F19: 0 | I19: =SUM(H20:H23) -> 473612.8 | J19: =I19/$D$7 -> 1480.04
A20: Structural Steel | C20: LS | D20: 1 | E20: 250000 | F20: 0 | G20: =E20*(1+F20) -> 250000 | H20: =G20*D20 -> 250000 | K20: Place holder
A21: Stair Handrail | C21: Count | D21: =10*3 -> 30 | E21: 2250 | F21: 0 | G21: =E21*(1+F21) -> 2250 | H21: =G21*D21 -> 67500
A22: Iron Railings | C22: LF | D22: 1352.4 | E22: 92 | F22: 0 | G22: =E22*(1+F22) -> 92 | H22: =G22*D22 -> 124420.8
A23: Other | C23: SF | D23: =B6 -> 316920 | E23: 0.1 | F23: 0 | G23: =E23*(1+F23) -> 0.1 | H23: =G23*D23 -> 31692
A24: Wood, Plastics, & Composites | B24: 06 | I24: =SUM(H25:H27) -> 7050352 | J24: =I24/$D$7 -> 22032.35
A25: Framing | B25: 06-1100 | C25: SF | D25: =$B$6 -> 316920 | E25: 18 | F25: 0 | G25: =E25*(1+F25) -> 18 | H25: =G25*D25 -> 5704560 | K25: Robindale and WH ave proposals $16.91
A26: Finish Carpentry - Units | B26: 06-2001 | C26: Unit | D26: =$D$7 -> 320 | E26: 2621 | F26: 0 | G26: =E26*(1+F26) -> 2621 | H26: =G26*D26 -> 838720 | K26: WH ave of 2 best proposals (Rystin and CMD)
A27: Other | C27: SF | D27: =B6 -> 316920 | E27: 1.5 | F27: 0 | G27: 1.6 | H27: =G27*D27 -> 507072
A28: Thermal & Moisture Protection | B28: 07 | I28: =SUM(H29:H31) -> 1538368 | J28: =I28/$D$7 -> 4807.4
A29: Insulation | B29: 07-2101 | C29: SF | D29: =B6 -> 316920 | E29: 2.45 | F29: 0 | G29: =E29*(1+F29) -> 2.45 | H29: =G29*D29 -> 776454
A30: Roofing | B30: 07-3001 | C30: Square | D30: =J4 -> 1126 | E30: 550 | F30: 0 | G30: =E30*(1+F30) -> 550 | H30: =G30*D30 -> 619300
A31: Other | C31: SF | D31: =B6 -> 316920 | E31: 0.45 | F31: 0 | G31: =E31*(1+F31) -> 0.45 | H31: =G31*D31 -> 142614
A32: Openings | B32: 08 | I32: =SUM(H33:H34) -> 543076 | J32: =I32/$D$7 -> 1697.1125
A33: Windows & Sliding Glass Doors | B33: 08-5301 | C33: Unit | D33: =$D$7 -> 320 | E33: 1400 | F33: 0 | G33: =E33*(1+F33) -> 1400 | H33: =G33*D33 -> 448000
A34: Other | C34: SF | D34: =B6 -> 316920 | E34: 0.3 | F34: 0 | G34: =E34*(1+F34) -> 0.3 | H34: =G34*D34 -> 95076
A35: Finishes | B35: 09 | I35: =SUM(H36:H40) -> 4943219.4 | J35: =I35/$D$7 -> 15447.561
A36: Stucco | B36: 09-2423 | C36: SY | D36: =J5 -> 17226.173 | E36: 40 | F36: 0 | G36: =E36*(1+F36) -> 40 | H36: =G36*D36 -> 689046.93
A37: Drywall | B37: 09-2905 | C37: SF | D37: =$B$6 -> 316920 | E37: 7.4 | F37: 0 | G37: =E37*(1+F37) -> 7.4 | H37: =G37*D37 -> 2345208
A38: Flooring - Units | B38: 09-6001 | C38: SY | D38: 26590 | E38: =2.15*9 -> 19.35 | F38: 0 | G38: =E38*(1+F38) -> 19.35 | H38: =G38*D38 -> 514516.5
A39: Painting | B39: 09-9101 | C39: SF | D39: =$B$6 -> 316920 | E39: 1.9 | F39: 0 | G39: =E39*(1+F39) -> 1.9 | H39: =G39*D39 -> 602148
A40: Other | C40: SF | D40: =B6 -> 316920 | E40: 2.5 | F40: 0 | G40: =E40*(1+F40) -> 2.5 | H40: =G40*D40 -> 792300
A41: Specialties | B41: 10 | C41: SF | D41: =B6 -> 316920 | E41: 1.3 | F41: 0 | G41: =E41*(1+F41) -> 1.3 | I41: =$G$41*$D$41 -> 411996 | J41: =I41/$D$7 -> 1287.4875
A42: Equipment / Appliances | B42: 11 | C42: Unit | D42: =D7 -> 320 | E42: =3489 -> 3489 | F42: 0 | G42: =E42*(1+F42) -> 3489 | I42: =$G$42*$D$42 -> 1116480 | J42: =I42/$D$7 -> 3489
...

Sheet Comparison to Other
F1: SENIOR / AFFORABLE PROJECTS
D2: Windmill | F2: Gagnier | G2: Robindale | H2: West Henderson | I2: Bruner | J2: South Nellis | K2: Torrey Pines | L2: Decatur | M2: Pebble
A3: Budget | D3: 190 | F3: 190 | G3: 363 | H3: 390 | I3: 194 | J3: 50 | K3: 190 | L3: 276 | M3: 195
A4: Proposal | D4: 191224 | F4: 191224 | G4: 362571 | H4: 422635 | I4: 196289 | J4: 34388 | K4: 188825 | L4: 258464 | M4: 184108
A5: Contract | D5: 4.14 | F5: 4.14 | G5: 17.35 | H5: 15.826 | I5: 4.9 | J5: 1.3 | K5: 5 | L5: 9.45 | M5: 5
D6: 180338 | F6: 180338 | G6: 755766 | H6: 689380.56 | I6: 213444 | J6: 56628 | K6: 217800 | L6: 411642 | M6: 217800
A7: Description | C7: UOM | D7: PU | F7: PU | G7: PU | H7: PU | I7: PU | J7: PU | K7: PU | L7: PU | M7: PU
A8: Framing | C8: Bld Gross SF | D8: ='Level 0'!G25 -> 18 | F8: 19.9 | G8: 17.039127 | H8: 16.779696 | I8: 18.68 | J8: 20.075375 | K8: 19.921525 | L8: 22.888453 | M8: 19.011015
A9: Electrical | C9: Bld Gross SF | D9: ='Level 0'!G62 -> 12.5 | F9: 13.453144 | G9: 12.801217 | H9: 11.447113 | I9: 10.06 | J9: 12.504362 | K9: 9.2699537 | L9: 10.176018 | M9: 12.13429
A10: HVAC Standard | C10: Per Unit | D10: ='Level 0'!G60 -> 11550 | F10: 10358.127 | G10: 10358.127 | H10: 10170.479 | I10: 9875 | J10: 10148.68 | K10: 9739.2737 | L10: 10104.674 | M10: 9218.2513
A11: Drywall | C11: Bld Gross SF | D11: ='Level 0'!G37 -> 7.4 | F11: 7.64 | G11: 7.3637605 | H11: 7.1643995 | I11: 7.2940664 | J11: 7.7384864 | K11: 8.0157077 | L11: 7.3585311 | M11: 8.0768353
A12: Plumbing | C12: Per Unt | D12: ='Level 0'!G57 -> 10500 | F12: 10515.956 | G12: 10456.129 | H12: 12220.556 | I12: 10069 | J12: 10196.24 | K12: 10526.311 | L12: 11042.514 | M12: 10050.21
A13: Site Landscaping | C13: Per Landscaping Area SF | D13: ='Level 0'!G73 -> 8 | F13: 13.68 | G13: 9 | H13: =(2066905+2326356.65+2429874)/3/304555 -> 7.4678746 | I13: 13.681367 | J13: 10.5 | K13: 12.007558 | L13: 13.483701 | M13: 21.389001
A14: Slabs | C14: Per slab square footage | D14: ='Level 0'!G15 -> 11.99 | F14: 14.719437 | G14: 10.385552 | H14: 10.975209 | I14: 11.11 | J14: 16.778816 | K14: 11.989967 | L14: 15.882903 | M14: 16.060895
A15: Appliances | C15: Per unit | D15: ='Level 0'!G42 -> 3489 | F15: 3663 | G15: 3361 | H15: 3328.1895 | I15: 3169.7043 | J15: 3064.485 | K15: 3488.5 | L15: 3454.4783 | M15: 3201.4974
A16: Cabinets Units | C16: Per unit | D16: ='Level 0'!G44 -> 3500 | F16: 3318 | G16: 2593 | H16: 3451.319 | I16: 4150.2474 | J16: 1985.2 | K16: 3778.0053 | L16: 3705.4275 | M16: 3113.7333
A17: Finish Carpentry - Units | C17: Per unit | D17: ='Level 0'!G26 -> 2621 | F17: 3213.0526 | G17: 3531 | H17: 2621 | I17: 2607.1546 | J17: 2710.9005 | K17: 3210.0359 | L17: 2983.3587 | M17: 3081.2324
A18: Insulation | C18: Bld Gross SF | D18: ='Level 0'!G29 -> 2.45 | F18: 2.6960005 | G18: 2.3587573 | H18: 2.317624 | I18: 2.5 | J18: 2.5423113 | K18: 2.6983715 | L18: 2.2715182 | M18: 2.5011406
A19: Stucco | C19: Per exterior elevation stucco takeoff | D19: ='Level 0'!G36 -> 40 | F19: 55.094999 | G19: 39.624942 | H19: 40.060754 | I19: 39.836808 | J19: 39.371016 | K19: 40.818674 | L19: 42.234692 | M19: 46.688382
A20: Sprinkler System | C20: Bld Gross SF | D20: ='Level 0'!G53 -> 2.65 | F20: 3.3739907 | G20: 3.1224229 | H20: 2.5314042 | I20: 2.65 | J20: 3.2147842 | K20: 2.453065 | L20: 2.94 | M20: 2.4480196
A21: Roofing | C21: Per roof squares takeoff | D21: ='Level 0'!G30 -> 550 | F21: 697.17311 | G21: 504.64069 | H21: 507.25165 | I21: 596 | J21: 491.39689 | K21: 603.3984 | L21: 598.38652 | M21: 535.7424
A22: Painting | C22: Bld Gross SF | D22: ='Level 0'!G39 -> 1.9 | F22: 1.92 | G22: 2.5351255 | H22: 1.7784199 | I22: 1.58 | J22: 2.0533616 | K22: 1.8370925 | L22: 2.0978638 | M22: 1.9319964
A23: Lightweight Concrete | C23: Per lightwright areas SF | D23: ='Level 0'!G16 -> 2.6 | F23: 2.6618086 | G23: 2.66 | H23: 2.4969184 | I23: 2.8 | J23: 2.9324031 | K23: 2.9421304 | L23: 1.2965678 | M23: 1.1
A24: Fire Alarm / Two Way Comm AOR | C24: Bld Gross SF | D24: ='Level 0'!G66 -> 1.65 | F24: 1.6117224 | G24: 1.3042963 | H24: 2.0881383 | I24: 1.3350213 | J24: 1.977434 | K24: 1.6733483 | L24: 1.94 | M24: 1.553436
A25: Flooring - Units | C25: Per total SY of unit measurement | D25: ='Level 0'!G38 -> 19.35 | F25: 26.640866 | G25: 17.1 | H25: 20 | I25: 22.5 | J25: 24.63 | K25: 20.97 | L25: 18.754769 | M25: 16.261536
A26: Counter Tops Units | C26: Per unit | D26: ='Level 0'!G45 -> 1868 | F26: 1532 | G26: 1545 | H26: 1868.4433 | I26: 1868.4433 | J26: 1100 | K26: 1724 | L26: 1551.7283 | M26: 1600.2513
A27: Windows and Sliding Glass Doors | C27: Per unit | D27: ='Level 0'!G33 -> 1400 | F27: 1450 | G27: 1550 | H27: 1259.8213 | I27: 1335.866 | J27: 1300.6084 | K27: 1157.8947 | L27: 1408.8261 | M27: 739.27144
A28: Pools and Spas | C28: Total Pool Estimate | D28: ='Level 0'!G48 -> 260000 | F28: 257146.67 | G28: 257146.67 | H28: 253813.33 | I28: 249085 | J28: N/A | K28: 245000 | L28: 228710 | M28: 208310
A29: Fire Pump | C29: Total Pump House Estimate | D29: ='Level 0'!E54 -> 125000 | F29: 125000 | G29: 125000 | H29: N/A | I29: 103700 | J29: N/A | K29: 133300 | L29: 160560 | M29: 120800
A30: Total Hard Costs

Sheet Division Calculations
C4: ='Level 0'!B2 -> Windmill | D4: ='Level 0'!D7 -> 320 | E4: ='Level 0'!B6 -> 316920 | G4: Gagnier | H4: 190 | I4: 191224 | K4: Bruner Sr | L4: 194 | M4: 196289 | O4: VARIANCE
A5: Description | C5: Total | D5: Per Unit | E5: Per SF | G5: Total | H5: Per Unit | I5: Per SF | K5: Total | L5: Per Unit | M5: Per SF | O5: Total | P5: Per Unit | Q5: Per SF | S5: Expl.
A6: General Requirements | C6: =VLOOKUP(A6,'Level 0'!$A$12:$I$102,9,FALSE) -> 2817177.3 | D6: =C6/$D$4 -> 8803.6791 | E6: =C6/$E$4 -> 8.889238 | G6: 1639003.3 | H6: =G6/$H$4 -> 8626.3332 | I6: =G6/$I$4 -> 8.5711171 | K6: 1692096 | L6: =K6/$L$4 -> 8722.1443 | M6: =K6/$M$4 -> 8.6204321 | O6: =C6-K6 -> 1125081.3 | P6: =L6-D6 -> -81.534791 | Q6: =E6-M6 -> 0.26880592
A7: Potholing | C7: =VLOOKUP(A7,'Level 0'!$A$12:$I$102,9,FALSE) -> 8000 | D7: =C7/$D$4 -> 25 | E7: =C7/$E$4 -> 0.025242964 | G7: 16000 | H7: =G7/$H$4 -> 84.210526 | I7: =G7/$I$4 -> 0.083671506 | K7: 3500 | L7: =K7/$L$4 -> 18.041237 | M7: =K7/$M$4 -> 0.017830851 | O7: =C7-K7 -> 4500 | P7: =L7-D7 -> -6.9587629 | Q7: =E7-M7 -> 0.0074121121
A8: Concrete | C8: =VLOOKUP(A8,'Level 0'!$A$12:$I$102,9,FALSE) -> 1672110.7 | D8: =C8/$D$4 -> 5225.346 | E8: =C8/$E$4 -> 5.2761288 | G8: 1055314.9 | H8: =G8/$H$4 -> 5554.2889 | I8: =G8/$I$4 -> 5.5187367 | K8: 1089279.8 | L8: =K8/$L$4 -> 5614.8444 | M8: =K8/$M$4 -> 5.5493676 | O8: =C8-K8 -> 582830.91 | P8: =L8-D8 -> 389.49839 | Q8: =E8-M8 -> -0.27323883
A9: Slabs | C9: =VLOOKUP(A9,'Level 0'!$A$12:$I$102,8,FALSE) -> 916911.27 | D9: =C9/$D$4 -> 2865.3477 | E9: =C9/$E$4 -> 2.8931947 | G9: 563410.1 | H9: =G9/$H$4 -> 2965.3163 | I9: =G9/$I$4 -> 2.9463357 | K9: 576982.78 | L9: =K9/$L$4 -> 2974.138 | M9: =K9/$M$4 -> 2.9394555 | O9: =C9-K9 -> 339928.49 | P9: =L9-D9 -> 108.79032 | Q9: =E9-M9 -> -0.046260779
A10: Lightweight Concrete | C10: =VLOOKUP(A10,'Level 0'!$A$12:$I$102,8,FALSE) -> 612585.46 | D10: =C10/$D$4 -> 1914.3296 | E10: =C10/$E$4 -> 1.9329341 | G10: 377386.8 | H10: =G10/$H$4 -> 1986.2463 | I10: =G10/$I$4 -> 1.9735326 | K10: 432915 | L10: =K10/$L$4 -> 2231.5206 | M10: =K10/$M$4 -> 2.205498 | O10: =C10-K10 -> 179670.46 | P10: =L10-D10 -> 317.19104 | Q10: =E10-M10 -> -0.27256395
A11: Other | C11: =C8-C9-C10 -> 142614 | D11: =C11/$D$4 -> 445.66875 | E11: =C11/$E$4 -> 0.45 | G11: =G8-G9-G10 -> 114518 | H11: =G11/$H$4 -> 602.72632 | I11: =G11/$I$4 -> 0.59886834 | K11: =K8-K9-K10 -> 79382.04 | L11: =K11/$L$4 -> 409.18577 | M11: =K11/$M$4 -> 0.4044141 | O11: =C11-K11 -> 63231.96 | P11: =L11-D11 -> -36.482977 | Q11: =E11-M11 -> 0.045585896
A12: Masonry | C12: =VLOOKUP(A12,'Level 0'!$A$12:$I$102,9,FALSE) -> 120000 | D12: =C12/$D$4 -> 375 | E12: =C12/$E$4 -> 0.37864445 | G12: 130500 | H12: =G12/$H$4 -> 686.84211 | I12: =G12/$I$4 -> 0.68244572 | K12: 112800 | L12: =K12/$L$4 -> 581.4433 | M12: =K12/$M$4 -> 0.57466287 | O12: =C12-K12 -> 7200 | P12: =L12-D12 -> 206.4433 | Q12: =E12-M12 -> -0.19601842
A13: Metals | C13: =VLOOKUP(A13,'Level 0'!$A$12:$I$102,9,FALSE) -> 473612.8 | D13: =C13/$D$4 -> 1480.04 | E13: =C13/$E$4 -> 1.4944238 | G13: 418954 | H13: =G13/$H$4 -> 2205.0211 | I13: =G13/$I$4 -> 2.190907 | K13: 325412.13 | L13: =K13/$L$4 -> 1677.3821 | M13: =K13/$M$4 -> 1.6578215 | O13: =C13-K13 -> 148200.67 | P13: =L13-D13 -> 197.3421 | Q13: =E13-M13 -> -0.16339769
A14: Structural Steel | C14: =VLOOKUP(A14,'Level 0'!$A$12:$I$102,8,FALSE) -> 250000 | D14: =C14/$D$4 -> 781.25 | E14: =C14/$E$4 -> 0.78884261 | G14: 130000 | H14: =G14/$H$4 -> 684.21053 | I14: =G14/$I$4 -> 0.67983098 | K14: 112826.13 | L14: =K14/$L$4 -> 581.57798 | M14: =K14/$M$4 -> 0.57479598 | O14: =C14-K14 -> 137173.87 | P14: =L14-D14 -> -199.67202 | Q14: =E14-M14 -> 0.21404663
A15: Stair Handrail | C15: =VLOOKUP(A15,'Level 0'!$A$12:$I$102,8,FALSE) -> 67500 | D15: =C15/$D$4 -> 210.9375 | E15: =C15/$E$4 -> 0.2129875 | G15: 24000 | H15: =G15/$H$4 -> 126.31579 | I15: =G15/$I$4 -> 0.12550726 | K15: 56000 | L15: =K15/$L$4 -> 288.65979 | M15: =K15/$M$4 -> 0.28529362 | O15: =C15-K15 -> 11500 | P15: =L15-D15 -> 77.722294 | Q15: =E15-M15 -> -0.072306118
A16: Iron Railings | C16: =VLOOKUP(A16,'Level 0'!$A$12:$I$102,8,FALSE) -> 124420.8 | D16: =C16/$D$4 -> 388.815 | E16: =C16/$E$4 -> 0.39259371 | G16: 124292 | H16: =G16/$H$4 -> 654.16842 | I16: =G16/$I$4 -> 0.64998117 | K16: 146556 | L16: =K16/$L$4 -> 755.4433 | M16: =K16/$M$4 -> 0.74663379 | O16: =C16-K16 -> -22135.2 | P16: =L16-D16 -> 366.6283 | Q16: =E16-M16 -> -0.35404008
A17: Other | C17: =C13-SUM(C14:C16) -> 31692 | D17: =C17/$D$4 -> 99.0375 | E17: =C17/$E$4 -> 0.1 | G17: =G13-SUM(G14:G16) -> 140662 | H17: =G17/$H$4 -> 740.32632 | I17: =G17/$I$4 -> 0.73558758 | K17: =K13-SUM(K14:K16) -> 10030 | L17: =K17/$L$4 -> 51.701031 | M17: =K17/$M$4 -> 0.051098126 | O17: =C17-K17 -> 21662 | P17: =L17-D17 -> -47.336469 | Q17: =E17-M17 -> 0.048901874
A18: Wood, Plastics, & Composites | C18: =VLOOKUP(A18,'Level 0'!$A$12:$I$102,9,FALSE) -> 7050352 | D18: =C18/$D$4 -> 22032.35 | E18: =C18/$E$4 -> 22.246472 | G18: 4314821.2 | H18: =G18/$H$4 -> 22709.585 | I18: =G18/$I$4 -> 22.564224 | K18: 4804000.7 | L18: =K18/$L$4 -> 24762.89 | M18: =K18/$M$4 -> 24.474121 | O18: =C18-K18 -> 2246351.3 | P18: =L18-D18 -> 2730.5402 | Q18: =E18-M18 -> -2.2276485
A19: Framing | C19: =VLOOKUP(A19,'Level 0'!$A$12:$I$102,8,FALSE) -> 5704560 | D19: =C19/$D$4 -> 17826.75 | E19: =C19/$E$4 -> 18 | G19: 3572064.3 | H19: =G19/$H$4 -> 18800.339 | I19: =G19/$I$4 -> 18.68 | K19: 4023924.5 | L19: =K19/$L$4 -> 20741.879 | M19: =K19/$M$4 -> 20.5 | O19: =C19-K19 -> 1680635.5 | P19: =L19-D19 -> 2915.1289 | Q19: =E19-M19 -> -2.5
A20: Finish Carpentry - Units | C20: =VLOOKUP(A20,'Level 0'!$A$12:$I$102,8,FALSE) -> 838720 | D20: =C20/$D$4 -> 2621 | E20: =C20/$E$4 -> 2.6464723 | G20: 495900 | H20: =G20/$H$4 -> 2610 | I20: =G20/$I$4 -> 2.5932937 | K20: 619345 | L20: =K20/$L$4 -> 3192.5 | M20: =K20/$M$4 -> 3.1552711 | O20: =C20-K20 -> 219375 | P20: =L20-D20 -> 571.5 | Q20: =E20-M20 -> -0.50879876
A21: Other | C21: =C18-C19-C20 -> 507072 | D21: =C21/$D$4 -> 1584.6 | E21: =C21/$E$4 -> 1.6 | G21: =G18-G19-G20 -> 246856.92 | H21: =G21/$H$4 -> 1299.2469 | I21: =G21/$I$4 -> 1.2909306 | K21: =K18-K19-K20 -> 160731.2 | L21: =K21/$L$4 -> 828.51134 | M21: =K21/$M$4 -> 0.81884976 | O21: =C21-K21 -> 346340.8 | P21: =L21-D21 -> -756.08866 | Q21: =E21-M21 -> 0.78115024
A22: Thermal & Moisture Protection | C22: =VLOOKUP(A22,'Level 0'!$A$12:$I$102,9,FALSE) -> 1538368 | D22: =C22/$D$4 -> 4807.4 | E22: =C22/$E$4 -> 4.8541209 | G22: 905735.12 | H22: =G22/$H$4 -> 4767.0269 | I22: =G22/$I$4 -> 4.7365138 | K22: 905486.76 | L22: =K22/$L$4 -> 4667.4575 | M22: =K22/$M$4 -> 4.6130285 | O22: =C22-K22 -> 632881.24 | P22: =L22-D22 -> -139.94247 | Q22: =E22-M22 -> 0.24109237
A23: Insulation | C23: =VLOOKUP(A23,'Level 0'!$A$12:$I$102,8,FALSE) -> 776454 | D23: =C23/$D$4 -> 2426.4187 | E23: =C23/$E$4 -> 2.45 | G23: 520033.67 | H23: =G23/$H$4 -> 2737.0193 | I23: =G23/$I$4 -> 2.7195 | K23: 529980.3 | L23: =K23/$L$4 -> 2731.8572 | M23: =K23/$M$4 -> 2.7 | O23: =C23-K23 -> 246473.7 | P23: =L23-D23 -> 305.43847 | Q23: =E23-M23 -> -0.25
A24: Roofing | C24: =VLOOKUP(A24,'Level 0'!$A$12:$I$102,8,FALSE) -> 619300 | D24: =C24/$D$4 -> 1935.3125 | E24: =C24/$E$4 -> 1.9541209 | G24: 296742.33 | H24: =G24/$H$4 -> 1561.8017 | I24: =G24/$I$4 -> 1.5518048 | K24: 303688.89 | L24: =K24/$L$4 -> 1565.4066 | M24: =K24/$M$4 -> 1.5471519 | O24: =C24-K24 -> 315611.11 | P24: =L24-D24 -> -369.90585 | Q24: =E24-M24 -> 0.40696906
A25: Other | C25: =C22-C23-C24 -> 142614 | D25: =C25/$D$4 -> 445.66875 | E25: =C25/$E$4 -> 0.45 | G25: =G22-G23-G24 -> 88959.12 | H25: =G25/$H$4 -> 468.20589 | I25: =G25/$I$4 -> 0.46520897 | K25: =K22-K23-K24 -> 71817.57 | L25: =K25/$L$4 -> 370.19366 | M25: =K25/$M$4 -> 0.36587669 | O25: =C25-K25 -> 70796.43 | P25: =L25-D25 -> -75.47509 | Q25: =E25-M25 -> 0.084123308
A26: Openings | C26: =VLOOKUP(A26,'Level 0'!$A$12:$I$102,9,FALSE) -> 543076 | D26: =C26/$D$4 -> 1697.1125 | E26: =C26/$E$4 -> 1.713606 | G26: 319450 | H26: =G26/$H$4 -> 1681.3158 | I26: =G26/$I$4 -> 1.6705539 | K26: 279109.58 | L26: =K26/$L$4 -> 1438.7092 | M26: =K26/$M$4 -> 1.4219318 | O26: =C26-K26 -> 263966.42 | P26: =L26-D26 -> -258.40333 | Q26: =E26-M26 -> 0.29167412
A27: Windows & Sliding Glass Doors | C27: =VLOOKUP(A27,'Level 0'!$A$12:$I$102,8,FALSE) -> 448000 | D27: =C27/$D$4 -> 1400 | E27: =C27/$E$4 -> 1.413606 | G27: 262390 | H27: =G27/$H$4 -> 1381 | I27: =G27/$I$4 -> 1.3721604 | K27: 224631.58 | L27: =K27/$L$4 -> 1157.8947 | M27: =K27/$M$4 -> 1.1443921 | O27: =C27-K27 -> 223368.42 | P27: =L27-D27 -> -242.10526 | Q27: =E27-M27 -> 0.26921387
A28: Other | C28: =C26-C27 -> 95076 | D28: =C28/$D$4 -> 297.1125 | E28: =C28/$E$4 -> 0.3 | G28: =G26-G27 -> 57060 | H28: =G28/$H$4 -> 300.31579 | I28: =G28/$I$4 -> 0.29839351 | K28: =K26-K27 -> 54478 | L28: =K28/$L$4 -> 280.81443 | M28: =K28/$M$4 -> 0.27753975 | O28: =C28-K28 -> 40598 | P28: =L28-D28 -> -16.298067 | Q28: =E28-M28 -> 0.02246025
A29: Finishes | C29: =VLOOKUP(A29,'Level 0'!$A$12:$I$102,9,FALSE) -> 4943219.4 | D29: =C29/$D$4 -> 15447.561 | E29: =C29/$E$4 -> 15.597688 | G29: 3031250.9 | H29: =G29/$H$4 -> 15953.952 | I29: =G29/$I$4 -> 15.851833 | K29: 3261602.4 | L29: =K29/$L$4 -> 16812.383 | M29: =K29/$M$4 -> 16.616328 | O29: =C29-K29 -> 1681617.1 | P29: =L29-D29 -> 1364.8226 | Q29: =E29-M29 -> -1.0186393
A30: Stucco | C30: =VLOOKUP(A30,'Level 0'!$A$12:$I$102,8,FALSE) -> 689046.93 | D30: =C30/$D$4 -> 2153.2717 | E30: =C30/$E$4 -> 2.1741983 | G30: 334992 | H30: =G30/$H$4 -> 1763.1158 | I30: =G30/$I$4 -> 1.7518303 | K30: 482655.68 | L30: =K30/$L$4 -> 2487.9159 | M30: =K30/$M$4 -> 2.4589034 | O30: =C30-K30 -> 206391.25 | P30: =L30-D30 -> 334.64423 | Q30: =E30-M30 -> -0.28470504
A31: Drywall | C31: =VLOOKUP(A31,'Level 0'!$A$12:$I$102,8,FALSE) -> 2345208 | D31: =C31/$D$4 -> 7328.775 | E31: =C31/$E$4 -> 7.4 | G31: 1472424.8 | H31: =G31/$H$4 -> 7749.6042 | I31: =G31/$I$4 -> 7.7 | K31: 1574237.8 | L31: =K31/$L$4 -> 8114.6277 | M31: =K31/$M$4 -> 8.02 | O31: =C31-K31 -> 770970.22 | P31: =L31-D31 -> 785.85273 | Q31: =E31-M31 -> -0.62
A32: Flooring - Units | C32: =VLOOKUP(A32,'Level 0'!$A$12:$I$102,8,FALSE) -> 514516.5 | D32: =C32/$D$4 -> 1607.8641 | E32: =C32/$E$4 -> 1.6234902 | G32: 299556 | H32: =G32/$H$4 -> 1576.6105 | I32: =G32/$I$4 -> 1.5665188 | K32: 305547.12 | L32: =K32/$L$4 -> 1574.9852 | M32: =K32/$M$4 -> 1.5566187 | O32: =C32-K32 -> 208969.38 | P32: =L32-D32 -> -32.878908 | Q32: =E32-M32 -> 0.066871496
A33: Painting | C33: =VLOOKUP(A33,'Level 0'!$A$12:$I$102,8,FALSE) -> 602148 | D33: =C33/$D$4 -> 1881.7125 | E33: =C33/$E$4 -> 1.9 | G33: 367150.08 | H33: =G33/$H$4 -> 1932.3688 | I33: =G33/$I$4 -> 1.92 | K33: 361171.76 | L33: =K33/$L$4 -> 1861.7101 | M33: =K33/$M$4 -> 1.84 | O33: =C33-K33 -> 240976.24 | P33: =L33-D33 -> -20.002397 | Q33: =E33-M33 -> 0.06
A34: Other | C34: =C29-SUM(C30:C33) -> 792300 | D34: =C34/$D$4 -> 2475.9375 | E34: =C34/$E$4 -> 2.5 | G34: =G29-SUM(G30:G33) -> 557127.99 | H34: =G34/$H$4 -> 2932.2526 | I34: =G34/$I$4 -> 2.9134836 | K34: =K29-SUM(K30:K33) -> 537990.01 | L34: =K34/$L$4 -> 2773.1444 | M34: =K34/$M$4 -> 2.7408057 | O34: =C34-K34 -> 254309.99 | P34: =L34-D34 -> 297.2069 | Q34: =E34-M34 -> -0.24080571
A35: Specialties | C35: =VLOOKUP(A35,'Level 0'!$A$12:$I$102,9,FALSE) -> 411996 | D35: =C35/$D$4 -> 1287.4875 | E35: =C35/$E$4 -> 1.3 | G35: 255620 | H35: =G35/$H$4 -> 1345.3684 | I35: =G35/$I$4 -> 1.3367569 | K35: 233950 | L35: =K35/$L$4 -> 1205.9278 | M35: =K35/$M$4 -> 1.1918651 | O35: =C35-K35 -> 178046 | P35: =L35-D35 -> -81.559665 | Q35: =E35-M35 -> 0.10813494
A36: Equipment / Appliances | C36: =VLOOKUP(A36,'Level 0'!$A$12:$I$102,9,FALSE) -> 1116480 | D36: =C36/$D$4 -> 3489 | E36: =C36/$E$4 -> 3.522908 | G36: 633504 | H36: =G36/$H$4 -> 3334.2316 | I36: =G36/$I$4 -> 3.3128896 | K36: 621090.5 | L36: =K36/$L$4 -> 3201.4974 | M36: =K36/$M$4 -> 3.1641636 | O36: =C36-K36 -> 495389.5 | P36: =L36-D36 -> -287.50256 | Q36: =E36-M36 -> 0.35874442
A37: Furnishings | C37: =VLOOKUP(A37,'Level 0'!$A$12:$I$102,9,FALSE) -> 2034680 | D37: =C37/$D$4 -> 6358.375 | E37: =C37/$E$4 -> 6.4201691 | G37: 1156370 | H37: =G37/$H$4 -> 6086.1579 | I37: =G37/$I$4 -> 6.0472012 | K37: 1046615.4 | L37: =K37/$L$4 -> 5394.9245 | M37: =K37/$M$4 -> 5.3320123 | O37: =C37-K37 -> 988064.64 | P37: =L37-D37 -> -963.45046 | Q37: =E37-M37 -> 1.0881568
A38: Cabinets Units | C38: =VLOOKUP(A38,'Level 0'!$A$12:$I$102,8,FALSE) -> 1120000 | D38: =C38/$D$4 -> 3500 | E38: =C38/$E$4 -> 3.5340149 | G38: 598690 | H38: =G38/$H$4 -> 3151 | I38: =G38/$I$4 -> 3.1308309 | K38: 610712 | L38: =K38/$L$4 -> 3148 | M38: =K38/$M$4 -> 3.11129 | O38: =C38-K38 -> 509288 | P38: =L38-D38 -> -352 | Q38: =E38-M38 -> 0.42272491
A39: Counter Tops Units | C39: =VLOOKUP(A39,'Level 0'!$A$12:$I$102,8,FALSE) -> 597760 | D39: =C39/$D$4 -> 1868 | E39: =C39/$E$4 -> 1.8861542 | G39: 309510 | H39: =G39/$H$4 -> 1629 | I39: =G39/$I$4 -> 1.618573 | K39: 338777.27 | L39: =K39/$L$4 -> 1746.2746 | M39: =K39/$M$4 -> 1.7259106 | O39: =C39-K39 -> 258982.73 | P39: =L39-D39 -> -121.72542 | Q39: =E39-M39 -> 0.16024362
A40: Other | C40: =C37-C38-C39 -> 316920 | D40: =C40/$D$4 -> 990.375 | E40: =C40/$E$4 -> 1 | G40: =G37-G38-G39 -> 248170 | H40: =G40/$H$4 -> 1306.1579 | I40: =G40/$I$4 -> 1.2977973 | K40: =K37-K38-K39 -> 97126.092 | L40: =K40/$L$4 -> 500.64996 | M40: =K40/$M$4 -> 0.49481169 | O40: =C40-K40 -> 219793.91 | P40: =L40-D40 -> -489.72504 | Q40: =E40-M40 -> 0.50518831
A41: Special Construction | C41: =VLOOKUP(A41,'Level 0'!$A$12:$I$102,9,FALSE) -> 1023200 | D41: =C41/$D$4 -> 3197.5 | E41: =C41/$E$4 -> 3.228575 | G41: 536257 | H41: =G41/$H$4 -> 2822.4053 | I41: =G41/$I$4 -> 2.8043394 | K41: 572485 | L41: =K41/$L$4 -> 2950.9536 | M41: =K41/$M$4 -> 2.9165414 | O41: =C41-K41 -> 450715 | P41: =L41-D41 -> -246.54639 | Q41: =E41-M41 -> 0.31203361
A42: Pools and Spas | C42: =VLOOKUP(A42,'Level 0'!$A$12:$I$102,8,FALSE) -> 260000 | D42: =C42/$D$4 -> 812.5 | E42: =C42/$E$4 -> 0.82039631 | G42: 245000 | H42: =G42/$H$4 -> 1289.4737 | I42: =G42/$I$4 -> 1.2812199 | K42: 245000 | L42: =K42/$L$4 -> 1262.8866 | M42: =K42/$M$4 -> 1.2481596 | O42: =C42-K42 -> 15000 | P42: =L42-D42 -> 450.3866 | Q42: =E42-M42 -> -0.42776329
A43: Carports | C43: =VLOOKUP(A43,'Level 0'!$A$12:$I$102,8,FALSE) -> 752000 | D43: =C43/$D$4 -> 2350 | E43: =C43/$E$4 -> 2.3728386 | G43: 284208 | H43: =G43/$H$4 -> 1495.8316 | I43: =G43/$I$4 -> 1.486257 | K43: 320436 | L43: =K43/$L$4 -> 1651.732 | M43: =K43/$M$4 -> 1.6324705 | O43: =C43-K43 -> 431564 | P43: =L43-D43 -> -698.26804 | Q43: =E43-M43 -> 0.74036808
...

Sheet Bruner Comparison
E3: Flamingo Riley | I3: Gagnier | M3: Bruner | Q3: Variance
E4: $ | F4: $ / GSF | G4: $ / U | I4: $ | J4: $ / GSF | K4: $ / U | M4: $ | N4: $ / GSF | O4: $ / U | Q4: $ | R4: $ / GSF | S4: $ / U
B5: Hard Cost
B6: 01 - General Requirements | E6: ='Level 0'!I12 -> 2817177.3 | F6: =E6/'Level 0'!B6 -> 8.889238 | G6: =E6/'Level 0'!D7 -> 8803.6791 | I6: 1787886.7 | J6: 11.04179 | K6: 9409.9299 | M6: ='Division Calculations'!K6 -> 1692096 | N6: 8.6291782 | O6: 8537.5488 | Q6: 131602.23 | R6: 2.4126121 | S6: 872.38117
B7: 02 - Existing Conditions | F7: =E7/'Level 0'!B7 -> 0 | G7: =E7/'Level 0'!D7 -> 0 | I7: 8000 | J7: 0.049407115 | K7: 42.105263 | M7: ='Division Calculations'!K7 -> 3500 | N7: 0.018234865 | O7: 18.041237 | Q7: 4500 | R7: 0.03117225 | S7: 24.064026
B8: 03 - Concrete | E8: ='Level 0'!I14 -> 1672110.7 | F8: =E8/'Level 0'!B6 -> 5.2761288 | G8: =E8/'Level 0'!D7 -> 5225.346 | I8: 1097353.6 | J8: 6.7771341 | K8: 5775.545 | M8: ='Division Calculations'!K8 -> 1089279.8 | N8: 5.6751059 | O8: 5614.8444 | Q8: 8073.7301 | R8: 1.1020282 | S8: 160.70057
B9: 04 - Masonry | E9: ='Level 0'!I18 -> 120000 | F9: =E9/'Level 0'!B6 -> 0.37864445 | G9: =E9/'Level 0'!D7 -> 375 | I9: 114000 | J9: 0.70405138 | K9: 600 | M9: 112800 | N9: 0.58768365 | O9: 581.4433 | Q9: 1200 | R9: 0.11636773 | S9: 18.556701
B10: 05 - Metals | E10: ='Level 0'!I19 -> 473612.8 | F10: =E10/'Level 0'!B6 -> 1.4944238 | G10: =E10/'Level 0'!D7 -> 1480.04 | I10: 342950 | J10: 2.1180212 | K10: 1805 | M10: 325412.13 | N10: 1.6953846 | O10: 1677.3821 | Q10: 17537.872 | R10: 0.4226366 | S10: 127.6179
B11: 06 - Wood, Plastics, & Composites | E11: ='Level 0'!I24 -> 7050352 | F11: =E11/'Level 0'!B6 -> 22.246472 | G11: =E11/'Level 0'!D7 -> 22032.35 | I11: 4802924.5 | J11: 29.66233 | K11: 25278.55 | M11: 4804000.7 | N11: 25.028658 | O11: 24762.89 | Q11: -1076.2 | R11: 4.6336717 | S11: 515.65979
B12: 07 - Thermal & Moisture Protection | E12: ='Level 0'!I28 -> 1538368 | F12: =E12/'Level 0'!B6 -> 4.8541209 | G12: =E12/'Level 0'!D7 -> 4807.4 | I12: 943030.3 | J12: 5.8240508 | K12: 4963.3174 | M12: 905486.76 | N12: 4.7175511 | O12: 4667.4575 | Q12: 37543.54 | R12: 1.1064997 | S12: 295.85984
B13: 08 - Openings | E13: ='Level 0'!I32 -> 543076 | F13: =E13/'Level 0'!B6 -> 1.713606 | G13: =E13/'Level 0'!D7 -> 1697.1125 | I13: 296000 | J13: 1.8280632 | K13: 1557.8947 | M13: 279109.58 | N13: 1.4541501 | O13: 1438.7092 | Q13: 16890.421 | R13: 0.3739131 | S13: 119.18557
B14: 09 - Finishes | E14: ='Level 0'!I35 -> 4943219.4 | F14: =E14/'Level 0'!B6 -> 15.597688 | G14: =E14/'Level 0'!D7 -> 15447.561 | I14: 3247896.6 | J14: 20.05865 | K14: 17094.193 | M14: 3261602.4 | N14: 16.992823 | O14: 16812.383 | Q14: -13705.767 | R14: 3.0658274 | S14: 281.8093
B15: 10 - Specialties | E15: ='Level 0'!I41 -> 411996 | F15: =E15/'Level 0'!B6 -> 1.3 | G15: =E15/'Level 0'!D7 -> 1287.4875 | I15: 237500 | J15: 1.4667737 | K15: 1250 | M15: 233950 | N15: 1.2188705 | O15: 1205.9278 | Q15: 3550 | R15: 0.24790324 | S15: 44.072165
B16: 11 - Equipment | E16: ='Level 0'!I42 -> 1116480 | F16: =E16/'Level 0'!B6 -> 3.522908 | G16: =E16/'Level 0'!D7 -> 3489 | I16: 617500 | J16: 3.8136117 | K16: 3250 | M16: 621090.5 | N16: 3.2358576 | O16: 3201.4974 | Q16: -3590.5026 | R16: 0.57775409 | S16: 48.502564
B17: 12 - Furnishings | E17: ='Level 0'!I43 -> 2034680 | F17: =E17/'Level 0'!B6 -> 6.4201691 | G17: =E17/'Level 0'!D7 -> 6358.375 | I17: 1021250 | J17: 6.307127 | K17: 5375 | M17: 1046615.4 | N17: 5.4528257 | O17: 5394.9245 | Q17: -25365.361 | R17: 0.85430129 | S17: -19.924543
B18: 13 - Special Construction | E18: ='Level 0'!I47 -> 1023200 | F18: =E18/'Level 0'!B6 -> 3.228575 | G18: =E18/'Level 0'!D7 -> 3197.5 | I18: 662875 | J18: 4.0938426 | K18: 3488.8158 | M18: 572485 | N18: 2.9826248 | O18: 2950.9536 | Q18: 90390 | R18: 1.1112179 | S18: 537.86218
B19: 14 - Conveying Equipment | E19: ='Level 0'!I51 -> 668000 | F19: =E19/'Level 0'!B6 -> 2.1077875 | G19: =E19/'Level 0'!D7 -> 2087.5 | I19: 368264 | J19: 2.2743577 | K19: 1938.2316 | M19: 323200 | N19: 1.6838595 | O19: 1665.9794 | Q19: 45064 | R19: 0.59049817 | S19: 272.2522
B20: 21 - Fire Suppression | E20: ='Level 0'!I52 -> 1012376 | F20: =E20/'Level 0'!B6 -> 3.1944213 | G20: =E20/'Level 0'!D7 -> 3163.675 | I20: 1228085.7 | J20: 7.5845211 | K20: 6463.6087 | M20: 623908.05 | N20: 3.2505369 | O20: 3216.0209 | Q20: 604177.61 | R20: 4.3339842 | S20: 3247.5878
B21: 22 - Plumbing | E21: ='Level 0'!I56 -> 3407538 | F21: =E21/'Level 0'!B6 -> 10.752045 | G21: =E21/'Level 0'!D7 -> 10648.556 | I21: 2028440 | J21: 12.527421 | K21: 10676 | M21: 2072717.3 | N21: 10.798777 | O21: 10684.11 | Q21: -44277.263 | R21: 1.7286439 | S21: -8.1096039
B22: 23 - HVAC | E22: ='Level 0'!I60 -> 3696000 | F22: =E22/'Level 0'!B6 -> 11.662249 | G22: =E22/'Level 0'!D7 -> 11550 | I22: 2035451 | J22: 12.57072 | K22: 10712.9 | M22: 2078302.6 | N22: 10.827876 | O22: 10712.9 | Q22: -42851.6 | R22: 1.7428437 | S22: 0
B23: 26 - Electrical | E23: ='Level 0'!I61 -> 4595340 | F23: =E23/'Level 0'!B6 -> 14.5 | G23: =E23/'Level 0'!D7 -> 14360.438 | I23: 2224079 | J23: 13.735666 | K23: 11705.679 | M23: 2246065.4 | N23: 11.701914 | O23: 11577.657 | Q23: -21986.449 | R23: 2.0337513 | S23: 128.02199
B24: 27 - Communications | E24: ='Level 0'!I64 -> 224000 | F24: =E24/'Level 0'!B6 -> 0.70680298 | G24: =E24/'Level 0'!D7 -> 700 | I24: 133000 | J24: 0.82139328 | K24: 700 | M24: 117610.51 | N24: 0.61274622 | O24: 606.23974 | Q24: 15389.49 | R24: 0.20864706 | S24: 93.760258
B25: 28 - Electronic Safety & Security | E25: ='Level 0'!I65 -> 823992 | F25: =E25/'Level 0'!B6 -> 2.6 | G25: =E25/'Level 0'!D7 -> 2574.975 | I25: 0 | J25: 0 | K25: 0 | M25: 521084 | N25: 2.7148276 | O25: 2686 | Q25: -521084 | R25: -2.7148276 | S25: -2686
B26: 31 - Earthwork | E26: ='Level 0'!I68 -> 782531 | F26: =E26/'Level 0'!B6 -> 2.4691752 | G26: =E26/'Level 0'!D7 -> 2445.4094 | I26: 669561.16 | J26: 4.1351356 | K26: 3524.0061 | M26: 347262 | N26: 1.8092216 | O26: 1790.0103 | Q26: 322299.16 | R26: 2.325914 | S26: 1733.9958
B27: 32 - Exterior Improvements | E27: ='Level 0'!I71 -> 5109722.4 | F27: =E27/'Level 0'!B6 -> 16.123067 | G27: =E27/'Level 0'!D7 -> 15967.882 | I27: 2071879.6 | J27: 12.795699 | K27: 10904.63 | M27: 2302071.9 | N27: 11.993706 | O27: 11866.35 | Q27: -230192.27 | R27: 0.80199346 | S27: -961.72036
B28: 33 - Utilities | E28: ='Level 0'!I78 -> 1900406 | F28: =E28/'Level 0'!B6 -> 5.9964849 | G28: =E28/'Level 0'!D7 -> 5938.7688 | I28: 3039786 | J28: 18.773382 | K28: 15998.874 | M28: 1619983 | N28: 8.440049 | O28: 8350.4278 | Q28: 1419803 | R28: 10.333333 | S28: 7648.4458
B29: 34 - Transportation | E29: ='Level 0'!I87 -> 15000 | F29: =E29/'Level 0'!B6 -> 0.047330557 | G29: =E29/'Level 0'!D7 -> 46.875 | I29: 10000 | J29: 0.061758893 | K29: 52.631579 | M29: 7500 | N29: 0.039074711 | O29: 38.659794 | Q29: 2500 | R29: 0.022684182 | S29: 13.971785
B30: 48 - Electrical Power Generation | E30: ='Level 0'!I88 -> 480000 | F30: =E30/'Level 0'!B6 -> 1.5145778 | G30: =E30/'Level 0'!D7 -> 1500 | I30: 182400 | J30: 1.1264822 | K30: 960 | M30: 392850 | N30: 2.0467334 | O30: 2025 | Q30: -210450 | R30: -0.92025114 | S30: -1065
B31: 49 - Field Surveys, Staking | E31: ='Level 0'!I89 -> 325250 | F31: =E31/'Level 0'!B6 -> 1.0262842 | G31: =E31/'Level 0'!D7 -> 1016.4062 | I31: 240000 | J31: 1.4822134 | K31: 1263.1579 | M31: 234787.5 | N31: 1.2232338 | O31: 1210.2448 | Q31: 5212.5 | R31: 0.25897962 | S31: 52.913049
B32: Bid Risk | E32: ='Level 0'!I90 -> 879505.01 | F32: =E32/'Level 0'!B6 -> 2.7751641 | G32: =E32/'Level 0'!D7 -> 2748.4531 | I32: 552444.53 | J32: 3.4118363 | K32: 2907.6028 | M32: 0 | N32: 0 | O32: 0 | Q32: 552444.53 | R32: 3.4118363 | S32: 2907.6028
B33: FFE Extra | E33: ='Level 0'!I93 -> 1155000 | F33: =E33/'Level 0'!B6 -> 3.6444529 | G33: =E33/'Level 0'!D7 -> 3609.375 | I33: 950000 | J33: 5.8670949 | K33: 5000 | M33: 691024.09 | N33: 3.6002089 | O33: 3561.9798 | Q33: 258975.91 | R33: 2.266886 | S33: 1438.0202
B34: 50 - Sub Bonds / Contractor Insurance | E34: =SUM('Level 0'!I97:I98) -> 943199.98 | F34: =E34/'Level 0'!B6 -> 2.9761453 | G34: =E34/'Level 0'!D7 -> 2947.5 | I34: 673440.57 | J34: 4.1590944 | K34: 3544.4241 | M34: 771042.45 | N34: 4.0171014 | O34: 3974.4456 | Q34: -97601.877 | R34: 0.14199301 | S34: -430.02155
B35: 55 - Construction Contingency | E35: ='Level 0'!I96 -> 2817177.3 | F35: =E35/'Level 0'!B6 -> 8.889238 | G35: =E35/'Level 0'!D7 -> 8803.6791 | I35: 1698492.4 | J35: 10.489701 | K35: 8939.4334 | M35: 1573470.2 | N35: 8.1977193 | O35: 8110.6713 | Q35: 125022.12 | R35: 2.2919815 | S35: 828.76212
B36: 56 - Contractor Fee | E36: ='Level 0'!I99 -> 3756236.4 | F36: =E36/'Level 0'!B6 -> 11.852317 | G36: =E36/'Level 0'!D7 -> 11738.239 | I36: 2383848.9 | J36: 14.722387 | K36: 12546.573 | M36: 2208379.3 | N36: 11.505571 | O36: 11383.398 | Q36: 175469.64 | R36: 3.2168162 | S36: 1163.1749
B38: Total Hard Costs | E38: =SUM(E6:E36) -> 56335546 | F38: =SUM(F6:F36) -> 177.75952 | G38: =SUM(G6:G36) -> 176048.58 | I38: 35668339 | J38: 220.28372 | K38: 187728.1 | M38: 33042875 | N38: =SUM(N6:N36) -> 172.1521 | O38: =SUM(O6:O36) -> 170324.1 | Q38: 2625464.4 | R38: =SUM(R6:R36) -> 48.131612 | S38: =SUM(S6:S36) -> 17404.004

Sheet Torrey Comparison
B2: Flamingo Riley | F2: Gagnier | J2: Torrey Pines | N2: Variance
B4: $ | C4: $ / GSF | D4: $ / U | F4: $ | G4: $ / GSF | H4: $ / U | J4: $ | K4: $ / GSF | L4: $ / U | N4: $ | O4: $ / GSF | P4: $ / U | R4: Comments
A5: Leaseable | G5: =[59]Input!C15 -> 133584 | H5: =[59]Input!C13 -> 190 | K5: 201630 | L5: 276 | O5: 344214 | P5: 388
A6: Gross | G6: =[59]Input!C20 -> 161920 | K6: 254891
A8: =[59]Const_Cost_Summ!B9 -> Hard Cost
A9: 01 - General Requirements | B9: ='Level 0'!I12 -> 2817177.3 | C9: =B9/$G$6 -> 17.398575 | D9: =B9/$H$5 -> 14827.249 | F9: 1787886.7 | G9: 11.04179 | H9: 9409.9299 | J9: 1675207.3 | K9: 8.8717451 | L9: 8816.8803 | N9: =F9-J9 -> 112679.43 | O9: =G9-K9 -> 2.1700452 | P9: =H9-L9 -> 593.04961
A10: 02 - Existing Conditions | C10: =B10/$G$6 -> 0 | D10: =B10/$H$5 -> 0 | F10: 8000 | G10: 0.049407115 | H10: 42.105263 | J10: 3500 | K10: 0.018535681 | L10: 18.421053 | N10: =F10-J10 -> 4500 | O10: =G10-K10 -> 0.030871433 | P10: =H10-L10 -> 23.684211
A11: 03 - Concrete | B11: ='Level 0'!I14 -> 1672110.7 | C11: =B11/$G$6 -> 10.326771 | D11: =B11/$H$5 -> 8800.5828 | F11: 1097353.6 | G11: 6.7771341 | H11: 5775.545 | J11: 855751.3 | K11: 4.5319809 | L11: 4503.9542 | N11: =F11-J11 -> 241602.25 | O11: =G11-K11 -> 2.2451531 | P11: =H11-L11 -> 1271.5908
A12: 04 - Masonry | B12: ='Level 0'!I18 -> 120000 | C12: =B12/$G$6 -> 0.74110672 | D12: =B12/$H$5 -> 631.57895 | F12: 114000 | G12: 0.70405138 | H12: 600 | J12: 154110 | K12: 0.81615252 | L12: 811.10526 | N12: =F12-J12 -> -40110 | O12: =G12-K12 -> -0.11210114 | P12: =H12-L12 -> -211.10526
A13: 05 - Metals | B13: ='Level 0'!I19 -> 473612.8 | C13: =B13/$G$6 -> 2.9249802 | D13: =B13/$H$5 -> 2492.6989 | F13: 342950 | G13: 2.1180212 | H13: 1805 | J13: 288724 | K13: 1.529056 | L13: 1519.6 | N13: =F13-J13 -> 54226 | O13: =G13-K13 -> 0.58896524 | P13: =H13-L13 -> 285.4
A14: 06 - Wood, Plastics, & Composites | B14: ='Level 0'!I24 -> 7050352 | C14: =B14/$G$6 -> 43.542194 | D14: =B14/$H$5 -> 37107.116 | F14: 4802924.5 | G14: 29.66233 | H14: 25278.55 | J14: 4782473.5 | K14: 25.327544 | L14: 25170.913 | N14: =F14-J14 -> 20451 | O14: =G14-K14 -> 4.3347861 | P14: =H14-L14 -> 107.63684
A15: 07 - Thermal & Moisture Protection | B15: ='Level 0'!I28 -> 1538368 | C15: =B15/$G$6 -> 9.5007905 | D15: =B15/$H$5 -> 8096.6737 | F15: 943030.3 | G15: 5.8240508 | H15: 4963.3174 | J15: 886843.75 | K15: 4.6966437 | L15: 4667.5987 | N15: =F15-J15 -> 56186.55 | O15: =G15-K15 -> 1.127407 | P15: =H15-L15 -> 295.71868
A16: 08 - Openings | B16: ='Level 0'!I32 -> 543076 | C16: =B16/$G$6 -> 3.3539773 | D16: =B16/$H$5 -> 2858.2947 | F16: 296000 | G16: 1.8280632 | H16: 1557.8947 | J16: 462292.91 | K16: 2.4482611 | L16: 2433.1206 | N16: =F16-J16 -> -166292.91 | O16: =G16-K16 -> -0.6201979 | P16: =H16-L16 -> -875.22584 | R16: Common Area Doors ($200k)are under (06) Finish Carpentry.
A17: 09 - Finishes | B17: ='Level 0'!I35 -> 4943219.4 | C17: =B17/$G$6 -> 30.528776 | D17: =B17/$H$5 -> 26016.944 | F17: 3247896.6 | G17: 20.05865 | H17: 17094.193 | J17: 3275902.9 | K17: 17.348884 | L17: 17241.594 | N17: =F17-J17 -> -28006.354 | O17: =G17-K17 -> 2.7097663 | P17: =H17-L17 -> -147.40186
A18: 10 - Specialties | B18: ='Level 0'!I41 -> 411996 | C18: =B18/$G$6 -> 2.5444417 | D18: =B18/$H$5 -> 2168.4 | F18: 237500 | G18: 1.4667737 | H18: 1250 | J18: 207648 | K18: 1.0996849 | L18: 1092.8842 | N18: =F18-J18 -> 29852 | O18: =G18-K18 -> 0.36708882 | P18: =H18-L18 -> 157.11579
A19: 11 - Equipment | B19: ='Level 0'!I42 -> 1116480 | C19: =B19/$G$6 -> 6.8952569 | D19: =B19/$H$5 -> 5876.2105 | F19: 617500 | G19: 3.8136117 | H19: 3250 | J19: 555940 | K19: 2.9442076 | L19: 2926 | N19: =F19-J19 -> 61560 | O19: =G19-K19 -> 0.86940406 | P19: =H19-L19 -> 324
A20: 12 - Furnishings | B20: ='Level 0'!I43 -> 2034680 | C20: =B20/$G$6 -> 12.565958 | D20: =B20/$H$5 -> 10708.842 | F20: 1021250 | G20: 6.307127 | H20: 5375 | J20: 1126769 | K20: 5.967266 | L20: 5930.3632 | N20: =F20-J20 -> -105519 | O20: =G20-K20 -> 0.33986099 | P20: =H20-L20 -> -555.36316
A21: 13 - Special Construction | B21: ='Level 0'!I47 -> 1023200 | C21: =B21/$G$6 -> 6.31917 | D21: =B21/$H$5 -> 5385.2632 | F21: 662875 | G21: 4.0938426 | H21: 3488.8158 | J21: 514455.07 | K21: 2.7245072 | L21: 2707.6583 | N21: =F21-J21 -> 148419.93 | O21: =G21-K21 -> 1.3693354 | P21: =H21-L21 -> 781.15753
A22: 14 - Conveying Equipment | B22: ='Level 0'!I51 -> 668000 | C22: =B22/$G$6 -> 4.1254941 | D22: =B22/$H$5 -> 3515.7895 | F22: 368264 | G22: 2.2743577 | H22: 1938.2316 | J22: 337555 | K22: 1.7876605 | L22: 1776.6053 | N22: =F22-J22 -> 30709 | O22: =G22-K22 -> 0.48669718 | P22: =H22-L22 -> 161.62632
A23: 21 - Fire Suppression | B23: ='Level 0'!I52 -> 1012376 | C23: =B23/$G$6 -> 6.2523221 | D23: =B23/$H$5 -> 5328.2947 | F23: 644722.5 | G23: 3.9817348 | H23: 3393.2763 | J23: 661214.75 | K23: 3.5017331 | L23: 3480.0776 | N23: =F23-J23 -> -16492.25 | O23: =G23-K23 -> 0.48000172 | P23: =H23-L23 -> -86.801316
A24: 22 - Plumbing | B24: ='Level 0'!I56 -> 3407538 | C24: =B24/$G$6 -> 21.044578 | D24: =B24/$H$5 -> 17934.411 | F24: 2028440 | G24: 12.527421 | H24: 10676 | J24: 2166278.5 | K24: 11.472414 | L24: 11401.466 | N24: =F24-J24 -> -137838.5 | O24: =G24-K24 -> 1.0550073 | P24: =H24-L24 -> -725.46579
A25: 23 - HVAC | B25: ='Level 0'!I60 -> 3696000 | C25: =B25/$G$6 -> 22.826087 | D25: =B25/$H$5 -> 19452.632 | F25: 2035451 | G25: 12.57072 | H25: 10712.9 | J25: 1751619.5 | K25: 9.2764173 | L25: 9219.05 | N25: =F25-J25 -> 283831.5 | O25: =G25-K25 -> 3.2943028 | P25: =H25-L25 -> 1493.85 | R25: New refrigerant cost provided on Hualapai proposal by Enix.
A26: 26 - Electrical | B26: ='Level 0'!I61 -> 4595340 | C26: =B26/$G$6 -> 28.380311 | D26: =B26/$H$5 -> 24186 | F26: 2224079 | G26: 13.735666 | H26: 11705.679 | J26: 2257308 | K26: 11.954498 | L26: 11880.568 | N26: =F26-J26 -> -33229.019 | O26: =G26-K26 -> 1.7811681 | P26: =H26-L26 -> -174.88957
A27: 27 - Communications | B27: ='Level 0'!I64 -> 224000 | C27: =B27/$G$6 -> 1.3833992 | D27: =B27/$H$5 -> 1178.9474 | F27: 133000 | G27: 0.82139328 | H27: 700 | J27: 900 | K27: 0.004766318 | L27: 4.7368421 | N27: =F27-J27 -> 132100 | O27: =G27-K27 -> 0.81662696 | P27: =H27-L27 -> 695.26316 | R27: DAS System budget. Normal cost aroung $115k to $120k.
A28: 28 - Electronic Safety & Security | B28: ='Level 0'!I65 -> 823992 | C28: =B28/$G$6 -> 5.0888834 | D28: =B28/$H$5 -> 4336.8 | F28: 583363.16 | G28: 3.6027863 | H28: 3070.3324 | J28: 464996.5 | K28: 2.4625791 | L28: 2447.35 | N28: =F28-J28 -> 118366.66 | O28: =G28-K28 -> 1.1402072 | P28: =H28-L28 -> 622.9824 | R28: Esc @ 20% if CC implement new alarm code.
A29: 31 - Earthwork | B29: ='Level 0'!I68 -> 782531 | C29: =B29/$G$6 -> 4.8328249 | D29: =B29/$H$5 -> 4118.5842 | F29: 669561.16 | G29: 4.1351356 | H29: 3524.0061 | J29: 609629.75 | K29: 3.2285436 | L29: 3208.5776 | N29: =F29-J29 -> 59931.41 | O29: =G29-K29 -> 0.906592 | P29: =H29-L29 -> 315.42847
A30: 32 - Exterior Improvements | B30: ='Level 0'!I71 -> 5109722.4 | C30: =B30/$G$6 -> 31.55708 | D30: =B30/$H$5 -> 26893.276 | F30: 2071879.6 | G30: 12.795699 | H30: 10904.63 | J30: 2186782.5 | K30: 11.581001 | L30: 11509.381 | N30: =F30-J30 -> -114902.81 | O30: =G30-K30 -> 1.2146987 | P30: =H30-L30 -> -604.75164
A31: 33 - Utilities | B31: ='Level 0'!I78 -> 1900406 | C31: =B31/$G$6 -> 11.736697 | D31: =B31/$H$5 -> 10002.137 | F31: 3039786 | G31: 18.773382 | H31: 15998.874 | J31: 1788881 | K31: 9.4737508 | L31: 9415.1632 | N31: =F31-J31 -> 1250905 | O31: =G31-K31 -> 9.2996311 | P31: =H31-L31 -> 6583.7105 | R31: Using initial GCW site evalation 5/20/2021 which has worse case scenerio.
A32: 34 - Transportation | B32: ='Level 0'!I87 -> 15000 | C32: =B32/$G$6 -> 0.09263834 | D32: =B32/$H$5 -> 78.947368 | F32: 10000 | G32: 0.061758893 | H32: 52.631579 | J32: 7500 | K32: 0.039719317 | L32: 39.473684 | N32: =F32-J32 -> 2500 | O32: =G32-K32 -> 0.022039576 | P32: =H32-L32 -> 13.157895
A33: 48 - Electrical Power Generation | B33: ='Level 0'!I88 -> 480000 | C33: =B33/$G$6 -> 2.9644269 | D33: =B33/$H$5 -> 2526.3158 | F33: 182400 | G33: 1.1264822 | H33: 960 | J33: 707152.38 | K33: 3.7450146 | L33: 3721.8546 | N33: =F33-J33 -> -524752.38 | O33: =G33-K33 -> -2.6185324 | P33: =H33-L33 -> -2761.8546 | R33: Minimun amount condired for car charger requirement and rough for solar.
A34: 49 - Field Surveys, Staking | B34: ='Level 0'!I89 -> 325250 | C34: =B34/$G$6 -> 2.008708 | D34: =B34/$H$5 -> 1711.8421 | F34: 240000 | G34: 1.4822134 | H34: 1263.1579 | J34: 149353.1 | K34: 0.79096041 | L34: 786.06895 | N34: =F34-J34 -> 90646.9 | O34: =G34-K34 -> 0.69125303 | P34: =H34-L34 -> 477.08895 | R34: Pebble current estimate to completion is at $223k.
A35: Bid Risk | B35: ='Level 0'!I90 -> 879505.01 | C35: =B35/$G$6 -> 5.4317256 | D35: =B35/$H$5 -> 4628.9737 | F35: 552444.53 | G35: 3.4118363 | H35: 2907.6028 | J35: 0 | K35: 0 | L35: 0 | N35: =F35-J35 -> 552444.53 | O35: =G35-K35 -> 3.4118363 | P35: =H35-L35 -> 2907.6028
A36: FFE Extra | B36: ='Level 0'!I93 -> 1155000 | C36: =B36/$G$6 -> 7.1331522 | D36: =B36/$H$5 -> 6078.9474 | F36: 950000 | G36: 5.8670949 | H36: 5000 | J36: 1161406.5 | K36: 6.1507032 | L36: 6112.666 | N36: =F36-J36 -> -211406.53 | O36: =G36-K36 -> -0.28360834 | P36: =H36-L36 -> -1112.666
A37: 50 - Sub Bonds / Contractor Insurance | B37: =SUM('Level 0'!I97:I98) -> 943199.98 | C37: =B37/$G$6 -> 5.8250987 | D37: =B37/$H$5 -> 4964.2104 | F37: 673440.57 | G37: 4.1590944 | H37: 3544.4241 | J37: 555133.12 | K37: 2.9399344 | L37: 2921.7533 | N37: =F37-J37 -> 118307.45 | O37: =G37-K37 -> 1.21916 | P37: =H37-L37 -> 622.67081
A38: 55 - Construction Contingency | B38: ='Level 0'!I96 -> 2817177.3 | C38: =B38/$G$6 -> 17.398575 | D38: =B38/$H$5 -> 14827.249 | F38: 1698492.4 | G38: 10.489701 | H38: 8939.4334 | J38: 1591446.9 | K38: 8.4281578 | L38: 8376.0363 | N38: =F38-J38 -> 107045.45 | O38: =G38-K38 -> 2.061543 | P38: =H38-L38 -> 563.39713
A39: 56 - Contractor Fee | B39: ='Level 0'!I99 -> 3756236.4 | C39: =B39/$G$6 -> 23.1981 | D39: =B39/$H$5 -> 19769.665 | F39: 2383848.9 | G39: 14.722387 | H39: 12546.573 | J39: 2233609.7 | K39: 11.828993 | L39: 11755.84 | N39: =F39-J39 -> 150239.23 | O39: =G39-K39 -> 2.8933937 | P39: =H39-L39 -> 790.73281
A41: Total Hard Costs | B41: =SUM(B9:B39) -> 56335546 | C41: =B41/$G$6 -> 347.9221 | D41: =B41/$H$5 -> 296502.88 | F41: 35668339 | G41: 220.28372 | H41: 187728.1 | J41: 33420385 | K41: 176.99131 | L41: 175896.76 | N41: =F41-J41 -> 2247954.5 | O41: =G41-K41 -> 43.292403 | P41: =H41-L41 -> 11831.34
